Workbook

Sheet Guide
A1: StatementPulse — Financial Statement Analysis (DEMO)
A2: Built around: Financial Statement Analysis Needed ASAP (Freelancer, Brisbane client).
A3: Data: SYNTHETIC — fictional Sharma Retail Pvt. Ltd., Patna; FY2024-FY2026, seeded.
A5: What this answers: is the business profitable, liquid, and generating cash?
A6: Statements rebuilds the P&L, balance sheet and indirect cash flow from the raw
A7: line items — every subtotal is a formula, nothing is hard-coded. Ratios benchmarks
A8: each ratio against a plain threshold and flags FY2026 exceptions. Trend shows the
A9: FY2026 monthly build-up; its totals tie exactly to the annual statements.
A11: How to use:
A12: 1. Replace the Amount column in Raw_Statements / rows in Raw_Monthly with real data,
A13: keeping the same Section / LineItem / Year labels.
A14: 2. Statements, Ratios, Trend, Dashboard and Checks update by formula.
... A18: Raw_Statements | Raw_Monthly | Checks (must all read TRUE).

Sheet Dashboard
A1: StatementPulse — Sharma Retail Pvt. Ltd. (SYNTHETIC DEMO, FY2024-FY2026)
A3: KPI (FY2026 unless stated) | B3: Value
A4: Revenue (FY2026) | B4: =Statements!D3
A5: Profit after tax (FY2026) | B5: =Statements!D13
A6: Net margin (FY2026) | B6: =Ratios!D7
A7: Current ratio (FY2026) | B7: =Ratios!D2
A8: Receivables days (FY2026) | B8: =Ratios!D10
A9: Operating cash conversion (FY2026) | B9: =Ratios!D13
A11: FY2026 ratio flags (see Ratios sheet) | B11: =Ratios!B15
A13: Year | B13: Revenue | C13: Profit after tax
A14: FY2024 | B14: =Statements!B3 | C14: =Statements!B35
A15: FY2025 | B15: =Statements!C3 | C15: =Statements!C35
A16: FY2026 | B16: =Statements!D3 | C16: =Statements!D35
A50: Cost item (FY2026) | B50: Amount
A51: Cost of goods sold | B51: =Statements!D4
A52: Operating expenses | B52: =Statements!D6
A53: Depreciation | B53: =Statements!D8
A54: Interest expense | B54: =Statements!D10
A55: Tax expense | B55: =Statements!D12

Sheet Raw_Statements
A1: Section | B1: LineItem | C1: Year | D1: Amount
A2: Profit & loss | B2: Revenue | C2: FY2024 | D2: 42000000
A3: Profit & loss | B3: Cost of goods sold | C3: FY2024 | D3: 26040000
A4: Profit & loss | B4: Operating expenses | C4: FY2024 | D4: 9240000
A5: Profit & loss | B5: Depreciation | C5: FY2024 | D5: 1800000
A6: Profit & loss | B6: Interest expense | C6: FY2024 | D6: 2200000
A7: Profit & loss | B7: Tax expense | C7: FY2024 | D7: 680000
A8: Balance sheet | B8: Cash and bank | C8: FY2024 | D8: 10331342
A9: Balance sheet | B9: Trade receivables | C9: FY2024 | D9: 5523288
A10: Balance sheet | B10: Inventories | C10: FY2024 | D10: 2996384
A11: Balance sheet | B11: Other current assets | C11: FY2024 | D11: 800000
A12: Balance sheet | B12: Property plant and equipment (net) | C12: FY2024 | D12: 15200000
A13: Balance sheet | B13: Other non-current assets | C13: FY2024 | D13: 1500000
... A73: Balance sheet | B73: Cash and bank | C73: Opening | D73: 7800000

Sheet Raw_Monthly
A1: Month | B1: Revenue | C1: COGS | D1: Opex | E1: Receivables | F1: Inventory | G1: Payables
A2: 2025-04 | B2: 4817785 | C2: 2842493 | D2: 1011735 | E2: 7411806 | F2: 3784495 | G2: 2925031
A3: 2025-05 | B3: 4817785 | C3: 2842493 | D3: 1011735 | E3: 7623769 | F3: 3892895 | G3: 2864529
A4: 2025-06 | B4: 5058674 | C4: 2984618 | D4: 1062322 | E4: 7589748 | F4: 3856757 | G4: 2933953
A5: 2025-07 | B5: 4576896 | C5: 2700369 | D5: 961148 | E5: 7788988 | F5: 3985374 | G5: 3129252
A6: 2025-08 | B6: 4817785 | C6: 2842493 | D6: 1011735 | E6: 8093154 | F6: 4266530 | G6: 3176422
A7: 2025-09 | B7: 5058674 | C7: 2984618 | D7: 1062322 | E7: 7954196 | F7: 4395404 | G7: 3093879
A8: 2025-10 | B8: 6022231 | C8: 3553116 | D8: 1264668 | E8: 8423974 | F8: 4442167 | G8: 3148907
A9: 2025-11 | B9: 6263120 | C9: 3695241 | D9: 1315255 | E9: 8685883 | F9: 4518742 | G9: 3386840
A10: 2025-12 | B10: 5299563 | C10: 3126742 | D10: 1112908 | E10: 9239876 | F10: 4700461 | G10: 3391090
A11: 2026-01 | B11: 4576896 | C11: 2700368 | D11: 961148 | E11: 8936827 | F11: 4517030 | G11: 3517512
A12: 2026-02 | B12: 4095117 | C12: 2416119 | D12: 859975 | E12: 9268597 | F12: 4653141 | G12: 3360596
A13: 2026-03 | B13: 5058674 | C13: 2984618 | D13: 1062321 | E13: 9607851 | F13: 4886752 | G13: 3518461

Sheet Statements
A1: Line item | B1: FY2024 | C1: FY2025 | D1: FY2026
A2: PROFIT & LOSS
A3: Revenue | B3: =SUMIFS(Raw_Statements!$D$2:$D$73,Raw_Statements!$B$2:$B$73,"Revenue",Raw_Statements!$C$2:$C$73,"FY2024") | C3: =SUMIFS(Raw_Statements!$D$2:$D$73,Raw_Statements!$B$2:$B$73,"Revenue",Raw_Statements!$C$2:$C$73,"FY2025") | D3: =SUMIFS(Raw_Statements!$D$2:$D$73,Raw_Statements!$B$2:$B$73,"Revenue",Raw_Statements!$C$2:$C$73,"FY2026")
A4: Cost of goods sold | B4: =SUMIFS(Raw_Statements!$D$2:$D$73,Raw_Statements!$B$2:$B$73,"Cost of goods sold",Raw_Statements!$C$2:$C$73,"FY2024") | C4: =SUMIFS(Raw_Statements!$D$2:$D$73,Raw_Statements!$B$2:$B$73,"Cost of goods sold",Raw_Statements!$C$2:$C$73,"FY2025") | D4: =SUMIFS(Raw_Statements!$D$2:$D$73,Raw_Statements!$B$2:$B$73,"Cost of goods sold",Raw_Statements!$C$2:$C$73,"FY2026")
A5: Gross profit | B5: =B3-B4 | C5: =C3-C4 | D5: =D3-D4
A6: Operating expenses | B6: =SUMIFS(Raw_Statements!$D$2:$D$73,Raw_Statements!$B$2:$B$73,"Operating expenses",Raw_Statements!$C$2:$C$73,"FY2024") | C6: =SUMIFS(Raw_Statements!$D$2:$D$73,Raw_Statements!$B$2:$B$73,"Operating expenses",Raw_Statements!$C$2:$C$73,"FY2025") | D6: =SUMIFS(Raw_Statements!$D$2:$D$73,Raw_Statements!$B$2:$B$73,"Operating expenses",Raw_Statements!$C$2:$C$73,"FY2026")
A7: EBITDA | B7: =B5-B6 | C7: =C5-C6 | D7: =D5-D6
A8: Depreciation | B8: =SUMIFS(Raw_Statements!$D$2:$D$73,Raw_Statements!$B$2:$B$73,"Depreciation",Raw_Statements!$C$2:$C$73,"FY2024") | C8: =SUMIFS(Raw_Statements!$D$2:$D$73,Raw_Statements!$B$2:$B$73,"Depreciation",Raw_Statements!$C$2:$C$73,"FY2025") | D8: =SUMIFS(Raw_Statements!$D$2:$D$73,Raw_Statements!$B$2:$B$73,"Depreciation",Raw_Statements!$C$2:$C$73,"FY2026")
A9: EBIT | B9: =B7-B8 | C9: =C7-C8 | D9: =D7-D8
A10: Interest expense | B10: =SUMIFS(Raw_Statements!$D$2:$D$73,Raw_Statements!$B$2:$B$73,"Interest expense",Raw_Statements!$C$2:$C$73,"FY2024") | C10: =SUMIFS(Raw_Statements!$D$2:$D$73,Raw_Statements!$B$2:$B$73,"Interest expense",Raw_Statements!$C$2:$C$73,"FY2025") | D10: =SUMIFS(Raw_Statements!$D$2:$D$73,Raw_Statements!$B$2:$B$73,"Interest expense",Raw_Statements!$C$2:$C$73,"FY2026")
A11: Profit before tax | B11: =B9-B10 | C11: =C9-C10 | D11: =D9-D10
A12: Tax expense | B12: =SUMIFS(Raw_Statements!$D$2:$D$73,Raw_Statements!$B$2:$B$73,"Tax expense",Raw_Statements!$C$2:$C$73,"FY2024") | C12: =SUMIFS(Raw_Statements!$D$2:$D$73,Raw_Statements!$B$2:$B$73,"Tax expense",Raw_Statements!$C$2:$C$73,"FY2025") | D12: =SUMIFS(Raw_Statements!$D$2:$D$73,Raw_Statements!$B$2:$B$73,"Tax expense",Raw_Statements!$C$2:$C$73,"FY2026")
A13: Profit after tax | B13: =B11-B12 | C13: =C11-C12 | D13: =D11-D12
A14: BALANCE SHEET
A15: Cash and bank | B15: =SUMIFS(Raw_Statements!$D$2:$D$73,Raw_Statements!$B$2:$B$73,"Cash and bank",Raw_Statements!$C$2:$C$73,"FY2024") | C15: =SUMIFS(Raw_Statements!$D$2:$D$73,Raw_Statements!$B$2:$B$73,"Cash and bank",Raw_Statements!$C$2:$C$73,"FY2025") | D15: =SUMIFS(Raw_Statements!$D$2:$D$73,Raw_Statements!$B$2:$B$73,"Cash and bank",Raw_Statements!$C$2:$C$73,"FY2026")
A16: Trade receivables | B16: =SUMIFS(Raw_Statements!$D$2:$D$73,Raw_Statements!$B$2:$B$73,"Trade receivables",Raw_Statements!$C$2:$C$73,"FY2024") | C16: =SUMIFS(Raw_Statements!$D$2:$D$73,Raw_Statements!$B$2:$B$73,"Trade receivables",Raw_Statements!$C$2:$C$73,"FY2025") | D16: =SUMIFS(Raw_Statements!$D$2:$D$73,Raw_Statements!$B$2:$B$73,"Trade receivables",Raw_Statements!$C$2:$C$73,"FY2026")
A17: Inventories | B17: =SUMIFS(Raw_Statements!$D$2:$D$73,Raw_Statements!$B$2:$B$73,"Inventories",Raw_Statements!$C$2:$C$73,"FY2024") | C17: =SUMIFS(Raw_Statements!$D$2:$D$73,Raw_Statements!$B$2:$B$73,"Inventories",Raw_Statements!$C$2:$C$73,"FY2025") | D17: =SUMIFS(Raw_Statements!$D$2:$D$73,Raw_Statements!$B$2:$B$73,"Inventories",Raw_Statements!$C$2:$C$73,"FY2026")
A18: Other current assets | B18: =SUMIFS(Raw_Statements!$D$2:$D$73,Raw_Statements!$B$2:$B$73,"Other current assets",Raw_Statements!$C$2:$C$73,"FY2024") | C18: =SUMIFS(Raw_Statements!$D$2:$D$73,Raw_Statements!$B$2:$B$73,"Other current assets",Raw_Statements!$C$2:$C$73,"FY2025") | D18: =SUMIFS(Raw_Statements!$D$2:$D$73,Raw_Statements!$B$2:$B$73,"Other current assets",Raw_Statements!$C$2:$C$73,"FY2026")
A19: Total current assets | B19: =SUM(B15:B18) | C19: =SUM(C15:C18) | D19: =SUM(D15:D18)
A20: Property plant and equipment (net) | B20: =SUMIFS(Raw_Statements!$D$2:$D$73,Raw_Statements!$B$2:$B$73,"Property plant and equipment (net)",Raw_Statements!$C$2:$C$73,"FY2024") | C20: =SUMIFS(Raw_Statements!$D$2:$D$73,Raw_Statements!$B$2:$B$73,"Property plant and equipment (net)",Raw_Statements!$C$2:$C$73,"FY2025") | D20: =SUMIFS(Raw_Statements!$D$2:$D$73,Raw_Statements!$B$2:$B$73,"Property plant and equipment (net)",Raw_Statements!$C$2:$C$73,"FY2026")
A21: Other non-current assets | B21: =SUMIFS(Raw_Statements!$D$2:$D$73,Raw_Statements!$B$2:$B$73,"Other non-current assets",Raw_Statements!$C$2:$C$73,"FY2024") | C21: =SUMIFS(Raw_Statements!$D$2:$D$73,Raw_Statements!$B$2:$B$73,"Other non-current assets",Raw_Statements!$C$2:$C$73,"FY2025") | D21: =SUMIFS(Raw_Statements!$D$2:$D$73,Raw_Statements!$B$2:$B$73,"Other non-current assets",Raw_Statements!$C$2:$C$73,"FY2026")
A22: Total non-current assets | B22: =B20+B21 | C22: =C20+C21 | D22: =D20+D21
A23: TOTAL ASSETS | B23: =B19+B22 | C23: =C19+C22 | D23: =D19+D22
A24: Trade payables | B24: =SUMIFS(Raw_Statements!$D$2:$D$73,Raw_Statements!$B$2:$B$73,"Trade payables",Raw_Statements!$C$2:$C$73,"FY2024") | C24: =SUMIFS(Raw_Statements!$D$2:$D$73,Raw_Statements!$B$2:$B$73,"Trade payables",Raw_Statements!$C$2:$C$73,"FY2025") | D24: =SUMIFS(Raw_Statements!$D$2:$D$73,Raw_Statements!$B$2:$B$73,"Trade payables",Raw_Statements!$C$2:$C$73,"FY2026")
A25: Short-term borrowings | B25: =SUMIFS(Raw_Statements!$D$2:$D$73,Raw_Statements!$B$2:$B$73,"Short-term borrowings",Raw_Statements!$C$2:$C$73,"FY2024") | C25: =SUMIFS(Raw_Statements!$D$2:$D$73,Raw_Statements!$B$2:$B$73,"Short-term borrowings",Raw_Statements!$C$2:$C$73,"FY2025") | D25: =SUMIFS(Raw_Statements!$D$2:$D$73,Raw_Statements!$B$2:$B$73,"Short-term borrowings",Raw_Statements!$C$2:$C$73,"FY2026")
A26: Other current liabilities | B26: =SUMIFS(Raw_Statements!$D$2:$D$73,Raw_Statements!$B$2:$B$73,"Other current liabilities",Raw_Statements!$C$2:$C$73,"FY2024") | C26: =SUMIFS(Raw_Statements!$D$2:$D$73,Raw_Statements!$B$2:$B$73,"Other current liabilities",Raw_Statements!$C$2:$C$73,"FY2025") | D26: =SUMIFS(Raw_Statements!$D$2:$D$73,Raw_Statements!$B$2:$B$73,"Other current liabilities",Raw_Statements!$C$2:$C$73,"FY2026")
A27: Total current liabilities | B27: =SUM(B24:B26) | C27: =SUM(C24:C26) | D27: =SUM(D24:D26)
A28: Long-term borrowings | B28: =SUMIFS(Raw_Statements!$D$2:$D$73,Raw_Statements!$B$2:$B$73,"Long-term borrowings",Raw_Statements!$C$2:$C$73,"FY2024") | C28: =SUMIFS(Raw_Statements!$D$2:$D$73,Raw_Statements!$B$2:$B$73,"Long-term borrowings",Raw_Statements!$C$2:$C$73,"FY2025") | D28: =SUMIFS(Raw_Statements!$D$2:$D$73,Raw_Statements!$B$2:$B$73,"Long-term borrowings",Raw_Statements!$C$2:$C$73,"FY2026")
A29: Share capital | B29: =SUMIFS(Raw_Statements!$D$2:$D$73,Raw_Statements!$B$2:$B$73,"Share capital",Raw_Statements!$C$2:$C$73,"FY2024") | C29: =SUMIFS(Raw_Statements!$D$2:$D$73,Raw_Statements!$B$2:$B$73,"Share capital",Raw_Statements!$C$2:$C$73,"FY2025") | D29: =SUMIFS(Raw_Statements!$D$2:$D$73,Raw_Statements!$B$2:$B$73,"Share capital",Raw_Statements!$C$2:$C$73,"FY2026")
A30: Retained earnings | B30: =SUMIFS(Raw_Statements!$D$2:$D$73,Raw_Statements!$B$2:$B$73,"Retained earnings",Raw_Statements!$C$2:$C$73,"FY2024") | C30: =SUMIFS(Raw_Statements!$D$2:$D$73,Raw_Statements!$B$2:$B$73,"Retained earnings",Raw_Statements!$C$2:$C$73,"FY2025") | D30: =SUMIFS(Raw_Statements!$D$2:$D$73,Raw_Statements!$B$2:$B$73,"Retained earnings",Raw_Statements!$C$2:$C$73,"FY2026")
A31: Total equity | B31: =B29+B30 | C31: =C29+C30 | D31: =D29+D30
A32: TOTAL LIABILITIES + EQUITY | B32: =B27+B28+B31 | C32: =C27+C28+C31 | D32: =D27+D28+D31
A33: Balance check (assets - L+E; must be 0) | B33: =B23-B32 | C33: =C23-C32 | D33: =D23-D32
A34: CASH FLOW (indirect)
A35: Profit after tax | B35: =B13 | C35: =C13 | D35: =D13
A36: Add: Depreciation | B36: =B8 | C36: =C8 | D36: =D8
A37: Less: increase in receivables | B37: =-(B16-SUMIFS(Raw_Statements!$D$2:$D$73,Raw_Statements!$B$2:$B$73,"Trade receivables",Raw_Statements!$C$2:$C$73,"Opening")) | C37: =-(C16-B16) | D37: =-(D16-C16)
A38: Less: increase in inventories | B38: =-(B17-SUMIFS(Raw_Statements!$D$2:$D$73,Raw_Statements!$B$2:$B$73,"Inventories",Raw_Statements!$C$2:$C$73,"Opening")) | C38: =-(C17-B17) | D38: =-(D17-C17)
A39: Add: increase in payables | B39: =+(B24-SUMIFS(Raw_Statements!$D$2:$D$73,Raw_Statements!$B$2:$B$73,"Trade payables",Raw_Statements!$C$2:$C$73,"Opening")) | C39: =+(C24-B24) | D39: =+(D24-C24)
A40: Working capital: other current items | B40: =-(B18-SUMIFS(Raw_Statements!$D$2:$D$73,Raw_Statements!$B$2:$B$73,"Other current assets",Raw_Statements!$C$2:$C$73,"Opening"))++(B26-SUMIFS(Raw_Statements!$D$2:$D$73,Raw_Statements!$B$2:$B$73,"Other current liabilities",Raw_Statements!$C$2:$C$73,"Opening")) | C40: =-(C18-B18)++(C26-B26) | D40: =-(D18-C18)++(D26-C26)
...

Sheet Ratios
A1: Ratio | B1: FY2024 | C1: FY2025 | D1: FY2026 | E1: Benchmark | F1: FY2026 status
A2: Current ratio (CA / CL) | B2: =Statements!B19/Statements!B27 | C2: =Statements!C19/Statements!C27 | D2: =Statements!D19/Statements!D27 | E2: 1.5 | F2: =IF(D2>=E2,"OK","FLAG")
A3: Quick ratio ((CA - inventory) / CL) | B3: =(Statements!B19-Statements!B17)/Statements!B27 | C3: =(Statements!C19-Statements!C17)/Statements!C27 | D3: =(Statements!D19-Statements!D17)/Statements!D27 | E3: 1 | F3: =IF(D3>=E3,"OK","FLAG")
A4: Debt-to-equity ((ST + LT debt) / equity) | B4: =(Statements!B25+Statements!B28)/Statements!B31 | C4: =(Statements!C25+Statements!C28)/Statements!C31 | D4: =(Statements!D25+Statements!D28)/Statements!D31 | E4: 1 | F4: =IF(D4<=E4,"OK","FLAG")
A5: Interest coverage (EBIT / interest) | B5: =Statements!B9/Statements!B10 | C5: =Statements!C9/Statements!C10 | D5: =Statements!D9/Statements!D10 | E5: 3 | F5: =IF(D5>=E5,"OK","FLAG")
A6: Gross margin | B6: =Statements!B5/Statements!B3 | C6: =Statements!C5/Statements!C3 | D6: =Statements!D5/Statements!D3 | E6: — | F6: —
A7: Net margin (PAT / revenue) | B7: =Statements!B13/Statements!B3 | C7: =Statements!C13/Statements!C3 | D7: =Statements!D13/Statements!D3 | E7: 0.08 | F7: =IF(D7>=E7,"OK","FLAG")
A8: Return on assets (PAT / total assets) | B8: =Statements!B13/Statements!B23 | C8: =Statements!C13/Statements!C23 | D8: =Statements!D13/Statements!D23 | E8: — | F8: —
A9: Return on equity (PAT / equity) | B9: =Statements!B13/Statements!B31 | C9: =Statements!C13/Statements!C31 | D9: =Statements!D13/Statements!D31 | E9: 0.15 | F9: =IF(D9>=E9,"OK","FLAG")
A10: Receivables days | B10: =Statements!B16/Statements!B3*365 | C10: =Statements!C16/Statements!C3*365 | D10: =Statements!D16/Statements!D3*365 | E10: 60 | F10: =IF(D10<=E10,"OK","FLAG")
A11: Inventory days | B11: =Statements!B17/Statements!B4*365 | C11: =Statements!C17/Statements!C4*365 | D11: =Statements!D17/Statements!D4*365 | E11: 60 | F11: =IF(D11<=E11,"OK","FLAG")
A12: Payables days | B12: =Statements!B24/Statements!B4*365 | C12: =Statements!C24/Statements!C4*365 | D12: =Statements!D24/Statements!D4*365 | E12: 45 | F12: =IF(D12<=E12,"OK","FLAG")
A13: Operating cash conversion (CFO / PAT) | B13: =Statements!B41/Statements!B13 | C13: =Statements!C41/Statements!C13 | D13: =Statements!D41/Statements!D13 | E13: 1 | F13: =IF(D13>=E13,"OK","FLAG")
A14: Working capital (CA - CL, Rs) | B14: =Statements!B19-Statements!B27 | C14: =Statements!C19-Statements!C27 | D14: =Statements!D19-Statements!D27 | E14: — | F14: —
A15: FY2026 flags (count of FLAG above) | B15: =COUNTIF(F2:F14,"FLAG")

Sheet Trend
A1: Month | B1: Revenue | C1: COGS | D1: Gross profit | E1: Opex | F1: Operating surplus | G1: Margin% | H1: Receivables | I1: Inventory | J1: Payables | K1: Working capital
A2: 2025-04 | B2: =SUMIFS(Raw_Monthly!$B$2:$B$13,Raw_Monthly!$A$2:$A$13,$A2) | C2: =SUMIFS(Raw_Monthly!$C$2:$C$13,Raw_Monthly!$A$2:$A$13,$A2) | D2: =B2-C2 | E2: =SUMIFS(Raw_Monthly!$D$2:$D$13,Raw_Monthly!$A$2:$A$13,$A2) | F2: =B2-C2-E2 | G2: =IF(B2=0,0,F2/B2) | H2: =SUMIFS(Raw_Monthly!$E$2:$E$13,Raw_Monthly!$A$2:$A$13,$A2) | I2: =SUMIFS(Raw_Monthly!$F$2:$F$13,Raw_Monthly!$A$2:$A$13,$A2) | J2: =SUMIFS(Raw_Monthly!$G$2:$G$13,Raw_Monthly!$A$2:$A$13,$A2) | K2: =H2+I2-J2
A3: 2025-05 | B3: =SUMIFS(Raw_Monthly!$B$2:$B$13,Raw_Monthly!$A$2:$A$13,$A3) | C3: =SUMIFS(Raw_Monthly!$C$2:$C$13,Raw_Monthly!$A$2:$A$13,$A3) | D3: =B3-C3 | E3: =SUMIFS(Raw_Monthly!$D$2:$D$13,Raw_Monthly!$A$2:$A$13,$A3) | F3: =B3-C3-E3 | G3: =IF(B3=0,0,F3/B3) | H3: =SUMIFS(Raw_Monthly!$E$2:$E$13,Raw_Monthly!$A$2:$A$13,$A3) | I3: =SUMIFS(Raw_Monthly!$F$2:$F$13,Raw_Monthly!$A$2:$A$13,$A3) | J3: =SUMIFS(Raw_Monthly!$G$2:$G$13,Raw_Monthly!$A$2:$A$13,$A3) | K3: =H3+I3-J3
A4: 2025-06 | B4: =SUMIFS(Raw_Monthly!$B$2:$B$13,Raw_Monthly!$A$2:$A$13,$A4) | C4: =SUMIFS(Raw_Monthly!$C$2:$C$13,Raw_Monthly!$A$2:$A$13,$A4) | D4: =B4-C4 | E4: =SUMIFS(Raw_Monthly!$D$2:$D$13,Raw_Monthly!$A$2:$A$13,$A4) | F4: =B4-C4-E4 | G4: =IF(B4=0,0,F4/B4) | H4: =SUMIFS(Raw_Monthly!$E$2:$E$13,Raw_Monthly!$A$2:$A$13,$A4) | I4: =SUMIFS(Raw_Monthly!$F$2:$F$13,Raw_Monthly!$A$2:$A$13,$A4) | J4: =SUMIFS(Raw_Monthly!$G$2:$G$13,Raw_Monthly!$A$2:$A$13,$A4) | K4: =H4+I4-J4
A5: 2025-07 | B5: =SUMIFS(Raw_Monthly!$B$2:$B$13,Raw_Monthly!$A$2:$A$13,$A5) | C5: =SUMIFS(Raw_Monthly!$C$2:$C$13,Raw_Monthly!$A$2:$A$13,$A5) | D5: =B5-C5 | E5: =SUMIFS(Raw_Monthly!$D$2:$D$13,Raw_Monthly!$A$2:$A$13,$A5) | F5: =B5-C5-E5 | G5: =IF(B5=0,0,F5/B5) | H5: =SUMIFS(Raw_Monthly!$E$2:$E$13,Raw_Monthly!$A$2:$A$13,$A5) | I5: =SUMIFS(Raw_Monthly!$F$2:$F$13,Raw_Monthly!$A$2:$A$13,$A5) | J5: =SUMIFS(Raw_Monthly!$G$2:$G$13,Raw_Monthly!$A$2:$A$13,$A5) | K5: =H5+I5-J5
A6: 2025-08 | B6: =SUMIFS(Raw_Monthly!$B$2:$B$13,Raw_Monthly!$A$2:$A$13,$A6) | C6: =SUMIFS(Raw_Monthly!$C$2:$C$13,Raw_Monthly!$A$2:$A$13,$A6) | D6: =B6-C6 | E6: =SUMIFS(Raw_Monthly!$D$2:$D$13,Raw_Monthly!$A$2:$A$13,$A6) | F6: =B6-C6-E6 | G6: =IF(B6=0,0,F6/B6) | H6: =SUMIFS(Raw_Monthly!$E$2:$E$13,Raw_Monthly!$A$2:$A$13,$A6) | I6: =SUMIFS(Raw_Monthly!$F$2:$F$13,Raw_Monthly!$A$2:$A$13,$A6) | J6: =SUMIFS(Raw_Monthly!$G$2:$G$13,Raw_Monthly!$A$2:$A$13,$A6) | K6: =H6+I6-J6
A7: 2025-09 | B7: =SUMIFS(Raw_Monthly!$B$2:$B$13,Raw_Monthly!$A$2:$A$13,$A7) | C7: =SUMIFS(Raw_Monthly!$C$2:$C$13,Raw_Monthly!$A$2:$A$13,$A7) | D7: =B7-C7 | E7: =SUMIFS(Raw_Monthly!$D$2:$D$13,Raw_Monthly!$A$2:$A$13,$A7) | F7: =B7-C7-E7 | G7: =IF(B7=0,0,F7/B7) | H7: =SUMIFS(Raw_Monthly!$E$2:$E$13,Raw_Monthly!$A$2:$A$13,$A7) | I7: =SUMIFS(Raw_Monthly!$F$2:$F$13,Raw_Monthly!$A$2:$A$13,$A7) | J7: =SUMIFS(Raw_Monthly!$G$2:$G$13,Raw_Monthly!$A$2:$A$13,$A7) | K7: =H7+I7-J7
A8: 2025-10 | B8: =SUMIFS(Raw_Monthly!$B$2:$B$13,Raw_Monthly!$A$2:$A$13,$A8) | C8: =SUMIFS(Raw_Monthly!$C$2:$C$13,Raw_Monthly!$A$2:$A$13,$A8) | D8: =B8-C8 | E8: =SUMIFS(Raw_Monthly!$D$2:$D$13,Raw_Monthly!$A$2:$A$13,$A8) | F8: =B8-C8-E8 | G8: =IF(B8=0,0,F8/B8) | H8: =SUMIFS(Raw_Monthly!$E$2:$E$13,Raw_Monthly!$A$2:$A$13,$A8) | I8: =SUMIFS(Raw_Monthly!$F$2:$F$13,Raw_Monthly!$A$2:$A$13,$A8) | J8: =SUMIFS(Raw_Monthly!$G$2:$G$13,Raw_Monthly!$A$2:$A$13,$A8) | K8: =H8+I8-J8
A9: 2025-11 | B9: =SUMIFS(Raw_Monthly!$B$2:$B$13,Raw_Monthly!$A$2:$A$13,$A9) | C9: =SUMIFS(Raw_Monthly!$C$2:$C$13,Raw_Monthly!$A$2:$A$13,$A9) | D9: =B9-C9 | E9: =SUMIFS(Raw_Monthly!$D$2:$D$13,Raw_Monthly!$A$2:$A$13,$A9) | F9: =B9-C9-E9 | G9: =IF(B9=0,0,F9/B9) | H9: =SUMIFS(Raw_Monthly!$E$2:$E$13,Raw_Monthly!$A$2:$A$13,$A9) | I9: =SUMIFS(Raw_Monthly!$F$2:$F$13,Raw_Monthly!$A$2:$A$13,$A9) | J9: =SUMIFS(Raw_Monthly!$G$2:$G$13,Raw_Monthly!$A$2:$A$13,$A9) | K9: =H9+I9-J9
A10: 2025-12 | B10: =SUMIFS(Raw_Monthly!$B$2:$B$13,Raw_Monthly!$A$2:$A$13,$A10) | C10: =SUMIFS(Raw_Monthly!$C$2:$C$13,Raw_Monthly!$A$2:$A$13,$A10) | D10: =B10-C10 | E10: =SUMIFS(Raw_Monthly!$D$2:$D$13,Raw_Monthly!$A$2:$A$13,$A10) | F10: =B10-C10-E10 | G10: =IF(B10=0,0,F10/B10) | H10: =SUMIFS(Raw_Monthly!$E$2:$E$13,Raw_Monthly!$A$2:$A$13,$A10) | I10: =SUMIFS(Raw_Monthly!$F$2:$F$13,Raw_Monthly!$A$2:$A$13,$A10) | J10: =SUMIFS(Raw_Monthly!$G$2:$G$13,Raw_Monthly!$A$2:$A$13,$A10) | K10: =H10+I10-J10
A11: 2026-01 | B11: =SUMIFS(Raw_Monthly!$B$2:$B$13,Raw_Monthly!$A$2:$A$13,$A11) | C11: =SUMIFS(Raw_Monthly!$C$2:$C$13,Raw_Monthly!$A$2:$A$13,$A11) | D11: =B11-C11 | E11: =SUMIFS(Raw_Monthly!$D$2:$D$13,Raw_Monthly!$A$2:$A$13,$A11) | F11: =B11-C11-E11 | G11: =IF(B11=0,0,F11/B11) | H11: =SUMIFS(Raw_Monthly!$E$2:$E$13,Raw_Monthly!$A$2:$A$13,$A11) | I11: =SUMIFS(Raw_Monthly!$F$2:$F$13,Raw_Monthly!$A$2:$A$13,$A11) | J11: =SUMIFS(Raw_Monthly!$G$2:$G$13,Raw_Monthly!$A$2:$A$13,$A11) | K11: =H11+I11-J11
A12: 2026-02 | B12: =SUMIFS(Raw_Monthly!$B$2:$B$13,Raw_Monthly!$A$2:$A$13,$A12) | C12: =SUMIFS(Raw_Monthly!$C$2:$C$13,Raw_Monthly!$A$2:$A$13,$A12) | D12: =B12-C12 | E12: =SUMIFS(Raw_Monthly!$D$2:$D$13,Raw_Monthly!$A$2:$A$13,$A12) | F12: =B12-C12-E12 | G12: =IF(B12=0,0,F12/B12) | H12: =SUMIFS(Raw_Monthly!$E$2:$E$13,Raw_Monthly!$A$2:$A$13,$A12) | I12: =SUMIFS(Raw_Monthly!$F$2:$F$13,Raw_Monthly!$A$2:$A$13,$A12) | J12: =SUMIFS(Raw_Monthly!$G$2:$G$13,Raw_Monthly!$A$2:$A$13,$A12) | K12: =H12+I12-J12
A13: 2026-03 | B13: =SUMIFS(Raw_Monthly!$B$2:$B$13,Raw_Monthly!$A$2:$A$13,$A13) | C13: =SUMIFS(Raw_Monthly!$C$2:$C$13,Raw_Monthly!$A$2:$A$13,$A13) | D13: =B13-C13 | E13: =SUMIFS(Raw_Monthly!$D$2:$D$13,Raw_Monthly!$A$2:$A$13,$A13) | F13: =B13-C13-E13 | G13: =IF(B13=0,0,F13/B13) | H13: =SUMIFS(Raw_Monthly!$E$2:$E$13,Raw_Monthly!$A$2:$A$13,$A13) | I13: =SUMIFS(Raw_Monthly!$F$2:$F$13,Raw_Monthly!$A$2:$A$13,$A13) | J13: =SUMIFS(Raw_Monthly!$G$2:$G$13,Raw_Monthly!$A$2:$A$13,$A13) | K13: =H13+I13-J13
A14: TOTAL / Mar-26 | B14: =SUM(B2:B13) | C14: =SUM(C2:C13) | D14: =SUM(D2:D13) | E14: =SUM(E2:E13) | F14: =SUM(F2:F13) | G14: =IF(B14=0,0,F14/B14) | H14: =H13 | I14: =I13 | J14: =J13 | K14: =K13

Sheet Checks
A1: Check | B1: Result
A2: Balance sheet balances, FY2024 | B2: =ABS(Statements!B33)<1
A3: Balance sheet balances, FY2025 | B3: =ABS(Statements!C33)<1
A4: Balance sheet balances, FY2026 | B4: =ABS(Statements!D33)<1
A5: Cash-flow closing cash = balance-sheet cash, FY2024 | B5: =ABS(Statements!B49)<1
A6: Cash-flow closing cash = balance-sheet cash, FY2025 | B6: =ABS(Statements!C49)<1
A7: Cash-flow closing cash = balance-sheet cash, FY2026 | B7: =ABS(Statements!D49)<1
A8: Monthly revenue total = FY2026 revenue | B8: =ABS(Trend!B14-Statements!D3)<1
A9: Retained earnings roll-forward, FY2026 | B9: =ABS(Statements!D30-(Statements!C30+Statements!D35-SUMIFS(Raw_Statements!$D$2:$D$73,Raw_Statements!$B$2:$B$73,"Dividends paid",Raw_Statements!$C$2:$C$73,"FY2026")))<1
