Workbook

Sheet Guide
A1: CollectionPulse — Payment Collections Tracker
A3: As-of date (all DPD maths anchor here): | B3: 46315
A5: Sheet | B5: What it holds
A6: Raw_Schedule | B6: One row per scheduled EMI due (read-only source data)
A7: Raw_Payments | B7: One row per actual receipt (read-only source data)
A8: Receivables_Ledger | B8: Per-due ledger: paid, outstanding, status, DPD, bucket — all formulas
A9: Aging | B9: Outstanding by DPD bucket (COLLECTED / 1-30 / 31-60 / 61-90 / 90+)
A10: Collector_Scorecard | B10: Per-collector efficiency, overdue load, avg DPD, rank
A11: FollowUp | B11: Auto-built action list: every overdue due with severity + next-action date
A12: Dashboard | B12: 8 KPIs + 3 native charts (monthly efficiency, aging, collectors)
A13: AI_Report | B13: Rule-based narrative summary + 8 status flags
A14: Checks | B14: 8 integrity checks — all must read TRUE
A16: How to refresh: paste new dues into Raw_Schedule and receipts into Raw_Payments,
A17: extend the Receivables_Ledger formulas down, and every sheet recalculates.
A19: Demo data is fictional (seeded generator). Replace with real exports to go live.

Sheet Raw_Schedule
A1: DueID | B1: Account | C1: Borrower | D1: Branch | E1: Collector | F1: LoanType | G1: DueDate | H1: DueAmount
A2: D0001 | B2: A0001 | C2: Mohan Rai | D2: Muzaffarpur | E2: S. Gupta | F2: Personal | G2: 46117 | H2: 5833
A3: D0002 | B3: A0001 | C3: Mohan Rai | D3: Muzaffarpur | E3: S. Gupta | F3: Personal | G3: 46147 | H3: 5833
A4: D0003 | B4: A0001 | C4: Mohan Rai | D4: Muzaffarpur | E4: S. Gupta | F4: Personal | G4: 46178 | H4: 5833
A5: D0004 | B5: A0001 | C5: Mohan Rai | D5: Muzaffarpur | E5: S. Gupta | F5: Personal | G5: 46208 | H5: 5833
A6: D0005 | B6: A0001 | C6: Mohan Rai | D6: Muzaffarpur | E6: S. Gupta | F6: Personal | G6: 46239 | H6: 5833
A7: D0006 | B7: A0001 | C7: Mohan Rai | D7: Muzaffarpur | E7: S. Gupta | F7: Personal | G7: 46270 | H7: 5833
A8: D0007 | B8: A0002 | C8: Naresh Yadav | D8: Darbhanga | E8: S. Gupta | F8: Trade | G8: 46117 | H8: 5333
A9: D0008 | B9: A0002 | C9: Naresh Yadav | D9: Darbhanga | E9: S. Gupta | F9: Trade | G9: 46147 | H9: 5333
A10: D0009 | B10: A0002 | C10: Naresh Yadav | D10: Darbhanga | E10: S. Gupta | F10: Trade | G10: 46178 | H10: 5333
A11: D0010 | B11: A0002 | C11: Naresh Yadav | D11: Darbhanga | E11: S. Gupta | F11: Trade | G11: 46208 | H11: 5333
A12: D0011 | B12: A0002 | C12: Naresh Yadav | D12: Darbhanga | E12: S. Gupta | F12: Trade | G12: 46239 | H12: 5333
A13: D0012 | B13: A0002 | C13: Naresh Yadav | D13: Darbhanga | E13: S. Gupta | F13: Trade | G13: 46270 | H13: 5333
... A1201: D1200 | B1201: A0200 | C1201: Manoj Kumar | D1201: Patna | E1201: M. Mandal | F1201: Trade | G1201: 46270 | H1201: 13667

Sheet Raw_Payments
A1: PaymentID | B1: DueID | C1: Account | D1: PayDate | E1: Amount | F1: Mode
A2: P00001 | B2: D0001 | C2: A0001 | D2: 46152 | E2: 5833 | F2: Cash
A3: P00002 | B3: D0002 | C3: A0001 | D3: 46159 | E3: 5833 | F3: Cash
A4: P00003 | B4: D0003 | C4: A0001 | D4: 46189 | E4: 5833 | F4: NEFT
A5: P00004 | B5: D0004 | C5: A0001 | D5: 46234 | E5: 5833 | F5: Cash
A6: P00005 | B6: D0005 | C6: A0001 | D6: 46251 | E6: 5833 | F6: Cash
A7: P00006 | B7: D0006 | C7: A0001 | D7: 46293 | E7: 5833 | F7: UPI
A8: P00007 | B8: D0007 | C8: A0002 | D8: 46114 | E8: 5333 | F8: NEFT
A9: P00008 | B9: D0008 | C9: A0002 | D9: 46147 | E9: 5333 | F9: Cash
A10: P00009 | B10: D0009 | C10: A0002 | D10: 46177 | E10: 5333 | F10: Cash
A11: P00010 | B11: D0010 | C11: A0002 | D11: 46211 | E11: 5333 | F11: Cash
A12: P00011 | B12: D0011 | C12: A0002 | D12: 46241 | E12: 5333 | F12: UPI
A13: P00012 | B13: D0012 | C13: A0002 | D13: 46269 | E13: 5333 | F13: Cash
... A1079: P01078 | B1079: D1200 | C1079: A0200 | D1079: 46281 | E1079: 13667 | F1079: UPI

Sheet Receivables_Ledger
A1: DueID | B1: Account | C1: Borrower | D1: Branch | E1: Collector | F1: LoanType | G1: DueDate | H1: DueAmount | I1: PaidTotal | J1: Outstanding | K1: Status | L1: LastPayDate | M1: DaysOverdue | N1: Bucket | O1: Severity | P1: RowKey
A2: D0001 | B2: =INDEX(Raw_Schedule!B:B,MATCH(A2,Raw_Schedule!A:A,0)) | C2: =INDEX(Raw_Schedule!C:C,MATCH(A2,Raw_Schedule!A:A,0)) | D2: =INDEX(Raw_Schedule!D:D,MATCH(A2,Raw_Schedule!A:A,0)) | E2: =INDEX(Raw_Schedule!E:E,MATCH(A2,Raw_Schedule!A:A,0)) | F2: =INDEX(Raw_Schedule!F:F,MATCH(A2,Raw_Schedule!A:A,0)) | G2: =INDEX(Raw_Schedule!G:G,MATCH(A2,Raw_Schedule!A:A,0)) | H2: =INDEX(Raw_Schedule!H:H,MATCH(A2,Raw_Schedule!A:A,0)) | I2: =SUMIFS(Raw_Payments!E:E,Raw_Payments!B:B,A2) | J2: =H2-I2 | K2: =IF(J2<=0.005,"PAID",IF(I2>0,"PARTIAL","OVERDUE")) | L2: =IF(COUNTIFS(Raw_Payments!B:B,A2)=0,"",SUMPRODUCT(MAX((Raw_Payments!B$2:B$1079=A2)*Raw_Payments!D$2:D$1079))) | M2: =IF(K2="PAID",MAX(0,L2-G2),Guide!$B$3-G2) | N2: =IF(J2<=0.005,"COLLECTED",IF(M2<=30,"1-30",IF(M2<=60,"31-60",IF(M2<=90,"61-90","90+")))) | O2: =IF(N2="90+","LOST",IF(N2="61-90","ESCALATE",IF(N2="31-60","WATCH",IF(N2="1-30","MILD","OK")))) | P2: =IF(J2>0.005,ROW()-1,"")
A3: D0002 | B3: =INDEX(Raw_Schedule!B:B,MATCH(A3,Raw_Schedule!A:A,0)) | C3: =INDEX(Raw_Schedule!C:C,MATCH(A3,Raw_Schedule!A:A,0)) | D3: =INDEX(Raw_Schedule!D:D,MATCH(A3,Raw_Schedule!A:A,0)) | E3: =INDEX(Raw_Schedule!E:E,MATCH(A3,Raw_Schedule!A:A,0)) | F3: =INDEX(Raw_Schedule!F:F,MATCH(A3,Raw_Schedule!A:A,0)) | G3: =INDEX(Raw_Schedule!G:G,MATCH(A3,Raw_Schedule!A:A,0)) | H3: =INDEX(Raw_Schedule!H:H,MATCH(A3,Raw_Schedule!A:A,0)) | I3: =SUMIFS(Raw_Payments!E:E,Raw_Payments!B:B,A3) | J3: =H3-I3 | K3: =IF(J3<=0.005,"PAID",IF(I3>0,"PARTIAL","OVERDUE")) | L3: =IF(COUNTIFS(Raw_Payments!B:B,A3)=0,"",SUMPRODUCT(MAX((Raw_Payments!B$2:B$1079=A3)*Raw_Payments!D$2:D$1079))) | M3: =IF(K3="PAID",MAX(0,L3-G3),Guide!$B$3-G3) | N3: =IF(J3<=0.005,"COLLECTED",IF(M3<=30,"1-30",IF(M3<=60,"31-60",IF(M3<=90,"61-90","90+")))) | O3: =IF(N3="90+","LOST",IF(N3="61-90","ESCALATE",IF(N3="31-60","WATCH",IF(N3="1-30","MILD","OK")))) | P3: =IF(J3>0.005,ROW()-1,"")
A4: D0003 | B4: =INDEX(Raw_Schedule!B:B,MATCH(A4,Raw_Schedule!A:A,0)) | C4: =INDEX(Raw_Schedule!C:C,MATCH(A4,Raw_Schedule!A:A,0)) | D4: =INDEX(Raw_Schedule!D:D,MATCH(A4,Raw_Schedule!A:A,0)) | E4: =INDEX(Raw_Schedule!E:E,MATCH(A4,Raw_Schedule!A:A,0)) | F4: =INDEX(Raw_Schedule!F:F,MATCH(A4,Raw_Schedule!A:A,0)) | G4: =INDEX(Raw_Schedule!G:G,MATCH(A4,Raw_Schedule!A:A,0)) | H4: =INDEX(Raw_Schedule!H:H,MATCH(A4,Raw_Schedule!A:A,0)) | I4: =SUMIFS(Raw_Payments!E:E,Raw_Payments!B:B,A4) | J4: =H4-I4 | K4: =IF(J4<=0.005,"PAID",IF(I4>0,"PARTIAL","OVERDUE")) | L4: =IF(COUNTIFS(Raw_Payments!B:B,A4)=0,"",SUMPRODUCT(MAX((Raw_Payments!B$2:B$1079=A4)*Raw_Payments!D$2:D$1079))) | M4: =IF(K4="PAID",MAX(0,L4-G4),Guide!$B$3-G4) | N4: =IF(J4<=0.005,"COLLECTED",IF(M4<=30,"1-30",IF(M4<=60,"31-60",IF(M4<=90,"61-90","90+")))) | O4: =IF(N4="90+","LOST",IF(N4="61-90","ESCALATE",IF(N4="31-60","WATCH",IF(N4="1-30","MILD","OK")))) | P4: =IF(J4>0.005,ROW()-1,"")
A5: D0004 | B5: =INDEX(Raw_Schedule!B:B,MATCH(A5,Raw_Schedule!A:A,0)) | C5: =INDEX(Raw_Schedule!C:C,MATCH(A5,Raw_Schedule!A:A,0)) | D5: =INDEX(Raw_Schedule!D:D,MATCH(A5,Raw_Schedule!A:A,0)) | E5: =INDEX(Raw_Schedule!E:E,MATCH(A5,Raw_Schedule!A:A,0)) | F5: =INDEX(Raw_Schedule!F:F,MATCH(A5,Raw_Schedule!A:A,0)) | G5: =INDEX(Raw_Schedule!G:G,MATCH(A5,Raw_Schedule!A:A,0)) | H5: =INDEX(Raw_Schedule!H:H,MATCH(A5,Raw_Schedule!A:A,0)) | I5: =SUMIFS(Raw_Payments!E:E,Raw_Payments!B:B,A5) | J5: =H5-I5 | K5: =IF(J5<=0.005,"PAID",IF(I5>0,"PARTIAL","OVERDUE")) | L5: =IF(COUNTIFS(Raw_Payments!B:B,A5)=0,"",SUMPRODUCT(MAX((Raw_Payments!B$2:B$1079=A5)*Raw_Payments!D$2:D$1079))) | M5: =IF(K5="PAID",MAX(0,L5-G5),Guide!$B$3-G5) | N5: =IF(J5<=0.005,"COLLECTED",IF(M5<=30,"1-30",IF(M5<=60,"31-60",IF(M5<=90,"61-90","90+")))) | O5: =IF(N5="90+","LOST",IF(N5="61-90","ESCALATE",IF(N5="31-60","WATCH",IF(N5="1-30","MILD","OK")))) | P5: =IF(J5>0.005,ROW()-1,"")
A6: D0005 | B6: =INDEX(Raw_Schedule!B:B,MATCH(A6,Raw_Schedule!A:A,0)) | C6: =INDEX(Raw_Schedule!C:C,MATCH(A6,Raw_Schedule!A:A,0)) | D6: =INDEX(Raw_Schedule!D:D,MATCH(A6,Raw_Schedule!A:A,0)) | E6: =INDEX(Raw_Schedule!E:E,MATCH(A6,Raw_Schedule!A:A,0)) | F6: =INDEX(Raw_Schedule!F:F,MATCH(A6,Raw_Schedule!A:A,0)) | G6: =INDEX(Raw_Schedule!G:G,MATCH(A6,Raw_Schedule!A:A,0)) | H6: =INDEX(Raw_Schedule!H:H,MATCH(A6,Raw_Schedule!A:A,0)) | I6: =SUMIFS(Raw_Payments!E:E,Raw_Payments!B:B,A6) | J6: =H6-I6 | K6: =IF(J6<=0.005,"PAID",IF(I6>0,"PARTIAL","OVERDUE")) | L6: =IF(COUNTIFS(Raw_Payments!B:B,A6)=0,"",SUMPRODUCT(MAX((Raw_Payments!B$2:B$1079=A6)*Raw_Payments!D$2:D$1079))) | M6: =IF(K6="PAID",MAX(0,L6-G6),Guide!$B$3-G6) | N6: =IF(J6<=0.005,"COLLECTED",IF(M6<=30,"1-30",IF(M6<=60,"31-60",IF(M6<=90,"61-90","90+")))) | O6: =IF(N6="90+","LOST",IF(N6="61-90","ESCALATE",IF(N6="31-60","WATCH",IF(N6="1-30","MILD","OK")))) | P6: =IF(J6>0.005,ROW()-1,"")
A7: D0006 | B7: =INDEX(Raw_Schedule!B:B,MATCH(A7,Raw_Schedule!A:A,0)) | C7: =INDEX(Raw_Schedule!C:C,MATCH(A7,Raw_Schedule!A:A,0)) | D7: =INDEX(Raw_Schedule!D:D,MATCH(A7,Raw_Schedule!A:A,0)) | E7: =INDEX(Raw_Schedule!E:E,MATCH(A7,Raw_Schedule!A:A,0)) | F7: =INDEX(Raw_Schedule!F:F,MATCH(A7,Raw_Schedule!A:A,0)) | G7: =INDEX(Raw_Schedule!G:G,MATCH(A7,Raw_Schedule!A:A,0)) | H7: =INDEX(Raw_Schedule!H:H,MATCH(A7,Raw_Schedule!A:A,0)) | I7: =SUMIFS(Raw_Payments!E:E,Raw_Payments!B:B,A7) | J7: =H7-I7 | K7: =IF(J7<=0.005,"PAID",IF(I7>0,"PARTIAL","OVERDUE")) | L7: =IF(COUNTIFS(Raw_Payments!B:B,A7)=0,"",SUMPRODUCT(MAX((Raw_Payments!B$2:B$1079=A7)*Raw_Payments!D$2:D$1079))) | M7: =IF(K7="PAID",MAX(0,L7-G7),Guide!$B$3-G7) | N7: =IF(J7<=0.005,"COLLECTED",IF(M7<=30,"1-30",IF(M7<=60,"31-60",IF(M7<=90,"61-90","90+")))) | O7: =IF(N7="90+","LOST",IF(N7="61-90","ESCALATE",IF(N7="31-60","WATCH",IF(N7="1-30","MILD","OK")))) | P7: =IF(J7>0.005,ROW()-1,"")
A8: D0007 | B8: =INDEX(Raw_Schedule!B:B,MATCH(A8,Raw_Schedule!A:A,0)) | C8: =INDEX(Raw_Schedule!C:C,MATCH(A8,Raw_Schedule!A:A,0)) | D8: =INDEX(Raw_Schedule!D:D,MATCH(A8,Raw_Schedule!A:A,0)) | E8: =INDEX(Raw_Schedule!E:E,MATCH(A8,Raw_Schedule!A:A,0)) | F8: =INDEX(Raw_Schedule!F:F,MATCH(A8,Raw_Schedule!A:A,0)) | G8: =INDEX(Raw_Schedule!G:G,MATCH(A8,Raw_Schedule!A:A,0)) | H8: =INDEX(Raw_Schedule!H:H,MATCH(A8,Raw_Schedule!A:A,0)) | I8: =SUMIFS(Raw_Payments!E:E,Raw_Payments!B:B,A8) | J8: =H8-I8 | K8: =IF(J8<=0.005,"PAID",IF(I8>0,"PARTIAL","OVERDUE")) | L8: =IF(COUNTIFS(Raw_Payments!B:B,A8)=0,"",SUMPRODUCT(MAX((Raw_Payments!B$2:B$1079=A8)*Raw_Payments!D$2:D$1079))) | M8: =IF(K8="PAID",MAX(0,L8-G8),Guide!$B$3-G8) | N8: =IF(J8<=0.005,"COLLECTED",IF(M8<=30,"1-30",IF(M8<=60,"31-60",IF(M8<=90,"61-90","90+")))) | O8: =IF(N8="90+","LOST",IF(N8="61-90","ESCALATE",IF(N8="31-60","WATCH",IF(N8="1-30","MILD","OK")))) | P8: =IF(J8>0.005,ROW()-1,"")
A9: D0008 | B9: =INDEX(Raw_Schedule!B:B,MATCH(A9,Raw_Schedule!A:A,0)) | C9: =INDEX(Raw_Schedule!C:C,MATCH(A9,Raw_Schedule!A:A,0)) | D9: =INDEX(Raw_Schedule!D:D,MATCH(A9,Raw_Schedule!A:A,0)) | E9: =INDEX(Raw_Schedule!E:E,MATCH(A9,Raw_Schedule!A:A,0)) | F9: =INDEX(Raw_Schedule!F:F,MATCH(A9,Raw_Schedule!A:A,0)) | G9: =INDEX(Raw_Schedule!G:G,MATCH(A9,Raw_Schedule!A:A,0)) | H9: =INDEX(Raw_Schedule!H:H,MATCH(A9,Raw_Schedule!A:A,0)) | I9: =SUMIFS(Raw_Payments!E:E,Raw_Payments!B:B,A9) | J9: =H9-I9 | K9: =IF(J9<=0.005,"PAID",IF(I9>0,"PARTIAL","OVERDUE")) | L9: =IF(COUNTIFS(Raw_Payments!B:B,A9)=0,"",SUMPRODUCT(MAX((Raw_Payments!B$2:B$1079=A9)*Raw_Payments!D$2:D$1079))) | M9: =IF(K9="PAID",MAX(0,L9-G9),Guide!$B$3-G9) | N9: =IF(J9<=0.005,"COLLECTED",IF(M9<=30,"1-30",IF(M9<=60,"31-60",IF(M9<=90,"61-90","90+")))) | O9: =IF(N9="90+","LOST",IF(N9="61-90","ESCALATE",IF(N9="31-60","WATCH",IF(N9="1-30","MILD","OK")))) | P9: =IF(J9>0.005,ROW()-1,"")
A10: D0009 | B10: =INDEX(Raw_Schedule!B:B,MATCH(A10,Raw_Schedule!A:A,0)) | C10: =INDEX(Raw_Schedule!C:C,MATCH(A10,Raw_Schedule!A:A,0)) | D10: =INDEX(Raw_Schedule!D:D,MATCH(A10,Raw_Schedule!A:A,0)) | E10: =INDEX(Raw_Schedule!E:E,MATCH(A10,Raw_Schedule!A:A,0)) | F10: =INDEX(Raw_Schedule!F:F,MATCH(A10,Raw_Schedule!A:A,0)) | G10: =INDEX(Raw_Schedule!G:G,MATCH(A10,Raw_Schedule!A:A,0)) | H10: =INDEX(Raw_Schedule!H:H,MATCH(A10,Raw_Schedule!A:A,0)) | I10: =SUMIFS(Raw_Payments!E:E,Raw_Payments!B:B,A10) | J10: =H10-I10 | K10: =IF(J10<=0.005,"PAID",IF(I10>0,"PARTIAL","OVERDUE")) | L10: =IF(COUNTIFS(Raw_Payments!B:B,A10)=0,"",SUMPRODUCT(MAX((Raw_Payments!B$2:B$1079=A10)*Raw_Payments!D$2:D$1079))) | M10: =IF(K10="PAID",MAX(0,L10-G10),Guide!$B$3-G10) | N10: =IF(J10<=0.005,"COLLECTED",IF(M10<=30,"1-30",IF(M10<=60,"31-60",IF(M10<=90,"61-90","90+")))) | O10: =IF(N10="90+","LOST",IF(N10="61-90","ESCALATE",IF(N10="31-60","WATCH",IF(N10="1-30","MILD","OK")))) | P10: =IF(J10>0.005,ROW()-1,"")
A11: D0010 | B11: =INDEX(Raw_Schedule!B:B,MATCH(A11,Raw_Schedule!A:A,0)) | C11: =INDEX(Raw_Schedule!C:C,MATCH(A11,Raw_Schedule!A:A,0)) | D11: =INDEX(Raw_Schedule!D:D,MATCH(A11,Raw_Schedule!A:A,0)) | E11: =INDEX(Raw_Schedule!E:E,MATCH(A11,Raw_Schedule!A:A,0)) | F11: =INDEX(Raw_Schedule!F:F,MATCH(A11,Raw_Schedule!A:A,0)) | G11: =INDEX(Raw_Schedule!G:G,MATCH(A11,Raw_Schedule!A:A,0)) | H11: =INDEX(Raw_Schedule!H:H,MATCH(A11,Raw_Schedule!A:A,0)) | I11: =SUMIFS(Raw_Payments!E:E,Raw_Payments!B:B,A11) | J11: =H11-I11 | K11: =IF(J11<=0.005,"PAID",IF(I11>0,"PARTIAL","OVERDUE")) | L11: =IF(COUNTIFS(Raw_Payments!B:B,A11)=0,"",SUMPRODUCT(MAX((Raw_Payments!B$2:B$1079=A11)*Raw_Payments!D$2:D$1079))) | M11: =IF(K11="PAID",MAX(0,L11-G11),Guide!$B$3-G11) | N11: =IF(J11<=0.005,"COLLECTED",IF(M11<=30,"1-30",IF(M11<=60,"31-60",IF(M11<=90,"61-90","90+")))) | O11: =IF(N11="90+","LOST",IF(N11="61-90","ESCALATE",IF(N11="31-60","WATCH",IF(N11="1-30","MILD","OK")))) | P11: =IF(J11>0.005,ROW()-1,"")
A12: D0011 | B12: =INDEX(Raw_Schedule!B:B,MATCH(A12,Raw_Schedule!A:A,0)) | C12: =INDEX(Raw_Schedule!C:C,MATCH(A12,Raw_Schedule!A:A,0)) | D12: =INDEX(Raw_Schedule!D:D,MATCH(A12,Raw_Schedule!A:A,0)) | E12: =INDEX(Raw_Schedule!E:E,MATCH(A12,Raw_Schedule!A:A,0)) | F12: =INDEX(Raw_Schedule!F:F,MATCH(A12,Raw_Schedule!A:A,0)) | G12: =INDEX(Raw_Schedule!G:G,MATCH(A12,Raw_Schedule!A:A,0)) | H12: =INDEX(Raw_Schedule!H:H,MATCH(A12,Raw_Schedule!A:A,0)) | I12: =SUMIFS(Raw_Payments!E:E,Raw_Payments!B:B,A12) | J12: =H12-I12 | K12: =IF(J12<=0.005,"PAID",IF(I12>0,"PARTIAL","OVERDUE")) | L12: =IF(COUNTIFS(Raw_Payments!B:B,A12)=0,"",SUMPRODUCT(MAX((Raw_Payments!B$2:B$1079=A12)*Raw_Payments!D$2:D$1079))) | M12: =IF(K12="PAID",MAX(0,L12-G12),Guide!$B$3-G12) | N12: =IF(J12<=0.005,"COLLECTED",IF(M12<=30,"1-30",IF(M12<=60,"31-60",IF(M12<=90,"61-90","90+")))) | O12: =IF(N12="90+","LOST",IF(N12="61-90","ESCALATE",IF(N12="31-60","WATCH",IF(N12="1-30","MILD","OK")))) | P12: =IF(J12>0.005,ROW()-1,"")
A13: D0012 | B13: =INDEX(Raw_Schedule!B:B,MATCH(A13,Raw_Schedule!A:A,0)) | C13: =INDEX(Raw_Schedule!C:C,MATCH(A13,Raw_Schedule!A:A,0)) | D13: =INDEX(Raw_Schedule!D:D,MATCH(A13,Raw_Schedule!A:A,0)) | E13: =INDEX(Raw_Schedule!E:E,MATCH(A13,Raw_Schedule!A:A,0)) | F13: =INDEX(Raw_Schedule!F:F,MATCH(A13,Raw_Schedule!A:A,0)) | G13: =INDEX(Raw_Schedule!G:G,MATCH(A13,Raw_Schedule!A:A,0)) | H13: =INDEX(Raw_Schedule!H:H,MATCH(A13,Raw_Schedule!A:A,0)) | I13: =SUMIFS(Raw_Payments!E:E,Raw_Payments!B:B,A13) | J13: =H13-I13 | K13: =IF(J13<=0.005,"PAID",IF(I13>0,"PARTIAL","OVERDUE")) | L13: =IF(COUNTIFS(Raw_Payments!B:B,A13)=0,"",SUMPRODUCT(MAX((Raw_Payments!B$2:B$1079=A13)*Raw_Payments!D$2:D$1079))) | M13: =IF(K13="PAID",MAX(0,L13-G13),Guide!$B$3-G13) | N13: =IF(J13<=0.005,"COLLECTED",IF(M13<=30,"1-30",IF(M13<=60,"31-60",IF(M13<=90,"61-90","90+")))) | O13: =IF(N13="90+","LOST",IF(N13="61-90","ESCALATE",IF(N13="31-60","WATCH",IF(N13="1-30","MILD","OK")))) | P13: =IF(J13>0.005,ROW()-1,"")
... A1201: D1200 | B1201: =INDEX(Raw_Schedule!B:B,MATCH(A1201,Raw_Schedule!A:A,0)) | C1201: =INDEX(Raw_Schedule!C:C,MATCH(A1201,Raw_Schedule!A:A,0)) | D1201: =INDEX(Raw_Schedule!D:D,MATCH(A1201,Raw_Schedule!A:A,0)) | E1201: =INDEX(Raw_Schedule!E:E,MATCH(A1201,Raw_Schedule!A:A,0)) | F1201: =INDEX(Raw_Schedule!F:F,MATCH(A1201,Raw_Schedule!A:A,0)) | G1201: =INDEX(Raw_Schedule!G:G,MATCH(A1201,Raw_Schedule!A:A,0)) | H1201: =INDEX(Raw_Schedule!H:H,MATCH(A1201,Raw_Schedule!A:A,0)) | I1201: =SUMIFS(Raw_Payments!E:E,Raw_Payments!B:B,A1201) | J1201: =H1201-I1201 | K1201: =IF(J1201<=0.005,"PAID",IF(I1201>0,"PARTIAL","OVERDUE")) | L1201: =IF(COUNTIFS(Raw_Payments!B:B,A1201)=0,"",SUMPRODUCT(MAX((Raw_Payments!B$2:B$1079=A1201)*Raw_Payments!D$2:D$1079))) | M1201: =IF(K1201="PAID",MAX(0,L1201-G1201),Guide!$B$3-G1201) | N1201: =IF(J1201<=0.005,"COLLECTED",IF(M1201<=30,"1-30",IF(M1201<=60,"31-60",IF(M1201<=90,"61-90","90+")))) | O1201: =IF(N1201="90+","LOST",IF(N1201="61-90","ESCALATE",IF(N1201="31-60","WATCH",IF(N1201="1-30","MILD","OK")))) | P1201: =IF(J1201>0.005,ROW()-1,"")

Sheet Aging
A1: Bucket | B1: Dues | C1: Due (Rs) | D1: Collected (Rs) | E1: Outstanding (Rs) | F1: Collection %
A2: COLLECTED | B2: =COUNTIFS(Receivables_Ledger!N$2:N$1201,A2) | C2: =SUMIFS(Receivables_Ledger!H$2:H$1201,Receivables_Ledger!N$2:N$1201,A2) | D2: =SUMIFS(Receivables_Ledger!I$2:I$1201,Receivables_Ledger!N$2:N$1201,A2) | E2: =SUMIFS(Receivables_Ledger!J$2:J$1201,Receivables_Ledger!N$2:N$1201,A2) | F2: =IF(C2=0,0,D2/C2)
A3: 1-30 | B3: =COUNTIFS(Receivables_Ledger!N$2:N$1201,A3) | C3: =SUMIFS(Receivables_Ledger!H$2:H$1201,Receivables_Ledger!N$2:N$1201,A3) | D3: =SUMIFS(Receivables_Ledger!I$2:I$1201,Receivables_Ledger!N$2:N$1201,A3) | E3: =SUMIFS(Receivables_Ledger!J$2:J$1201,Receivables_Ledger!N$2:N$1201,A3) | F3: =IF(C3=0,0,D3/C3)
A4: 31-60 | B4: =COUNTIFS(Receivables_Ledger!N$2:N$1201,A4) | C4: =SUMIFS(Receivables_Ledger!H$2:H$1201,Receivables_Ledger!N$2:N$1201,A4) | D4: =SUMIFS(Receivables_Ledger!I$2:I$1201,Receivables_Ledger!N$2:N$1201,A4) | E4: =SUMIFS(Receivables_Ledger!J$2:J$1201,Receivables_Ledger!N$2:N$1201,A4) | F4: =IF(C4=0,0,D4/C4)
A5: 61-90 | B5: =COUNTIFS(Receivables_Ledger!N$2:N$1201,A5) | C5: =SUMIFS(Receivables_Ledger!H$2:H$1201,Receivables_Ledger!N$2:N$1201,A5) | D5: =SUMIFS(Receivables_Ledger!I$2:I$1201,Receivables_Ledger!N$2:N$1201,A5) | E5: =SUMIFS(Receivables_Ledger!J$2:J$1201,Receivables_Ledger!N$2:N$1201,A5) | F5: =IF(C5=0,0,D5/C5)
A6: 90+ | B6: =COUNTIFS(Receivables_Ledger!N$2:N$1201,A6) | C6: =SUMIFS(Receivables_Ledger!H$2:H$1201,Receivables_Ledger!N$2:N$1201,A6) | D6: =SUMIFS(Receivables_Ledger!I$2:I$1201,Receivables_Ledger!N$2:N$1201,A6) | E6: =SUMIFS(Receivables_Ledger!J$2:J$1201,Receivables_Ledger!N$2:N$1201,A6) | F6: =IF(C6=0,0,D6/C6)
A7: TOTAL | B7: =SUM(B2:B6) | C7: =SUM(C2:C6) | D7: =SUM(D2:D6) | E7: =SUM(E2:E6) | F7: =IF(C7=0,0,D7/C7)

Sheet Collector_Scorecard
A1: Collector | B1: Dues | C1: Due (Rs) | D1: Collected (Rs) | E1: Efficiency % | F1: Overdue (Rs) | G1: Avg DPD | H1: Rank
A2: A. Verma | B2: =COUNTIFS(Receivables_Ledger!E$2:E$1201,A2) | C2: =SUMIFS(Receivables_Ledger!H$2:H$1201,Receivables_Ledger!E$2:E$1201,A2) | D2: =SUMIFS(Receivables_Ledger!I$2:I$1201,Receivables_Ledger!E$2:E$1201,A2) | E2: =IF(C2=0,0,D2/C2) | F2: =SUMIFS(Receivables_Ledger!J$2:J$1201,Receivables_Ledger!E$2:E$1201,A2,Receivables_Ledger!J$2:J$1201,">0.005") | G2: =IF(COUNTIFS(Receivables_Ledger!E$2:E$1201,A2,Receivables_Ledger!J$2:J$1201,">0.005")=0,0,AVERAGEIFS(Receivables_Ledger!M$2:M$1201,Receivables_Ledger!E$2:E$1201,A2,Receivables_Ledger!J$2:J$1201,">0.005")) | H2: =RANK(E2,$E$2:$E$7)
A3: K. Sharma | B3: =COUNTIFS(Receivables_Ledger!E$2:E$1201,A3) | C3: =SUMIFS(Receivables_Ledger!H$2:H$1201,Receivables_Ledger!E$2:E$1201,A3) | D3: =SUMIFS(Receivables_Ledger!I$2:I$1201,Receivables_Ledger!E$2:E$1201,A3) | E3: =IF(C3=0,0,D3/C3) | F3: =SUMIFS(Receivables_Ledger!J$2:J$1201,Receivables_Ledger!E$2:E$1201,A3,Receivables_Ledger!J$2:J$1201,">0.005") | G3: =IF(COUNTIFS(Receivables_Ledger!E$2:E$1201,A3,Receivables_Ledger!J$2:J$1201,">0.005")=0,0,AVERAGEIFS(Receivables_Ledger!M$2:M$1201,Receivables_Ledger!E$2:E$1201,A3,Receivables_Ledger!J$2:J$1201,">0.005")) | H3: =RANK(E3,$E$2:$E$7)
A4: M. Mandal | B4: =COUNTIFS(Receivables_Ledger!E$2:E$1201,A4) | C4: =SUMIFS(Receivables_Ledger!H$2:H$1201,Receivables_Ledger!E$2:E$1201,A4) | D4: =SUMIFS(Receivables_Ledger!I$2:I$1201,Receivables_Ledger!E$2:E$1201,A4) | E4: =IF(C4=0,0,D4/C4) | F4: =SUMIFS(Receivables_Ledger!J$2:J$1201,Receivables_Ledger!E$2:E$1201,A4,Receivables_Ledger!J$2:J$1201,">0.005") | G4: =IF(COUNTIFS(Receivables_Ledger!E$2:E$1201,A4,Receivables_Ledger!J$2:J$1201,">0.005")=0,0,AVERAGEIFS(Receivables_Ledger!M$2:M$1201,Receivables_Ledger!E$2:E$1201,A4,Receivables_Ledger!J$2:J$1201,">0.005")) | H4: =RANK(E4,$E$2:$E$7)
A5: P. Yadav | B5: =COUNTIFS(Receivables_Ledger!E$2:E$1201,A5) | C5: =SUMIFS(Receivables_Ledger!H$2:H$1201,Receivables_Ledger!E$2:E$1201,A5) | D5: =SUMIFS(Receivables_Ledger!I$2:I$1201,Receivables_Ledger!E$2:E$1201,A5) | E5: =IF(C5=0,0,D5/C5) | F5: =SUMIFS(Receivables_Ledger!J$2:J$1201,Receivables_Ledger!E$2:E$1201,A5,Receivables_Ledger!J$2:J$1201,">0.005") | G5: =IF(COUNTIFS(Receivables_Ledger!E$2:E$1201,A5,Receivables_Ledger!J$2:J$1201,">0.005")=0,0,AVERAGEIFS(Receivables_Ledger!M$2:M$1201,Receivables_Ledger!E$2:E$1201,A5,Receivables_Ledger!J$2:J$1201,">0.005")) | H5: =RANK(E5,$E$2:$E$7)
A6: R. Singh | B6: =COUNTIFS(Receivables_Ledger!E$2:E$1201,A6) | C6: =SUMIFS(Receivables_Ledger!H$2:H$1201,Receivables_Ledger!E$2:E$1201,A6) | D6: =SUMIFS(Receivables_Ledger!I$2:I$1201,Receivables_Ledger!E$2:E$1201,A6) | E6: =IF(C6=0,0,D6/C6) | F6: =SUMIFS(Receivables_Ledger!J$2:J$1201,Receivables_Ledger!E$2:E$1201,A6,Receivables_Ledger!J$2:J$1201,">0.005") | G6: =IF(COUNTIFS(Receivables_Ledger!E$2:E$1201,A6,Receivables_Ledger!J$2:J$1201,">0.005")=0,0,AVERAGEIFS(Receivables_Ledger!M$2:M$1201,Receivables_Ledger!E$2:E$1201,A6,Receivables_Ledger!J$2:J$1201,">0.005")) | H6: =RANK(E6,$E$2:$E$7)
A7: S. Gupta | B7: =COUNTIFS(Receivables_Ledger!E$2:E$1201,A7) | C7: =SUMIFS(Receivables_Ledger!H$2:H$1201,Receivables_Ledger!E$2:E$1201,A7) | D7: =SUMIFS(Receivables_Ledger!I$2:I$1201,Receivables_Ledger!E$2:E$1201,A7) | E7: =IF(C7=0,0,D7/C7) | F7: =SUMIFS(Receivables_Ledger!J$2:J$1201,Receivables_Ledger!E$2:E$1201,A7,Receivables_Ledger!J$2:J$1201,">0.005") | G7: =IF(COUNTIFS(Receivables_Ledger!E$2:E$1201,A7,Receivables_Ledger!J$2:J$1201,">0.005")=0,0,AVERAGEIFS(Receivables_Ledger!M$2:M$1201,Receivables_Ledger!E$2:E$1201,A7,Receivables_Ledger!J$2:J$1201,">0.005")) | H7: =RANK(E7,$E$2:$E$7)

Sheet FollowUp
A1: # | B1: DueID | C1: Borrower | D1: Collector | E1: Days Overdue | F1: Outstanding (Rs) | G1: Severity | H1: Next Action
A2: =ROW()-1 | B2: =INDEX(Receivables_Ledger!A$2:A$1201,SMALL(Receivables_Ledger!P$2:P$1201,1)) | C2: =INDEX(Receivables_Ledger!C$2:C$1201,SMALL(Receivables_Ledger!P$2:P$1201,1)) | D2: =INDEX(Receivables_Ledger!E$2:E$1201,SMALL(Receivables_Ledger!P$2:P$1201,1)) | E2: =INDEX(Receivables_Ledger!M$2:M$1201,SMALL(Receivables_Ledger!P$2:P$1201,1)) | F2: =INDEX(Receivables_Ledger!J$2:J$1201,SMALL(Receivables_Ledger!P$2:P$1201,1)) | G2: =IF(E2>90,"LOST",IF(E2>60,"ESCALATE",IF(E2>30,"WATCH","MILD"))) | H2: =Guide!$B$3+IF(G2="LOST",0,IF(G2="ESCALATE",1,IF(G2="WATCH",3,7)))
A3: =ROW()-1 | B3: =INDEX(Receivables_Ledger!A$2:A$1201,SMALL(Receivables_Ledger!P$2:P$1201,2)) | C3: =INDEX(Receivables_Ledger!C$2:C$1201,SMALL(Receivables_Ledger!P$2:P$1201,2)) | D3: =INDEX(Receivables_Ledger!E$2:E$1201,SMALL(Receivables_Ledger!P$2:P$1201,2)) | E3: =INDEX(Receivables_Ledger!M$2:M$1201,SMALL(Receivables_Ledger!P$2:P$1201,2)) | F3: =INDEX(Receivables_Ledger!J$2:J$1201,SMALL(Receivables_Ledger!P$2:P$1201,2)) | G3: =IF(E3>90,"LOST",IF(E3>60,"ESCALATE",IF(E3>30,"WATCH","MILD"))) | H3: =Guide!$B$3+IF(G3="LOST",0,IF(G3="ESCALATE",1,IF(G3="WATCH",3,7)))
A4: =ROW()-1 | B4: =INDEX(Receivables_Ledger!A$2:A$1201,SMALL(Receivables_Ledger!P$2:P$1201,3)) | C4: =INDEX(Receivables_Ledger!C$2:C$1201,SMALL(Receivables_Ledger!P$2:P$1201,3)) | D4: =INDEX(Receivables_Ledger!E$2:E$1201,SMALL(Receivables_Ledger!P$2:P$1201,3)) | E4: =INDEX(Receivables_Ledger!M$2:M$1201,SMALL(Receivables_Ledger!P$2:P$1201,3)) | F4: =INDEX(Receivables_Ledger!J$2:J$1201,SMALL(Receivables_Ledger!P$2:P$1201,3)) | G4: =IF(E4>90,"LOST",IF(E4>60,"ESCALATE",IF(E4>30,"WATCH","MILD"))) | H4: =Guide!$B$3+IF(G4="LOST",0,IF(G4="ESCALATE",1,IF(G4="WATCH",3,7)))
A5: =ROW()-1 | B5: =INDEX(Receivables_Ledger!A$2:A$1201,SMALL(Receivables_Ledger!P$2:P$1201,4)) | C5: =INDEX(Receivables_Ledger!C$2:C$1201,SMALL(Receivables_Ledger!P$2:P$1201,4)) | D5: =INDEX(Receivables_Ledger!E$2:E$1201,SMALL(Receivables_Ledger!P$2:P$1201,4)) | E5: =INDEX(Receivables_Ledger!M$2:M$1201,SMALL(Receivables_Ledger!P$2:P$1201,4)) | F5: =INDEX(Receivables_Ledger!J$2:J$1201,SMALL(Receivables_Ledger!P$2:P$1201,4)) | G5: =IF(E5>90,"LOST",IF(E5>60,"ESCALATE",IF(E5>30,"WATCH","MILD"))) | H5: =Guide!$B$3+IF(G5="LOST",0,IF(G5="ESCALATE",1,IF(G5="WATCH",3,7)))
A6: =ROW()-1 | B6: =INDEX(Receivables_Ledger!A$2:A$1201,SMALL(Receivables_Ledger!P$2:P$1201,5)) | C6: =INDEX(Receivables_Ledger!C$2:C$1201,SMALL(Receivables_Ledger!P$2:P$1201,5)) | D6: =INDEX(Receivables_Ledger!E$2:E$1201,SMALL(Receivables_Ledger!P$2:P$1201,5)) | E6: =INDEX(Receivables_Ledger!M$2:M$1201,SMALL(Receivables_Ledger!P$2:P$1201,5)) | F6: =INDEX(Receivables_Ledger!J$2:J$1201,SMALL(Receivables_Ledger!P$2:P$1201,5)) | G6: =IF(E6>90,"LOST",IF(E6>60,"ESCALATE",IF(E6>30,"WATCH","MILD"))) | H6: =Guide!$B$3+IF(G6="LOST",0,IF(G6="ESCALATE",1,IF(G6="WATCH",3,7)))
A7: =ROW()-1 | B7: =INDEX(Receivables_Ledger!A$2:A$1201,SMALL(Receivables_Ledger!P$2:P$1201,6)) | C7: =INDEX(Receivables_Ledger!C$2:C$1201,SMALL(Receivables_Ledger!P$2:P$1201,6)) | D7: =INDEX(Receivables_Ledger!E$2:E$1201,SMALL(Receivables_Ledger!P$2:P$1201,6)) | E7: =INDEX(Receivables_Ledger!M$2:M$1201,SMALL(Receivables_Ledger!P$2:P$1201,6)) | F7: =INDEX(Receivables_Ledger!J$2:J$1201,SMALL(Receivables_Ledger!P$2:P$1201,6)) | G7: =IF(E7>90,"LOST",IF(E7>60,"ESCALATE",IF(E7>30,"WATCH","MILD"))) | H7: =Guide!$B$3+IF(G7="LOST",0,IF(G7="ESCALATE",1,IF(G7="WATCH",3,7)))
A8: =ROW()-1 | B8: =INDEX(Receivables_Ledger!A$2:A$1201,SMALL(Receivables_Ledger!P$2:P$1201,7)) | C8: =INDEX(Receivables_Ledger!C$2:C$1201,SMALL(Receivables_Ledger!P$2:P$1201,7)) | D8: =INDEX(Receivables_Ledger!E$2:E$1201,SMALL(Receivables_Ledger!P$2:P$1201,7)) | E8: =INDEX(Receivables_Ledger!M$2:M$1201,SMALL(Receivables_Ledger!P$2:P$1201,7)) | F8: =INDEX(Receivables_Ledger!J$2:J$1201,SMALL(Receivables_Ledger!P$2:P$1201,7)) | G8: =IF(E8>90,"LOST",IF(E8>60,"ESCALATE",IF(E8>30,"WATCH","MILD"))) | H8: =Guide!$B$3+IF(G8="LOST",0,IF(G8="ESCALATE",1,IF(G8="WATCH",3,7)))
A9: =ROW()-1 | B9: =INDEX(Receivables_Ledger!A$2:A$1201,SMALL(Receivables_Ledger!P$2:P$1201,8)) | C9: =INDEX(Receivables_Ledger!C$2:C$1201,SMALL(Receivables_Ledger!P$2:P$1201,8)) | D9: =INDEX(Receivables_Ledger!E$2:E$1201,SMALL(Receivables_Ledger!P$2:P$1201,8)) | E9: =INDEX(Receivables_Ledger!M$2:M$1201,SMALL(Receivables_Ledger!P$2:P$1201,8)) | F9: =INDEX(Receivables_Ledger!J$2:J$1201,SMALL(Receivables_Ledger!P$2:P$1201,8)) | G9: =IF(E9>90,"LOST",IF(E9>60,"ESCALATE",IF(E9>30,"WATCH","MILD"))) | H9: =Guide!$B$3+IF(G9="LOST",0,IF(G9="ESCALATE",1,IF(G9="WATCH",3,7)))
A10: =ROW()-1 | B10: =INDEX(Receivables_Ledger!A$2:A$1201,SMALL(Receivables_Ledger!P$2:P$1201,9)) | C10: =INDEX(Receivables_Ledger!C$2:C$1201,SMALL(Receivables_Ledger!P$2:P$1201,9)) | D10: =INDEX(Receivables_Ledger!E$2:E$1201,SMALL(Receivables_Ledger!P$2:P$1201,9)) | E10: =INDEX(Receivables_Ledger!M$2:M$1201,SMALL(Receivables_Ledger!P$2:P$1201,9)) | F10: =INDEX(Receivables_Ledger!J$2:J$1201,SMALL(Receivables_Ledger!P$2:P$1201,9)) | G10: =IF(E10>90,"LOST",IF(E10>60,"ESCALATE",IF(E10>30,"WATCH","MILD"))) | H10: =Guide!$B$3+IF(G10="LOST",0,IF(G10="ESCALATE",1,IF(G10="WATCH",3,7)))
A11: =ROW()-1 | B11: =INDEX(Receivables_Ledger!A$2:A$1201,SMALL(Receivables_Ledger!P$2:P$1201,10)) | C11: =INDEX(Receivables_Ledger!C$2:C$1201,SMALL(Receivables_Ledger!P$2:P$1201,10)) | D11: =INDEX(Receivables_Ledger!E$2:E$1201,SMALL(Receivables_Ledger!P$2:P$1201,10)) | E11: =INDEX(Receivables_Ledger!M$2:M$1201,SMALL(Receivables_Ledger!P$2:P$1201,10)) | F11: =INDEX(Receivables_Ledger!J$2:J$1201,SMALL(Receivables_Ledger!P$2:P$1201,10)) | G11: =IF(E11>90,"LOST",IF(E11>60,"ESCALATE",IF(E11>30,"WATCH","MILD"))) | H11: =Guide!$B$3+IF(G11="LOST",0,IF(G11="ESCALATE",1,IF(G11="WATCH",3,7)))
A12: =ROW()-1 | B12: =INDEX(Receivables_Ledger!A$2:A$1201,SMALL(Receivables_Ledger!P$2:P$1201,11)) | C12: =INDEX(Receivables_Ledger!C$2:C$1201,SMALL(Receivables_Ledger!P$2:P$1201,11)) | D12: =INDEX(Receivables_Ledger!E$2:E$1201,SMALL(Receivables_Ledger!P$2:P$1201,11)) | E12: =INDEX(Receivables_Ledger!M$2:M$1201,SMALL(Receivables_Ledger!P$2:P$1201,11)) | F12: =INDEX(Receivables_Ledger!J$2:J$1201,SMALL(Receivables_Ledger!P$2:P$1201,11)) | G12: =IF(E12>90,"LOST",IF(E12>60,"ESCALATE",IF(E12>30,"WATCH","MILD"))) | H12: =Guide!$B$3+IF(G12="LOST",0,IF(G12="ESCALATE",1,IF(G12="WATCH",3,7)))
A13: =ROW()-1 | B13: =INDEX(Receivables_Ledger!A$2:A$1201,SMALL(Receivables_Ledger!P$2:P$1201,12)) | C13: =INDEX(Receivables_Ledger!C$2:C$1201,SMALL(Receivables_Ledger!P$2:P$1201,12)) | D13: =INDEX(Receivables_Ledger!E$2:E$1201,SMALL(Receivables_Ledger!P$2:P$1201,12)) | E13: =INDEX(Receivables_Ledger!M$2:M$1201,SMALL(Receivables_Ledger!P$2:P$1201,12)) | F13: =INDEX(Receivables_Ledger!J$2:J$1201,SMALL(Receivables_Ledger!P$2:P$1201,12)) | G13: =IF(E13>90,"LOST",IF(E13>60,"ESCALATE",IF(E13>30,"WATCH","MILD"))) | H13: =Guide!$B$3+IF(G13="LOST",0,IF(G13="ESCALATE",1,IF(G13="WATCH",3,7)))
A14: =ROW()-1 | B14: =INDEX(Receivables_Ledger!A$2:A$1201,SMALL(Receivables_Ledger!P$2:P$1201,13)) | C14: =INDEX(Receivables_Ledger!C$2:C$1201,SMALL(Receivables_Ledger!P$2:P$1201,13)) | D14: =INDEX(Receivables_Ledger!E$2:E$1201,SMALL(Receivables_Ledger!P$2:P$1201,13)) | E14: =INDEX(Receivables_Ledger!M$2:M$1201,SMALL(Receivables_Ledger!P$2:P$1201,13)) | F14: =INDEX(Receivables_Ledger!J$2:J$1201,SMALL(Receivables_Ledger!P$2:P$1201,13)) | G14: =IF(E14>90,"LOST",IF(E14>60,"ESCALATE",IF(E14>30,"WATCH","MILD"))) | H14: =Guide!$B$3+IF(G14="LOST",0,IF(G14="ESCALATE",1,IF(G14="WATCH",3,7)))
A15: =ROW()-1 | B15: =INDEX(Receivables_Ledger!A$2:A$1201,SMALL(Receivables_Ledger!P$2:P$1201,14)) | C15: =INDEX(Receivables_Ledger!C$2:C$1201,SMALL(Receivables_Ledger!P$2:P$1201,14)) | D15: =INDEX(Receivables_Ledger!E$2:E$1201,SMALL(Receivables_Ledger!P$2:P$1201,14)) | E15: =INDEX(Receivables_Ledger!M$2:M$1201,SMALL(Receivables_Ledger!P$2:P$1201,14)) | F15: =INDEX(Receivables_Ledger!J$2:J$1201,SMALL(Receivables_Ledger!P$2:P$1201,14)) | G15: =IF(E15>90,"LOST",IF(E15>60,"ESCALATE",IF(E15>30,"WATCH","MILD"))) | H15: =Guide!$B$3+IF(G15="LOST",0,IF(G15="ESCALATE",1,IF(G15="WATCH",3,7)))
A16: =ROW()-1 | B16: =INDEX(Receivables_Ledger!A$2:A$1201,SMALL(Receivables_Ledger!P$2:P$1201,15)) | C16: =INDEX(Receivables_Ledger!C$2:C$1201,SMALL(Receivables_Ledger!P$2:P$1201,15)) | D16: =INDEX(Receivables_Ledger!E$2:E$1201,SMALL(Receivables_Ledger!P$2:P$1201,15)) | E16: =INDEX(Receivables_Ledger!M$2:M$1201,SMALL(Receivables_Ledger!P$2:P$1201,15)) | F16: =INDEX(Receivables_Ledger!J$2:J$1201,SMALL(Receivables_Ledger!P$2:P$1201,15)) | G16: =IF(E16>90,"LOST",IF(E16>60,"ESCALATE",IF(E16>30,"WATCH","MILD"))) | H16: =Guide!$B$3+IF(G16="LOST",0,IF(G16="ESCALATE",1,IF(G16="WATCH",3,7)))
A17: =ROW()-1 | B17: =INDEX(Receivables_Ledger!A$2:A$1201,SMALL(Receivables_Ledger!P$2:P$1201,16)) | C17: =INDEX(Receivables_Ledger!C$2:C$1201,SMALL(Receivables_Ledger!P$2:P$1201,16)) | D17: =INDEX(Receivables_Ledger!E$2:E$1201,SMALL(Receivables_Ledger!P$2:P$1201,16)) | E17: =INDEX(Receivables_Ledger!M$2:M$1201,SMALL(Receivables_Ledger!P$2:P$1201,16)) | F17: =INDEX(Receivables_Ledger!J$2:J$1201,SMALL(Receivables_Ledger!P$2:P$1201,16)) | G17: =IF(E17>90,"LOST",IF(E17>60,"ESCALATE",IF(E17>30,"WATCH","MILD"))) | H17: =Guide!$B$3+IF(G17="LOST",0,IF(G17="ESCALATE",1,IF(G17="WATCH",3,7)))
A18: =ROW()-1 | B18: =INDEX(Receivables_Ledger!A$2:A$1201,SMALL(Receivables_Ledger!P$2:P$1201,17)) | C18: =INDEX(Receivables_Ledger!C$2:C$1201,SMALL(Receivables_Ledger!P$2:P$1201,17)) | D18: =INDEX(Receivables_Ledger!E$2:E$1201,SMALL(Receivables_Ledger!P$2:P$1201,17)) | E18: =INDEX(Receivables_Ledger!M$2:M$1201,SMALL(Receivables_Ledger!P$2:P$1201,17)) | F18: =INDEX(Receivables_Ledger!J$2:J$1201,SMALL(Receivables_Ledger!P$2:P$1201,17)) | G18: =IF(E18>90,"LOST",IF(E18>60,"ESCALATE",IF(E18>30,"WATCH","MILD"))) | H18: =Guide!$B$3+IF(G18="LOST",0,IF(G18="ESCALATE",1,IF(G18="WATCH",3,7)))
A19: =ROW()-1 | B19: =INDEX(Receivables_Ledger!A$2:A$1201,SMALL(Receivables_Ledger!P$2:P$1201,18)) | C19: =INDEX(Receivables_Ledger!C$2:C$1201,SMALL(Receivables_Ledger!P$2:P$1201,18)) | D19: =INDEX(Receivables_Ledger!E$2:E$1201,SMALL(Receivables_Ledger!P$2:P$1201,18)) | E19: =INDEX(Receivables_Ledger!M$2:M$1201,SMALL(Receivables_Ledger!P$2:P$1201,18)) | F19: =INDEX(Receivables_Ledger!J$2:J$1201,SMALL(Receivables_Ledger!P$2:P$1201,18)) | G19: =IF(E19>90,"LOST",IF(E19>60,"ESCALATE",IF(E19>30,"WATCH","MILD"))) | H19: =Guide!$B$3+IF(G19="LOST",0,IF(G19="ESCALATE",1,IF(G19="WATCH",3,7)))
A20: =ROW()-1 | B20: =INDEX(Receivables_Ledger!A$2:A$1201,SMALL(Receivables_Ledger!P$2:P$1201,19)) | C20: =INDEX(Receivables_Ledger!C$2:C$1201,SMALL(Receivables_Ledger!P$2:P$1201,19)) | D20: =INDEX(Receivables_Ledger!E$2:E$1201,SMALL(Receivables_Ledger!P$2:P$1201,19)) | E20: =INDEX(Receivables_Ledger!M$2:M$1201,SMALL(Receivables_Ledger!P$2:P$1201,19)) | F20: =INDEX(Receivables_Ledger!J$2:J$1201,SMALL(Receivables_Ledger!P$2:P$1201,19)) | G20: =IF(E20>90,"LOST",IF(E20>60,"ESCALATE",IF(E20>30,"WATCH","MILD"))) | H20: =Guide!$B$3+IF(G20="LOST",0,IF(G20="ESCALATE",1,IF(G20="WATCH",3,7)))
A21: =ROW()-1 | B21: =INDEX(Receivables_Ledger!A$2:A$1201,SMALL(Receivables_Ledger!P$2:P$1201,20)) | C21: =INDEX(Receivables_Ledger!C$2:C$1201,SMALL(Receivables_Ledger!P$2:P$1201,20)) | D21: =INDEX(Receivables_Ledger!E$2:E$1201,SMALL(Receivables_Ledger!P$2:P$1201,20)) | E21: =INDEX(Receivables_Ledger!M$2:M$1201,SMALL(Receivables_Ledger!P$2:P$1201,20)) | F21: =INDEX(Receivables_Ledger!J$2:J$1201,SMALL(Receivables_Ledger!P$2:P$1201,20)) | G21: =IF(E21>90,"LOST",IF(E21>60,"ESCALATE",IF(E21>30,"WATCH","MILD"))) | H21: =Guide!$B$3+IF(G21="LOST",0,IF(G21="ESCALATE",1,IF(G21="WATCH",3,7)))
A22: =ROW()-1 | B22: =INDEX(Receivables_Ledger!A$2:A$1201,SMALL(Receivables_Ledger!P$2:P$1201,21)) | C22: =INDEX(Receivables_Ledger!C$2:C$1201,SMALL(Receivables_Ledger!P$2:P$1201,21)) | D22: =INDEX(Receivables_Ledger!E$2:E$1201,SMALL(Receivables_Ledger!P$2:P$1201,21)) | E22: =INDEX(Receivables_Ledger!M$2:M$1201,SMALL(Receivables_Ledger!P$2:P$1201,21)) | F22: =INDEX(Receivables_Ledger!J$2:J$1201,SMALL(Receivables_Ledger!P$2:P$1201,21)) | G22: =IF(E22>90,"LOST",IF(E22>60,"ESCALATE",IF(E22>30,"WATCH","MILD"))) | H22: =Guide!$B$3+IF(G22="LOST",0,IF(G22="ESCALATE",1,IF(G22="WATCH",3,7)))
A23: =ROW()-1 | B23: =INDEX(Receivables_Ledger!A$2:A$1201,SMALL(Receivables_Ledger!P$2:P$1201,22)) | C23: =INDEX(Receivables_Ledger!C$2:C$1201,SMALL(Receivables_Ledger!P$2:P$1201,22)) | D23: =INDEX(Receivables_Ledger!E$2:E$1201,SMALL(Receivables_Ledger!P$2:P$1201,22)) | E23: =INDEX(Receivables_Ledger!M$2:M$1201,SMALL(Receivables_Ledger!P$2:P$1201,22)) | F23: =INDEX(Receivables_Ledger!J$2:J$1201,SMALL(Receivables_Ledger!P$2:P$1201,22)) | G23: =IF(E23>90,"LOST",IF(E23>60,"ESCALATE",IF(E23>30,"WATCH","MILD"))) | H23: =Guide!$B$3+IF(G23="LOST",0,IF(G23="ESCALATE",1,IF(G23="WATCH",3,7)))
A24: =ROW()-1 | B24: =INDEX(Receivables_Ledger!A$2:A$1201,SMALL(Receivables_Ledger!P$2:P$1201,23)) | C24: =INDEX(Receivables_Ledger!C$2:C$1201,SMALL(Receivables_Ledger!P$2:P$1201,23)) | D24: =INDEX(Receivables_Ledger!E$2:E$1201,SMALL(Receivables_Ledger!P$2:P$1201,23)) | E24: =INDEX(Receivables_Ledger!M$2:M$1201,SMALL(Receivables_Ledger!P$2:P$1201,23)) | F24: =INDEX(Receivables_Ledger!J$2:J$1201,SMALL(Receivables_Ledger!P$2:P$1201,23)) | G24: =IF(E24>90,"LOST",IF(E24>60,"ESCALATE",IF(E24>30,"WATCH","MILD"))) | H24: =Guide!$B$3+IF(G24="LOST",0,IF(G24="ESCALATE",1,IF(G24="WATCH",3,7)))
A25: =ROW()-1 | B25: =INDEX(Receivables_Ledger!A$2:A$1201,SMALL(Receivables_Ledger!P$2:P$1201,24)) | C25: =INDEX(Receivables_Ledger!C$2:C$1201,SMALL(Receivables_Ledger!P$2:P$1201,24)) | D25: =INDEX(Receivables_Ledger!E$2:E$1201,SMALL(Receivables_Ledger!P$2:P$1201,24)) | E25: =INDEX(Receivables_Ledger!M$2:M$1201,SMALL(Receivables_Ledger!P$2:P$1201,24)) | F25: =INDEX(Receivables_Ledger!J$2:J$1201,SMALL(Receivables_Ledger!P$2:P$1201,24)) | G25: =IF(E25>90,"LOST",IF(E25>60,"ESCALATE",IF(E25>30,"WATCH","MILD"))) | H25: =Guide!$B$3+IF(G25="LOST",0,IF(G25="ESCALATE",1,IF(G25="WATCH",3,7)))
A26: =ROW()-1 | B26: =INDEX(Receivables_Ledger!A$2:A$1201,SMALL(Receivables_Ledger!P$2:P$1201,25)) | C26: =INDEX(Receivables_Ledger!C$2:C$1201,SMALL(Receivables_Ledger!P$2:P$1201,25)) | D26: =INDEX(Receivables_Ledger!E$2:E$1201,SMALL(Receivables_Ledger!P$2:P$1201,25)) | E26: =INDEX(Receivables_Ledger!M$2:M$1201,SMALL(Receivables_Ledger!P$2:P$1201,25)) | F26: =INDEX(Receivables_Ledger!J$2:J$1201,SMALL(Receivables_Ledger!P$2:P$1201,25)) | G26: =IF(E26>90,"LOST",IF(E26>60,"ESCALATE",IF(E26>30,"WATCH","MILD"))) | H26: =Guide!$B$3+IF(G26="LOST",0,IF(G26="ESCALATE",1,IF(G26="WATCH",3,7)))
A27: =ROW()-1 | B27: =INDEX(Receivables_Ledger!A$2:A$1201,SMALL(Receivables_Ledger!P$2:P$1201,26)) | C27: =INDEX(Receivables_Ledger!C$2:C$1201,SMALL(Receivables_Ledger!P$2:P$1201,26)) | D27: =INDEX(Receivables_Ledger!E$2:E$1201,SMALL(Receivables_Ledger!P$2:P$1201,26)) | E27: =INDEX(Receivables_Ledger!M$2:M$1201,SMALL(Receivables_Ledger!P$2:P$1201,26)) | F27: =INDEX(Receivables_Ledger!J$2:J$1201,SMALL(Receivables_Ledger!P$2:P$1201,26)) | G27: =IF(E27>90,"LOST",IF(E27>60,"ESCALATE",IF(E27>30,"WATCH","MILD"))) | H27: =Guide!$B$3+IF(G27="LOST",0,IF(G27="ESCALATE",1,IF(G27="WATCH",3,7)))
A28: =ROW()-1 | B28: =INDEX(Receivables_Ledger!A$2:A$1201,SMALL(Receivables_Ledger!P$2:P$1201,27)) | C28: =INDEX(Receivables_Ledger!C$2:C$1201,SMALL(Receivables_Ledger!P$2:P$1201,27)) | D28: =INDEX(Receivables_Ledger!E$2:E$1201,SMALL(Receivables_Ledger!P$2:P$1201,27)) | E28: =INDEX(Receivables_Ledger!M$2:M$1201,SMALL(Receivables_Ledger!P$2:P$1201,27)) | F28: =INDEX(Receivables_Ledger!J$2:J$1201,SMALL(Receivables_Ledger!P$2:P$1201,27)) | G28: =IF(E28>90,"LOST",IF(E28>60,"ESCALATE",IF(E28>30,"WATCH","MILD"))) | H28: =Guide!$B$3+IF(G28="LOST",0,IF(G28="ESCALATE",1,IF(G28="WATCH",3,7)))
A29: =ROW()-1 | B29: =INDEX(Receivables_Ledger!A$2:A$1201,SMALL(Receivables_Ledger!P$2:P$1201,28)) | C29: =INDEX(Receivables_Ledger!C$2:C$1201,SMALL(Receivables_Ledger!P$2:P$1201,28)) | D29: =INDEX(Receivables_Ledger!E$2:E$1201,SMALL(Receivables_Ledger!P$2:P$1201,28)) | E29: =INDEX(Receivables_Ledger!M$2:M$1201,SMALL(Receivables_Ledger!P$2:P$1201,28)) | F29: =INDEX(Receivables_Ledger!J$2:J$1201,SMALL(Receivables_Ledger!P$2:P$1201,28)) | G29: =IF(E29>90,"LOST",IF(E29>60,"ESCALATE",IF(E29>30,"WATCH","MILD"))) | H29: =Guide!$B$3+IF(G29="LOST",0,IF(G29="ESCALATE",1,IF(G29="WATCH",3,7)))
A30: =ROW()-1 | B30: =INDEX(Receivables_Ledger!A$2:A$1201,SMALL(Receivables_Ledger!P$2:P$1201,29)) | C30: =INDEX(Receivables_Ledger!C$2:C$1201,SMALL(Receivables_Ledger!P$2:P$1201,29)) | D30: =INDEX(Receivables_Ledger!E$2:E$1201,SMALL(Receivables_Ledger!P$2:P$1201,29)) | E30: =INDEX(Receivables_Ledger!M$2:M$1201,SMALL(Receivables_Ledger!P$2:P$1201,29)) | F30: =INDEX(Receivables_Ledger!J$2:J$1201,SMALL(Receivables_Ledger!P$2:P$1201,29)) | G30: =IF(E30>90,"LOST",IF(E30>60,"ESCALATE",IF(E30>30,"WATCH","MILD"))) | H30: =Guide!$B$3+IF(G30="LOST",0,IF(G30="ESCALATE",1,IF(G30="WATCH",3,7)))
A31: =ROW()-1 | B31: =INDEX(Receivables_Ledger!A$2:A$1201,SMALL(Receivables_Ledger!P$2:P$1201,30)) | C31: =INDEX(Receivables_Ledger!C$2:C$1201,SMALL(Receivables_Ledger!P$2:P$1201,30)) | D31: =INDEX(Receivables_Ledger!E$2:E$1201,SMALL(Receivables_Ledger!P$2:P$1201,30)) | E31: =INDEX(Receivables_Ledger!M$2:M$1201,SMALL(Receivables_Ledger!P$2:P$1201,30)) | F31: =INDEX(Receivables_Ledger!J$2:J$1201,SMALL(Receivables_Ledger!P$2:P$1201,30)) | G31: =IF(E31>90,"LOST",IF(E31>60,"ESCALATE",IF(E31>30,"WATCH","MILD"))) | H31: =Guide!$B$3+IF(G31="LOST",0,IF(G31="ESCALATE",1,IF(G31="WATCH",3,7)))
A32: =ROW()-1 | B32: =INDEX(Receivables_Ledger!A$2:A$1201,SMALL(Receivables_Ledger!P$2:P$1201,31)) | C32: =INDEX(Receivables_Ledger!C$2:C$1201,SMALL(Receivables_Ledger!P$2:P$1201,31)) | D32: =INDEX(Receivables_Ledger!E$2:E$1201,SMALL(Receivables_Ledger!P$2:P$1201,31)) | E32: =INDEX(Receivables_Ledger!M$2:M$1201,SMALL(Receivables_Ledger!P$2:P$1201,31)) | F32: =INDEX(Receivables_Ledger!J$2:J$1201,SMALL(Receivables_Ledger!P$2:P$1201,31)) | G32: =IF(E32>90,"LOST",IF(E32>60,"ESCALATE",IF(E32>30,"WATCH","MILD"))) | H32: =Guide!$B$3+IF(G32="LOST",0,IF(G32="ESCALATE",1,IF(G32="WATCH",3,7)))
A33: =ROW()-1 | B33: =INDEX(Receivables_Ledger!A$2:A$1201,SMALL(Receivables_Ledger!P$2:P$1201,32)) | C33: =INDEX(Receivables_Ledger!C$2:C$1201,SMALL(Receivables_Ledger!P$2:P$1201,32)) | D33: =INDEX(Receivables_Ledger!E$2:E$1201,SMALL(Receivables_Ledger!P$2:P$1201,32)) | E33: =INDEX(Receivables_Ledger!M$2:M$1201,SMALL(Receivables_Ledger!P$2:P$1201,32)) | F33: =INDEX(Receivables_Ledger!J$2:J$1201,SMALL(Receivables_Ledger!P$2:P$1201,32)) | G33: =IF(E33>90,"LOST",IF(E33>60,"ESCALATE",IF(E33>30,"WATCH","MILD"))) | H33: =Guide!$B$3+IF(G33="LOST",0,IF(G33="ESCALATE",1,IF(G33="WATCH",3,7)))
A34: =ROW()-1 | B34: =INDEX(Receivables_Ledger!A$2:A$1201,SMALL(Receivables_Ledger!P$2:P$1201,33)) | C34: =INDEX(Receivables_Ledger!C$2:C$1201,SMALL(Receivables_Ledger!P$2:P$1201,33)) | D34: =INDEX(Receivables_Ledger!E$2:E$1201,SMALL(Receivables_Ledger!P$2:P$1201,33)) | E34: =INDEX(Receivables_Ledger!M$2:M$1201,SMALL(Receivables_Ledger!P$2:P$1201,33)) | F34: =INDEX(Receivables_Ledger!J$2:J$1201,SMALL(Receivables_Ledger!P$2:P$1201,33)) | G34: =IF(E34>90,"LOST",IF(E34>60,"ESCALATE",IF(E34>30,"WATCH","MILD"))) | H34: =Guide!$B$3+IF(G34="LOST",0,IF(G34="ESCALATE",1,IF(G34="WATCH",3,7)))
A35: =ROW()-1 | B35: =INDEX(Receivables_Ledger!A$2:A$1201,SMALL(Receivables_Ledger!P$2:P$1201,34)) | C35: =INDEX(Receivables_Ledger!C$2:C$1201,SMALL(Receivables_Ledger!P$2:P$1201,34)) | D35: =INDEX(Receivables_Ledger!E$2:E$1201,SMALL(Receivables_Ledger!P$2:P$1201,34)) | E35: =INDEX(Receivables_Ledger!M$2:M$1201,SMALL(Receivables_Ledger!P$2:P$1201,34)) | F35: =INDEX(Receivables_Ledger!J$2:J$1201,SMALL(Receivables_Ledger!P$2:P$1201,34)) | G35: =IF(E35>90,"LOST",IF(E35>60,"ESCALATE",IF(E35>30,"WATCH","MILD"))) | H35: =Guide!$B$3+IF(G35="LOST",0,IF(G35="ESCALATE",1,IF(G35="WATCH",3,7)))
A36: =ROW()-1 | B36: =INDEX(Receivables_Ledger!A$2:A$1201,SMALL(Receivables_Ledger!P$2:P$1201,35)) | C36: =INDEX(Receivables_Ledger!C$2:C$1201,SMALL(Receivables_Ledger!P$2:P$1201,35)) | D36: =INDEX(Receivables_Ledger!E$2:E$1201,SMALL(Receivables_Ledger!P$2:P$1201,35)) | E36: =INDEX(Receivables_Ledger!M$2:M$1201,SMALL(Receivables_Ledger!P$2:P$1201,35)) | F36: =INDEX(Receivables_Ledger!J$2:J$1201,SMALL(Receivables_Ledger!P$2:P$1201,35)) | G36: =IF(E36>90,"LOST",IF(E36>60,"ESCALATE",IF(E36>30,"WATCH","MILD"))) | H36: =Guide!$B$3+IF(G36="LOST",0,IF(G36="ESCALATE",1,IF(G36="WATCH",3,7)))
A37: =ROW()-1 | B37: =INDEX(Receivables_Ledger!A$2:A$1201,SMALL(Receivables_Ledger!P$2:P$1201,36)) | C37: =INDEX(Receivables_Ledger!C$2:C$1201,SMALL(Receivables_Ledger!P$2:P$1201,36)) | D37: =INDEX(Receivables_Ledger!E$2:E$1201,SMALL(Receivables_Ledger!P$2:P$1201,36)) | E37: =INDEX(Receivables_Ledger!M$2:M$1201,SMALL(Receivables_Ledger!P$2:P$1201,36)) | F37: =INDEX(Receivables_Ledger!J$2:J$1201,SMALL(Receivables_Ledger!P$2:P$1201,36)) | G37: =IF(E37>90,"LOST",IF(E37>60,"ESCALATE",IF(E37>30,"WATCH","MILD"))) | H37: =Guide!$B$3+IF(G37="LOST",0,IF(G37="ESCALATE",1,IF(G37="WATCH",3,7)))
A38: =ROW()-1 | B38: =INDEX(Receivables_Ledger!A$2:A$1201,SMALL(Receivables_Ledger!P$2:P$1201,37)) | C38: =INDEX(Receivables_Ledger!C$2:C$1201,SMALL(Receivables_Ledger!P$2:P$1201,37)) | D38: =INDEX(Receivables_Ledger!E$2:E$1201,SMALL(Receivables_Ledger!P$2:P$1201,37)) | E38: =INDEX(Receivables_Ledger!M$2:M$1201,SMALL(Receivables_Ledger!P$2:P$1201,37)) | F38: =INDEX(Receivables_Ledger!J$2:J$1201,SMALL(Receivables_Ledger!P$2:P$1201,37)) | G38: =IF(E38>90,"LOST",IF(E38>60,"ESCALATE",IF(E38>30,"WATCH","MILD"))) | H38: =Guide!$B$3+IF(G38="LOST",0,IF(G38="ESCALATE",1,IF(G38="WATCH",3,7)))
A39: =ROW()-1 | B39: =INDEX(Receivables_Ledger!A$2:A$1201,SMALL(Receivables_Ledger!P$2:P$1201,38)) | C39: =INDEX(Receivables_Ledger!C$2:C$1201,SMALL(Receivables_Ledger!P$2:P$1201,38)) | D39: =INDEX(Receivables_Ledger!E$2:E$1201,SMALL(Receivables_Ledger!P$2:P$1201,38)) | E39: =INDEX(Receivables_Ledger!M$2:M$1201,SMALL(Receivables_Ledger!P$2:P$1201,38)) | F39: =INDEX(Receivables_Ledger!J$2:J$1201,SMALL(Receivables_Ledger!P$2:P$1201,38)) | G39: =IF(E39>90,"LOST",IF(E39>60,"ESCALATE",IF(E39>30,"WATCH","MILD"))) | H39: =Guide!$B$3+IF(G39="LOST",0,IF(G39="ESCALATE",1,IF(G39="WATCH",3,7)))
A40: =ROW()-1 | B40: =INDEX(Receivables_Ledger!A$2:A$1201,SMALL(Receivables_Ledger!P$2:P$1201,39)) | C40: =INDEX(Receivables_Ledger!C$2:C$1201,SMALL(Receivables_Ledger!P$2:P$1201,39)) | D40: =INDEX(Receivables_Ledger!E$2:E$1201,SMALL(Receivables_Ledger!P$2:P$1201,39)) | E40: =INDEX(Receivables_Ledger!M$2:M$1201,SMALL(Receivables_Ledger!P$2:P$1201,39)) | F40: =INDEX(Receivables_Ledger!J$2:J$1201,SMALL(Receivables_Ledger!P$2:P$1201,39)) | G40: =IF(E40>90,"LOST",IF(E40>60,"ESCALATE",IF(E40>30,"WATCH","MILD"))) | H40: =Guide!$B$3+IF(G40="LOST",0,IF(G40="ESCALATE",1,IF(G40="WATCH",3,7)))
...

Sheet Dashboard
A1: CollectionPulse — Collections Dashboard
A2: KPI | B2: Value
A3: Total dues (Rs) | B3: =SUM(Raw_Schedule!H:H)
A4: Collected (Rs) | B4: =SUM(Raw_Payments!E:E)
A5: Collection % | B5: =B4/B3
A6: Overdue outstanding (Rs) | B6: =SUMIFS(Receivables_Ledger!J2:J1201,Receivables_Ledger!J2:J1201,">0.005")
A7: Overdue dues | B7: =COUNTIF(Receivables_Ledger!J2:J1201,">0.005")
A8: Avg DPD (overdue) | B8: =AVERAGEIFS(Receivables_Ledger!M2:M1201,Receivables_Ledger!J2:J1201,">0.005")
A9: Best collector | B9: =INDEX(Collector_Scorecard!A:A,MATCH(MAX(Collector_Scorecard!E:E),Collector_Scorecard!E:E,0))
A10: Worst collector | B10: =INDEX(Collector_Scorecard!A:A,MATCH(MIN(Collector_Scorecard!E:E),Collector_Scorecard!E:E,0))
A13: Month | B13: Due (Rs) | C13: Collected (Rs) | D13: Efficiency %
A14: Apr-26 | B14: =SUMIFS(Raw_Schedule!H:H,Raw_Schedule!G:G,">="&DATE(2026,4,1),Raw_Schedule!G:G,"<"&DATE(2026,5,1)) | C14: =SUMIFS(Raw_Payments!E:E,Raw_Payments!D:D,">="&DATE(2026,4,1),Raw_Payments!D:D,"<"&DATE(2026,5,1)) | D14: =IF(B14=0,0,C14/B14)
A15: May-26 | B15: =SUMIFS(Raw_Schedule!H:H,Raw_Schedule!G:G,">="&DATE(2026,5,1),Raw_Schedule!G:G,"<"&DATE(2026,6,1)) | C15: =SUMIFS(Raw_Payments!E:E,Raw_Payments!D:D,">="&DATE(2026,5,1),Raw_Payments!D:D,"<"&DATE(2026,6,1)) | D15: =IF(B15=0,0,C15/B15)
A16: Jun-26 | B16: =SUMIFS(Raw_Schedule!H:H,Raw_Schedule!G:G,">="&DATE(2026,6,1),Raw_Schedule!G:G,"<"&DATE(2026,7,1)) | C16: =SUMIFS(Raw_Payments!E:E,Raw_Payments!D:D,">="&DATE(2026,6,1),Raw_Payments!D:D,"<"&DATE(2026,7,1)) | D16: =IF(B16=0,0,C16/B16)
A17: Jul-26 | B17: =SUMIFS(Raw_Schedule!H:H,Raw_Schedule!G:G,">="&DATE(2026,7,1),Raw_Schedule!G:G,"<"&DATE(2026,8,1)) | C17: =SUMIFS(Raw_Payments!E:E,Raw_Payments!D:D,">="&DATE(2026,7,1),Raw_Payments!D:D,"<"&DATE(2026,8,1)) | D17: =IF(B17=0,0,C17/B17)
A18: Aug-26 | B18: =SUMIFS(Raw_Schedule!H:H,Raw_Schedule!G:G,">="&DATE(2026,8,1),Raw_Schedule!G:G,"<"&DATE(2026,9,1)) | C18: =SUMIFS(Raw_Payments!E:E,Raw_Payments!D:D,">="&DATE(2026,8,1),Raw_Payments!D:D,"<"&DATE(2026,9,1)) | D18: =IF(B18=0,0,C18/B18)
A19: Sep-26 | B19: =SUMIFS(Raw_Schedule!H:H,Raw_Schedule!G:G,">="&DATE(2026,9,1),Raw_Schedule!G:G,"<"&DATE(2026,10,1)) | C19: =SUMIFS(Raw_Payments!E:E,Raw_Payments!D:D,">="&DATE(2026,9,1),Raw_Payments!D:D,"<"&DATE(2026,10,1)) | D19: =IF(B19=0,0,C19/B19)

Sheet AI_Report
A1: AI_Report — rule-based portfolio summary
A3: ="As of "&TEXT(Guide!$B$3,"DD MMM YYYY")&", scheduled dues total "&TEXT(Dashboard!$B$3,"""Rs ""#,##0")&", of which "&TEXT(Dashboard!$B$4,"""Rs ""#,##0")&" ("&TEXT(Dashboard!$B$5,"0.0%")&") has been collected. "&TEXT(Dashboard!$B$7,"0")&" dues are overdue with "&TEXT(Dashboard!$B$6,"""Rs ""#,##0")&" outstanding; average days overdue is "&TEXT(Dashboard!$B$8,"0")&". "&"Best collector: "&Dashboard!$B$9&"; needs coaching: "&Dashboard!$B$10&"."
A5: Flags
A6: =IF(Dashboard!$B$5>=0.9,"OK Collection rate healthy (>=90%)","!! Collection rate below 90% - tighten follow-ups")
A7: =IF(SUMIFS(Aging!$E$2:$E$6,Aging!$A$2:$A$6,"90+")/MAX(1,Aging!$E$7)>0.25,"!! 90+ DPD bucket holds >25% of outstanding - escalate","OK 90+ DPD share under control")
A8: =IF(MAX(Collector_Scorecard!$E$2:$E$7)-MIN(Collector_Scorecard!$E$2:$E$7)>0.2,"!! Collector efficiency gap >20pp - coach the bottom quartile","OK Collector efficiency spread healthy")
A9: =IF(COUNTIF(Receivables_Ledger!$K$2:$K$1201,"PARTIAL")>0,"ii "&TEXT(COUNTIF(Receivables_Ledger!$K$2:$K$1201,"PARTIAL"),"0")&" partial payments need top-up calls","OK No partial payments pending")
A10: =IF(Dashboard!$B$8>45,"!! Average DPD above 45 days - portfolio stress","OK Average DPD within tolerance")
A11: =IF(COUNTIF(FollowUp!$G$2:$G$169,"LOST")>0,"!! "&TEXT(COUNTIF(FollowUp!$G$2:$G$169,"LOST"),"0")&" dues in LOST (90+ DPD) - consider write-off review","OK Nothing in 90+ DPD")
A12: =IF(COUNTIF(FollowUp!$G$2:$G$169,"ESCALATE")>10,"!! "&TEXT(COUNTIF(FollowUp!$G$2:$G$169,"ESCALATE"),"0")&" dues need escalation this week","OK Escalation queue manageable")
A13: =IF(Checks!$B$9=TRUE,"OK All 8 integrity checks pass","!! Integrity check failing - see Checks sheet")

Sheet Checks
A1: Check | B1: Result
A2: No negative outstandings | B2: =SUMPRODUCT(--(Receivables_Ledger!J2:J1201<-0.01))=0
A3: Aging due ties to schedule total | B3: =SUM(Aging!C2:C6)=SUM(Raw_Schedule!H:H)
A4: Scorecard due ties to schedule total | B4: =SUM(Collector_Scorecard!C2:C7)=SUM(Raw_Schedule!H:H)
A5: FollowUp rows = overdue dues | B5: =COUNTA(FollowUp!B2:B169)=COUNTIF(Receivables_Ledger!J2:J1201,">0.005")
A6: Ledger paid ties to payments total | B6: =SUM(Receivables_Ledger!I2:I1201)=SUM(Raw_Payments!E:E)
A7: No formula errors in ledger | B7: =SUMPRODUCT(--ISERROR(Receivables_Ledger!A2:P1201))=0
A8: Status values valid (PAID/PARTIAL/OVERDUE) | B8: =SUMPRODUCT(--(Receivables_Ledger!K2:K1201<>"PAID")*--(Receivables_Ledger!K2:K1201<>"PARTIAL")*--(Receivables_Ledger!K2:K1201<>"OVERDUE"))=0
A9: Outstanding = due - paid (global) | B9: =ABS(SUM(Receivables_Ledger!J2:J1201)-(SUM(Receivables_Ledger!H2:H1201)-SUM(Receivables_Ledger!I2:I1201)))<0.01
