Workbook

Sheet Guide
A1: QB2BI — QuickBooks data → Relational DB → Live Financial Reports
A3: What this is
A4: A working demo of the 'QuickBooks Data Integration for PowerBI' gig pattern: QuickBooks-style double-entry journals are normalised into a relational SQLite database, and this workbook renders trial balance, P&L, balance sheet, dashboard and integrity checks as LIVE Excel formulas over the raw journals — the same architecture a Power BI model would use, in a file any finance team can open.
A5: The pipeline
A6: 1. generate.py → synthesises 18 months of double-entry journals (data/*.csv) 2. build_db.py → loads them into qb2bi.sqlite (accounts + journal_lines) 3. build_workbook.py→ renders this workbook; every summary cell is a SUMIFS formula 4. tests/test_build.py → pytest suite incl. LibreOffice headless recalc vs Python ground truth
A7: How to run
A8: python3 generate.py && python3 build_db.py && python3 build_workbook.py && pytest -q
A9: Sheet map
A10: Raw_Journals every journal line + Period helper (formula) TrialBalance per-account totals via SUMIFS PL monthly P&L Apr-25..Sep-26 + YTD BalanceSheet as of Mar-26 and Sep-26, with balance check Dashboard 9 KPI cards + 3 native charts (all formula-driven) AI_Report rule-based management narrative Checks 8 automated integrity checks → all should read PASS
A11: Data note
A12: All figures are synthetic and fictional (seeded random), for demo purposes only.

Sheet Raw_Journals
A1: Date | B1: Journal | C1: Line | D1: Acct No | E1: Account | F1: Debit (₹) | G1: Credit (₹) | H1: Memo | I1: Party | J1: Period
A2: 45748 | B2: J-0001 | C2: 1 | D2: 1000 | E2: Cash & Bank | F2: 800000 | G2: 0 | H2: Opening balances 01-Apr-2025 | J2: =YEAR(A2)*12+MONTH(A2)
A3: 45748 | B3: J-0001 | C3: 2 | D3: 1100 | E3: Accounts Receivable | F3: 1200000 | G3: 0 | H3: Opening balances 01-Apr-2025 | J3: =YEAR(A3)*12+MONTH(A3)
A4: 45748 | B4: J-0001 | C4: 3 | D4: 1200 | E4: Inventory | F4: 1500000 | G4: 0 | H4: Opening balances 01-Apr-2025 | J4: =YEAR(A4)*12+MONTH(A4)
A5: 45748 | B5: J-0001 | C5: 4 | D5: 1500 | E5: Equipment | F5: 1000000 | G5: 0 | H5: Opening balances 01-Apr-2025 | J5: =YEAR(A5)*12+MONTH(A5)
A6: 45748 | B6: J-0001 | C6: 5 | D6: 1510 | E6: Accumulated Depreciation | F6: 0 | G6: 300000 | H6: Opening balances 01-Apr-2025 | J6: =YEAR(A6)*12+MONTH(A6)
A7: 45748 | B7: J-0001 | C7: 6 | D7: 2000 | E7: Accounts Payable | F7: 0 | G7: 900000 | H7: Opening balances 01-Apr-2025 | J7: =YEAR(A7)*12+MONTH(A7)
A8: 45748 | B8: J-0001 | C8: 7 | D8: 3000 | E8: Owner's Capital | F8: 0 | G8: 2500000 | H8: Opening balances 01-Apr-2025 | J8: =YEAR(A8)*12+MONTH(A8)
A9: 45748 | B9: J-0001 | C9: 8 | D9: 3100 | E9: Retained Earnings | F9: 0 | G9: 800000 | H9: Opening balances 01-Apr-2025 | J9: =YEAR(A9)*12+MONTH(A9)
A10: 45750 | B10: J-0002 | C10: 1 | D10: 1000 | E10: Cash & Bank | F10: 2000000 | G10: 0 | H10: Term loan disbursed (HDFC) | J10: =YEAR(A10)*12+MONTH(A10)
A11: 45750 | B11: J-0002 | C11: 2 | D11: 2200 | E11: Term Loan | F11: 0 | G11: 2000000 | H11: Term loan disbursed (HDFC) | J11: =YEAR(A11)*12+MONTH(A11)
A12: 45756 | B12: J-0003 | C12: 1 | D12: 1100 | E12: Accounts Receivable | F12: 349494.76 | G12: 0 | H12: Sales invoice INV-202504-1 | I12: Kumari Provision Store | J12: =YEAR(A12)*12+MONTH(A12)
A13: 45756 | B13: J-0003 | C13: 2 | D13: 4000 | E13: Sales Revenue | F13: 0 | G13: 296182 | H13: Sales invoice INV-202504-1 | I13: Kumari Provision Store | J13: =YEAR(A13)*12+MONTH(A13)
A14: 45756 | B14: J-0003 | C14: 3 | D14: 2100 | E14: GST Payable | F14: 0 | G14: 53312.76 | H14: Sales invoice INV-202504-1 | I14: GST | J14: =YEAR(A14)*12+MONTH(A14)
A15: 45770 | B15: J-0004 | C15: 1 | D15: 1100 | E15: Accounts Receivable | F15: 417074.39 | G15: 0 | H15: Sales invoice INV-202504-2 | I15: Verma Kirana Mart | J15: =YEAR(A15)*12+MONTH(A15)
A16: 45770 | B16: J-0004 | C16: 2 | D16: 4000 | E16: Sales Revenue | F16: 0 | G16: 353452.87 | H16: Sales invoice INV-202504-2 | I16: Verma Kirana Mart | J16: =YEAR(A16)*12+MONTH(A16)
A17: 45770 | B17: J-0004 | C17: 3 | D17: 2100 | E17: GST Payable | F17: 0 | G17: 63621.52 | H17: Sales invoice INV-202504-2 | I17: GST | J17: =YEAR(A17)*12+MONTH(A17)
A18: 45751 | B18: J-0005 | C18: 1 | D18: 1100 | E18: Accounts Receivable | F18: 593510.11 | G18: 0 | H18: Sales invoice INV-202504-3 | I18: Maa Vaishno Stores | J18: =YEAR(A18)*12+MONTH(A18)
A19: 45751 | B19: J-0005 | C19: 2 | D19: 4000 | E19: Sales Revenue | F19: 0 | G19: 502974.67 | H19: Sales invoice INV-202504-3 | I19: Maa Vaishno Stores | J19: =YEAR(A19)*12+MONTH(A19)
A20: 45751 | B20: J-0005 | C20: 3 | D20: 2100 | E20: GST Payable | F20: 0 | G20: 90535.44 | H20: Sales invoice INV-202504-3 | I20: GST | J20: =YEAR(A20)*12+MONTH(A20)
A21: 45749 | B21: J-0006 | C21: 1 | D21: 1100 | E21: Accounts Receivable | F21: 542305.32 | G21: 0 | H21: Sales invoice INV-202504-4 | I21: Sharma General Store | J21: =YEAR(A21)*12+MONTH(A21)
A22: 45749 | B22: J-0006 | C22: 2 | D22: 4000 | E22: Sales Revenue | F22: 0 | G22: 459580.78 | H22: Sales invoice INV-202504-4 | I22: Sharma General Store | J22: =YEAR(A22)*12+MONTH(A22)
A23: 45749 | B23: J-0006 | C23: 3 | D23: 2100 | E23: GST Payable | F23: 0 | G23: 82724.54 | H23: Sales invoice INV-202504-4 | I23: GST | J23: =YEAR(A23)*12+MONTH(A23)
... A32: 45762 | B32: J-0009 | C32: 3 | D32: 2100 | E32: GST Payable | F32: 0 | G32: 89253.44 | H32: Sales invoice INV-202504-7 | I32: GST | J32: =YEAR(A32)*12+MONTH(A32)
A33: 45774 | B33: J-0010 | C33: 1 | D33: 5000 | E33: Cost of Goods Sold | F33: 1988604.7 | G33: 0 | H33: Cost of goods sold - monthly | J33: =YEAR(A33)*12+MONTH(A33)
A34: 45774 | B34: J-0010 | C34: 2 | D34: 1200 | E34: Inventory | F34: 0 | G34: 1988604.7 | H34: Cost of goods sold - monthly | J34: =YEAR(A34)*12+MONTH(A34)
A35: 45775 | B35: J-0011 | C35: 1 | D35: 1000 | E35: Cash & Bank | F35: 2926053.4 | G35: 0 | H35: Customer receipts | J35: =YEAR(A35)*12+MONTH(A35)
A36: 45775 | B36: J-0011 | C36: 2 | D36: 1100 | E36: Accounts Receivable | F36: 0 | G36: 2926053.4 | H36: Customer receipts | J36: =YEAR(A36)*12+MONTH(A36)
A37: 45763 | B37: J-0012 | C37: 1 | D37: 1200 | E37: Inventory | F37: 329087.97 | G37: 0 | H37: Purchase bill PB-202504-1 | I37: Bihar Agro Supplies | J37: =YEAR(A37)*12+MONTH(A37)
A38: 45763 | B38: J-0012 | C38: 2 | D38: 1300 | E38: GST Input Credit | F38: 59235.83 | G38: 0 | H38: Purchase bill PB-202504-1 | I38: Bihar Agro Supplies | J38: =YEAR(A38)*12+MONTH(A38)
A39: 45763 | B39: J-0012 | C39: 3 | D39: 2000 | E39: Accounts Payable | F39: 0 | G39: 388323.8 | H39: Purchase bill PB-202504-1 | I39: Bihar Agro Supplies | J39: =YEAR(A39)*12+MONTH(A39)
A40: 45756 | B40: J-0013 | C40: 1 | D40: 1200 | E40: Inventory | F40: 383826.95 | G40: 0 | H40: Purchase bill PB-202504-2 | I40: Bihar Agro Supplies | J40: =YEAR(A40)*12+MONTH(A40)
A41: 45756 | B41: J-0013 | C41: 2 | D41: 1300 | E41: GST Input Credit | F41: 69088.85 | G41: 0 | H41: Purchase bill PB-202504-2 | I41: Bihar Agro Supplies | J41: =YEAR(A41)*12+MONTH(A41)
A42: 45756 | B42: J-0013 | C42: 3 | D42: 2000 | E42: Accounts Payable | F42: 0 | G42: 452915.8 | H42: Purchase bill PB-202504-2 | I42: Bihar Agro Supplies | J42: =YEAR(A42)*12+MONTH(A42)
A43: 45753 | B43: J-0014 | C43: 1 | D43: 1200 | E43: Inventory | F43: 485015.63 | G43: 0 | H43: Purchase bill PB-202504-3 | I43: National FMCG Distributors | J43: =YEAR(A43)*12+MONTH(A43)
A44: 45753 | B44: J-0014 | C44: 2 | D44: 1300 | E44: GST Input Credit | F44: 87302.81 | G44: 0 | H44: Purchase bill PB-202504-3 | I44: National FMCG Distributors | J44: =YEAR(A44)*12+MONTH(A44)
A45: 45753 | B45: J-0014 | C45: 3 | D45: 2000 | E45: Accounts Payable | F45: 0 | G45: 572318.44 | H45: Purchase bill PB-202504-3 | I45: National FMCG Distributors | J45: =YEAR(A45)*12+MONTH(A45)
A46: 45761 | B46: J-0015 | C46: 1 | D46: 1200 | E46: Inventory | F46: 343233.45 | G46: 0 | H46: Purchase bill PB-202504-4 | I46: Hindustan Foods Ltd | J46: =YEAR(A46)*12+MONTH(A46)
A47: 45761 | B47: J-0015 | C47: 2 | D47: 1300 | E47: GST Input Credit | F47: 61782.02 | G47: 0 | H47: Purchase bill PB-202504-4 | I47: Hindustan Foods Ltd | J47: =YEAR(A47)*12+MONTH(A47)
A48: 45761 | B48: J-0015 | C48: 3 | D48: 2000 | E48: Accounts Payable | F48: 0 | G48: 405015.47 | H48: Purchase bill PB-202504-4 | I48: Hindustan Foods Ltd | J48: =YEAR(A48)*12+MONTH(A48)
...

Sheet TrialBalance
A1: TRIAL BALANCE — live SUMIFS over Raw_Journals
A3: Acct No | B3: Account | C3: Type | D3: Total Debit (₹) | E3: Total Credit (₹) | F3: Net Debit (₹) | G3: Net Credit (₹)
A4: 1000 | B4: Cash & Bank | C4: Asset | D4: =SUMIFS(Raw_Journals!$F:$F,Raw_Journals!$D:$D,$A4) | E4: =SUMIFS(Raw_Journals!$G:$G,Raw_Journals!$D:$D,$A4) | F4: =IF(D4>=E4,D4-E4,0) | G4: =IF(E4>D4,E4-D4,0)
A5: 1100 | B5: Accounts Receivable | C5: Asset | D5: =SUMIFS(Raw_Journals!$F:$F,Raw_Journals!$D:$D,$A5) | E5: =SUMIFS(Raw_Journals!$G:$G,Raw_Journals!$D:$D,$A5) | F5: =IF(D5>=E5,D5-E5,0) | G5: =IF(E5>D5,E5-D5,0)
A6: 1200 | B6: Inventory | C6: Asset | D6: =SUMIFS(Raw_Journals!$F:$F,Raw_Journals!$D:$D,$A6) | E6: =SUMIFS(Raw_Journals!$G:$G,Raw_Journals!$D:$D,$A6) | F6: =IF(D6>=E6,D6-E6,0) | G6: =IF(E6>D6,E6-D6,0)
A7: 1300 | B7: GST Input Credit | C7: Asset | D7: =SUMIFS(Raw_Journals!$F:$F,Raw_Journals!$D:$D,$A7) | E7: =SUMIFS(Raw_Journals!$G:$G,Raw_Journals!$D:$D,$A7) | F7: =IF(D7>=E7,D7-E7,0) | G7: =IF(E7>D7,E7-D7,0)
A8: 1500 | B8: Equipment | C8: Asset | D8: =SUMIFS(Raw_Journals!$F:$F,Raw_Journals!$D:$D,$A8) | E8: =SUMIFS(Raw_Journals!$G:$G,Raw_Journals!$D:$D,$A8) | F8: =IF(D8>=E8,D8-E8,0) | G8: =IF(E8>D8,E8-D8,0)
A9: 1510 | B9: Accumulated Depreciation | C9: Asset | D9: =SUMIFS(Raw_Journals!$F:$F,Raw_Journals!$D:$D,$A9) | E9: =SUMIFS(Raw_Journals!$G:$G,Raw_Journals!$D:$D,$A9) | F9: =IF(D9>=E9,D9-E9,0) | G9: =IF(E9>D9,E9-D9,0)
A10: 2000 | B10: Accounts Payable | C10: Liability | D10: =SUMIFS(Raw_Journals!$F:$F,Raw_Journals!$D:$D,$A10) | E10: =SUMIFS(Raw_Journals!$G:$G,Raw_Journals!$D:$D,$A10) | F10: =IF(D10>=E10,D10-E10,0) | G10: =IF(E10>D10,E10-D10,0)
A11: 2100 | B11: GST Payable | C11: Liability | D11: =SUMIFS(Raw_Journals!$F:$F,Raw_Journals!$D:$D,$A11) | E11: =SUMIFS(Raw_Journals!$G:$G,Raw_Journals!$D:$D,$A11) | F11: =IF(D11>=E11,D11-E11,0) | G11: =IF(E11>D11,E11-D11,0)
A12: 2200 | B12: Term Loan | C12: Liability | D12: =SUMIFS(Raw_Journals!$F:$F,Raw_Journals!$D:$D,$A12) | E12: =SUMIFS(Raw_Journals!$G:$G,Raw_Journals!$D:$D,$A12) | F12: =IF(D12>=E12,D12-E12,0) | G12: =IF(E12>D12,E12-D12,0)
A13: 3000 | B13: Owner's Capital | C13: Equity | D13: =SUMIFS(Raw_Journals!$F:$F,Raw_Journals!$D:$D,$A13) | E13: =SUMIFS(Raw_Journals!$G:$G,Raw_Journals!$D:$D,$A13) | F13: =IF(D13>=E13,D13-E13,0) | G13: =IF(E13>D13,E13-D13,0)
A14: 3100 | B14: Retained Earnings | C14: Equity | D14: =SUMIFS(Raw_Journals!$F:$F,Raw_Journals!$D:$D,$A14) | E14: =SUMIFS(Raw_Journals!$G:$G,Raw_Journals!$D:$D,$A14) | F14: =IF(D14>=E14,D14-E14,0) | G14: =IF(E14>D14,E14-D14,0)
A15: 4000 | B15: Sales Revenue | C15: Income | D15: =SUMIFS(Raw_Journals!$F:$F,Raw_Journals!$D:$D,$A15) | E15: =SUMIFS(Raw_Journals!$G:$G,Raw_Journals!$D:$D,$A15) | F15: =IF(D15>=E15,D15-E15,0) | G15: =IF(E15>D15,E15-D15,0)
... A24: 5800 | B24: Miscellaneous Expense | C24: Expense | D24: =SUMIFS(Raw_Journals!$F:$F,Raw_Journals!$D:$D,$A24) | E24: =SUMIFS(Raw_Journals!$G:$G,Raw_Journals!$D:$D,$A24) | F24: =IF(D24>=E24,D24-E24,0) | G24: =IF(E24>D24,E24-D24,0)
B25: TOTAL | D25: =SUM(D4:D24) | E25: =SUM(E4:E24) | F25: =SUM(F4:F24) | G25: =SUM(G4:G24)

Sheet PL
A1: PROFIT & LOSS — monthly, live SUMIFS over Raw_Journals (₹)
A2: Particulars | B2: Apr-25 | C2: May-25 | D2: Jun-25 | E2: Jul-25 | F2: Aug-25 | G2: Sep-25 | H2: Oct-25 | I2: Nov-25 | J2: Dec-25 | K2: Jan-26 | L2: Feb-26 | M2: Mar-26 | N2: Apr-26 | O2: May-26 | P2: Jun-26 | Q2: Jul-26 | R2: Aug-26 | S2: Sep-26 | T2: YTD
B3: 24304 | C3: 24305 | D3: 24306 | E3: 24307 | F3: 24308 | G3: 24309 | H3: 24310 | I3: 24311 | J3: 24312 | K3: 24313 | L3: 24314 | M3: 24315 | N3: 24316 | O3: 24317 | P3: 24318 | Q3: 24319 | R3: 24320 | S3: 24321
A4: Sales Revenue | B4: =SUMIFS(Raw_Journals!$G:$G,Raw_Journals!$J:$J,B$3,Raw_Journals!$D:$D,"4000")-SUMIFS(Raw_Journals!$F:$F,Raw_Journals!$J:$J,B$3,Raw_Journals!$D:$D,"4000") | C4: =SUMIFS(Raw_Journals!$G:$G,Raw_Journals!$J:$J,C$3,Raw_Journals!$D:$D,"4000")-SUMIFS(Raw_Journals!$F:$F,Raw_Journals!$J:$J,C$3,Raw_Journals!$D:$D,"4000") | D4: =SUMIFS(Raw_Journals!$G:$G,Raw_Journals!$J:$J,D$3,Raw_Journals!$D:$D,"4000")-SUMIFS(Raw_Journals!$F:$F,Raw_Journals!$J:$J,D$3,Raw_Journals!$D:$D,"4000") | E4: =SUMIFS(Raw_Journals!$G:$G,Raw_Journals!$J:$J,E$3,Raw_Journals!$D:$D,"4000")-SUMIFS(Raw_Journals!$F:$F,Raw_Journals!$J:$J,E$3,Raw_Journals!$D:$D,"4000") | F4: =SUMIFS(Raw_Journals!$G:$G,Raw_Journals!$J:$J,F$3,Raw_Journals!$D:$D,"4000")-SUMIFS(Raw_Journals!$F:$F,Raw_Journals!$J:$J,F$3,Raw_Journals!$D:$D,"4000") | G4: =SUMIFS(Raw_Journals!$G:$G,Raw_Journals!$J:$J,G$3,Raw_Journals!$D:$D,"4000")-SUMIFS(Raw_Journals!$F:$F,Raw_Journals!$J:$J,G$3,Raw_Journals!$D:$D,"4000") | H4: =SUMIFS(Raw_Journals!$G:$G,Raw_Journals!$J:$J,H$3,Raw_Journals!$D:$D,"4000")-SUMIFS(Raw_Journals!$F:$F,Raw_Journals!$J:$J,H$3,Raw_Journals!$D:$D,"4000") | I4: =SUMIFS(Raw_Journals!$G:$G,Raw_Journals!$J:$J,I$3,Raw_Journals!$D:$D,"4000")-SUMIFS(Raw_Journals!$F:$F,Raw_Journals!$J:$J,I$3,Raw_Journals!$D:$D,"4000") | ... S4: =SUMIFS(Raw_Journals!$G:$G,Raw_Journals!$J:$J,S$3,Raw_Journals!$D:$D,"4000")-SUMIFS(Raw_Journals!$F:$F,Raw_Journals!$J:$J,S$3,Raw_Journals!$D:$D,"4000") | T4: =SUM(B4:S4)
A5: Cost of Goods Sold | B5: =SUMIFS(Raw_Journals!$F:$F,Raw_Journals!$J:$J,B$3,Raw_Journals!$D:$D,"5000")-SUMIFS(Raw_Journals!$G:$G,Raw_Journals!$J:$J,B$3,Raw_Journals!$D:$D,"5000") | C5: =SUMIFS(Raw_Journals!$F:$F,Raw_Journals!$J:$J,C$3,Raw_Journals!$D:$D,"5000")-SUMIFS(Raw_Journals!$G:$G,Raw_Journals!$J:$J,C$3,Raw_Journals!$D:$D,"5000") | D5: =SUMIFS(Raw_Journals!$F:$F,Raw_Journals!$J:$J,D$3,Raw_Journals!$D:$D,"5000")-SUMIFS(Raw_Journals!$G:$G,Raw_Journals!$J:$J,D$3,Raw_Journals!$D:$D,"5000") | E5: =SUMIFS(Raw_Journals!$F:$F,Raw_Journals!$J:$J,E$3,Raw_Journals!$D:$D,"5000")-SUMIFS(Raw_Journals!$G:$G,Raw_Journals!$J:$J,E$3,Raw_Journals!$D:$D,"5000") | F5: =SUMIFS(Raw_Journals!$F:$F,Raw_Journals!$J:$J,F$3,Raw_Journals!$D:$D,"5000")-SUMIFS(Raw_Journals!$G:$G,Raw_Journals!$J:$J,F$3,Raw_Journals!$D:$D,"5000") | G5: =SUMIFS(Raw_Journals!$F:$F,Raw_Journals!$J:$J,G$3,Raw_Journals!$D:$D,"5000")-SUMIFS(Raw_Journals!$G:$G,Raw_Journals!$J:$J,G$3,Raw_Journals!$D:$D,"5000") | H5: =SUMIFS(Raw_Journals!$F:$F,Raw_Journals!$J:$J,H$3,Raw_Journals!$D:$D,"5000")-SUMIFS(Raw_Journals!$G:$G,Raw_Journals!$J:$J,H$3,Raw_Journals!$D:$D,"5000") | I5: =SUMIFS(Raw_Journals!$F:$F,Raw_Journals!$J:$J,I$3,Raw_Journals!$D:$D,"5000")-SUMIFS(Raw_Journals!$G:$G,Raw_Journals!$J:$J,I$3,Raw_Journals!$D:$D,"5000") | ... S5: =SUMIFS(Raw_Journals!$F:$F,Raw_Journals!$J:$J,S$3,Raw_Journals!$D:$D,"5000")-SUMIFS(Raw_Journals!$G:$G,Raw_Journals!$J:$J,S$3,Raw_Journals!$D:$D,"5000") | T5: =SUM(B5:S5)
A6: Gross Profit | B6: =B4-B5 | C6: =C4-C5 | D6: =D4-D5 | E6: =E4-E5 | F6: =F4-F5 | G6: =G4-G5 | H6: =H4-H5 | I6: =I4-I5 | ... S6: =S4-S5 | T6: =SUM(B6:S6)
A7: Rent Expense | B7: =SUMIFS(Raw_Journals!$F:$F,Raw_Journals!$J:$J,B$3,Raw_Journals!$D:$D,"5100")-SUMIFS(Raw_Journals!$G:$G,Raw_Journals!$J:$J,B$3,Raw_Journals!$D:$D,"5100") | C7: =SUMIFS(Raw_Journals!$F:$F,Raw_Journals!$J:$J,C$3,Raw_Journals!$D:$D,"5100")-SUMIFS(Raw_Journals!$G:$G,Raw_Journals!$J:$J,C$3,Raw_Journals!$D:$D,"5100") | D7: =SUMIFS(Raw_Journals!$F:$F,Raw_Journals!$J:$J,D$3,Raw_Journals!$D:$D,"5100")-SUMIFS(Raw_Journals!$G:$G,Raw_Journals!$J:$J,D$3,Raw_Journals!$D:$D,"5100") | E7: =SUMIFS(Raw_Journals!$F:$F,Raw_Journals!$J:$J,E$3,Raw_Journals!$D:$D,"5100")-SUMIFS(Raw_Journals!$G:$G,Raw_Journals!$J:$J,E$3,Raw_Journals!$D:$D,"5100") | F7: =SUMIFS(Raw_Journals!$F:$F,Raw_Journals!$J:$J,F$3,Raw_Journals!$D:$D,"5100")-SUMIFS(Raw_Journals!$G:$G,Raw_Journals!$J:$J,F$3,Raw_Journals!$D:$D,"5100") | G7: =SUMIFS(Raw_Journals!$F:$F,Raw_Journals!$J:$J,G$3,Raw_Journals!$D:$D,"5100")-SUMIFS(Raw_Journals!$G:$G,Raw_Journals!$J:$J,G$3,Raw_Journals!$D:$D,"5100") | H7: =SUMIFS(Raw_Journals!$F:$F,Raw_Journals!$J:$J,H$3,Raw_Journals!$D:$D,"5100")-SUMIFS(Raw_Journals!$G:$G,Raw_Journals!$J:$J,H$3,Raw_Journals!$D:$D,"5100") | I7: =SUMIFS(Raw_Journals!$F:$F,Raw_Journals!$J:$J,I$3,Raw_Journals!$D:$D,"5100")-SUMIFS(Raw_Journals!$G:$G,Raw_Journals!$J:$J,I$3,Raw_Journals!$D:$D,"5100") | ... S7: =SUMIFS(Raw_Journals!$F:$F,Raw_Journals!$J:$J,S$3,Raw_Journals!$D:$D,"5100")-SUMIFS(Raw_Journals!$G:$G,Raw_Journals!$J:$J,S$3,Raw_Journals!$D:$D,"5100") | T7: =SUM(B7:S7)
A8: Salaries Expense | B8: =SUMIFS(Raw_Journals!$F:$F,Raw_Journals!$J:$J,B$3,Raw_Journals!$D:$D,"5200")-SUMIFS(Raw_Journals!$G:$G,Raw_Journals!$J:$J,B$3,Raw_Journals!$D:$D,"5200") | C8: =SUMIFS(Raw_Journals!$F:$F,Raw_Journals!$J:$J,C$3,Raw_Journals!$D:$D,"5200")-SUMIFS(Raw_Journals!$G:$G,Raw_Journals!$J:$J,C$3,Raw_Journals!$D:$D,"5200") | D8: =SUMIFS(Raw_Journals!$F:$F,Raw_Journals!$J:$J,D$3,Raw_Journals!$D:$D,"5200")-SUMIFS(Raw_Journals!$G:$G,Raw_Journals!$J:$J,D$3,Raw_Journals!$D:$D,"5200") | E8: =SUMIFS(Raw_Journals!$F:$F,Raw_Journals!$J:$J,E$3,Raw_Journals!$D:$D,"5200")-SUMIFS(Raw_Journals!$G:$G,Raw_Journals!$J:$J,E$3,Raw_Journals!$D:$D,"5200") | F8: =SUMIFS(Raw_Journals!$F:$F,Raw_Journals!$J:$J,F$3,Raw_Journals!$D:$D,"5200")-SUMIFS(Raw_Journals!$G:$G,Raw_Journals!$J:$J,F$3,Raw_Journals!$D:$D,"5200") | G8: =SUMIFS(Raw_Journals!$F:$F,Raw_Journals!$J:$J,G$3,Raw_Journals!$D:$D,"5200")-SUMIFS(Raw_Journals!$G:$G,Raw_Journals!$J:$J,G$3,Raw_Journals!$D:$D,"5200") | H8: =SUMIFS(Raw_Journals!$F:$F,Raw_Journals!$J:$J,H$3,Raw_Journals!$D:$D,"5200")-SUMIFS(Raw_Journals!$G:$G,Raw_Journals!$J:$J,H$3,Raw_Journals!$D:$D,"5200") | I8: =SUMIFS(Raw_Journals!$F:$F,Raw_Journals!$J:$J,I$3,Raw_Journals!$D:$D,"5200")-SUMIFS(Raw_Journals!$G:$G,Raw_Journals!$J:$J,I$3,Raw_Journals!$D:$D,"5200") | ... S8: =SUMIFS(Raw_Journals!$F:$F,Raw_Journals!$J:$J,S$3,Raw_Journals!$D:$D,"5200")-SUMIFS(Raw_Journals!$G:$G,Raw_Journals!$J:$J,S$3,Raw_Journals!$D:$D,"5200") | T8: =SUM(B8:S8)
A9: Utilities Expense | B9: =SUMIFS(Raw_Journals!$F:$F,Raw_Journals!$J:$J,B$3,Raw_Journals!$D:$D,"5300")-SUMIFS(Raw_Journals!$G:$G,Raw_Journals!$J:$J,B$3,Raw_Journals!$D:$D,"5300") | C9: =SUMIFS(Raw_Journals!$F:$F,Raw_Journals!$J:$J,C$3,Raw_Journals!$D:$D,"5300")-SUMIFS(Raw_Journals!$G:$G,Raw_Journals!$J:$J,C$3,Raw_Journals!$D:$D,"5300") | D9: =SUMIFS(Raw_Journals!$F:$F,Raw_Journals!$J:$J,D$3,Raw_Journals!$D:$D,"5300")-SUMIFS(Raw_Journals!$G:$G,Raw_Journals!$J:$J,D$3,Raw_Journals!$D:$D,"5300") | E9: =SUMIFS(Raw_Journals!$F:$F,Raw_Journals!$J:$J,E$3,Raw_Journals!$D:$D,"5300")-SUMIFS(Raw_Journals!$G:$G,Raw_Journals!$J:$J,E$3,Raw_Journals!$D:$D,"5300") | F9: =SUMIFS(Raw_Journals!$F:$F,Raw_Journals!$J:$J,F$3,Raw_Journals!$D:$D,"5300")-SUMIFS(Raw_Journals!$G:$G,Raw_Journals!$J:$J,F$3,Raw_Journals!$D:$D,"5300") | G9: =SUMIFS(Raw_Journals!$F:$F,Raw_Journals!$J:$J,G$3,Raw_Journals!$D:$D,"5300")-SUMIFS(Raw_Journals!$G:$G,Raw_Journals!$J:$J,G$3,Raw_Journals!$D:$D,"5300") | H9: =SUMIFS(Raw_Journals!$F:$F,Raw_Journals!$J:$J,H$3,Raw_Journals!$D:$D,"5300")-SUMIFS(Raw_Journals!$G:$G,Raw_Journals!$J:$J,H$3,Raw_Journals!$D:$D,"5300") | I9: =SUMIFS(Raw_Journals!$F:$F,Raw_Journals!$J:$J,I$3,Raw_Journals!$D:$D,"5300")-SUMIFS(Raw_Journals!$G:$G,Raw_Journals!$J:$J,I$3,Raw_Journals!$D:$D,"5300") | ... S9: =SUMIFS(Raw_Journals!$F:$F,Raw_Journals!$J:$J,S$3,Raw_Journals!$D:$D,"5300")-SUMIFS(Raw_Journals!$G:$G,Raw_Journals!$J:$J,S$3,Raw_Journals!$D:$D,"5300") | T9: =SUM(B9:S9)
A10: Transport & Logistics | B10: =SUMIFS(Raw_Journals!$F:$F,Raw_Journals!$J:$J,B$3,Raw_Journals!$D:$D,"5400")-SUMIFS(Raw_Journals!$G:$G,Raw_Journals!$J:$J,B$3,Raw_Journals!$D:$D,"5400") | C10: =SUMIFS(Raw_Journals!$F:$F,Raw_Journals!$J:$J,C$3,Raw_Journals!$D:$D,"5400")-SUMIFS(Raw_Journals!$G:$G,Raw_Journals!$J:$J,C$3,Raw_Journals!$D:$D,"5400") | D10: =SUMIFS(Raw_Journals!$F:$F,Raw_Journals!$J:$J,D$3,Raw_Journals!$D:$D,"5400")-SUMIFS(Raw_Journals!$G:$G,Raw_Journals!$J:$J,D$3,Raw_Journals!$D:$D,"5400") | E10: =SUMIFS(Raw_Journals!$F:$F,Raw_Journals!$J:$J,E$3,Raw_Journals!$D:$D,"5400")-SUMIFS(Raw_Journals!$G:$G,Raw_Journals!$J:$J,E$3,Raw_Journals!$D:$D,"5400") | F10: =SUMIFS(Raw_Journals!$F:$F,Raw_Journals!$J:$J,F$3,Raw_Journals!$D:$D,"5400")-SUMIFS(Raw_Journals!$G:$G,Raw_Journals!$J:$J,F$3,Raw_Journals!$D:$D,"5400") | G10: =SUMIFS(Raw_Journals!$F:$F,Raw_Journals!$J:$J,G$3,Raw_Journals!$D:$D,"5400")-SUMIFS(Raw_Journals!$G:$G,Raw_Journals!$J:$J,G$3,Raw_Journals!$D:$D,"5400") | H10: =SUMIFS(Raw_Journals!$F:$F,Raw_Journals!$J:$J,H$3,Raw_Journals!$D:$D,"5400")-SUMIFS(Raw_Journals!$G:$G,Raw_Journals!$J:$J,H$3,Raw_Journals!$D:$D,"5400") | I10: =SUMIFS(Raw_Journals!$F:$F,Raw_Journals!$J:$J,I$3,Raw_Journals!$D:$D,"5400")-SUMIFS(Raw_Journals!$G:$G,Raw_Journals!$J:$J,I$3,Raw_Journals!$D:$D,"5400") | ... S10: =SUMIFS(Raw_Journals!$F:$F,Raw_Journals!$J:$J,S$3,Raw_Journals!$D:$D,"5400")-SUMIFS(Raw_Journals!$G:$G,Raw_Journals!$J:$J,S$3,Raw_Journals!$D:$D,"5400") | T10: =SUM(B10:S10)
A11: Marketing Expense | B11: =SUMIFS(Raw_Journals!$F:$F,Raw_Journals!$J:$J,B$3,Raw_Journals!$D:$D,"5500")-SUMIFS(Raw_Journals!$G:$G,Raw_Journals!$J:$J,B$3,Raw_Journals!$D:$D,"5500") | C11: =SUMIFS(Raw_Journals!$F:$F,Raw_Journals!$J:$J,C$3,Raw_Journals!$D:$D,"5500")-SUMIFS(Raw_Journals!$G:$G,Raw_Journals!$J:$J,C$3,Raw_Journals!$D:$D,"5500") | D11: =SUMIFS(Raw_Journals!$F:$F,Raw_Journals!$J:$J,D$3,Raw_Journals!$D:$D,"5500")-SUMIFS(Raw_Journals!$G:$G,Raw_Journals!$J:$J,D$3,Raw_Journals!$D:$D,"5500") | E11: =SUMIFS(Raw_Journals!$F:$F,Raw_Journals!$J:$J,E$3,Raw_Journals!$D:$D,"5500")-SUMIFS(Raw_Journals!$G:$G,Raw_Journals!$J:$J,E$3,Raw_Journals!$D:$D,"5500") | F11: =SUMIFS(Raw_Journals!$F:$F,Raw_Journals!$J:$J,F$3,Raw_Journals!$D:$D,"5500")-SUMIFS(Raw_Journals!$G:$G,Raw_Journals!$J:$J,F$3,Raw_Journals!$D:$D,"5500") | G11: =SUMIFS(Raw_Journals!$F:$F,Raw_Journals!$J:$J,G$3,Raw_Journals!$D:$D,"5500")-SUMIFS(Raw_Journals!$G:$G,Raw_Journals!$J:$J,G$3,Raw_Journals!$D:$D,"5500") | H11: =SUMIFS(Raw_Journals!$F:$F,Raw_Journals!$J:$J,H$3,Raw_Journals!$D:$D,"5500")-SUMIFS(Raw_Journals!$G:$G,Raw_Journals!$J:$J,H$3,Raw_Journals!$D:$D,"5500") | I11: =SUMIFS(Raw_Journals!$F:$F,Raw_Journals!$J:$J,I$3,Raw_Journals!$D:$D,"5500")-SUMIFS(Raw_Journals!$G:$G,Raw_Journals!$J:$J,I$3,Raw_Journals!$D:$D,"5500") | ... S11: =SUMIFS(Raw_Journals!$F:$F,Raw_Journals!$J:$J,S$3,Raw_Journals!$D:$D,"5500")-SUMIFS(Raw_Journals!$G:$G,Raw_Journals!$J:$J,S$3,Raw_Journals!$D:$D,"5500") | T11: =SUM(B11:S11)
A12: Interest Expense | B12: =SUMIFS(Raw_Journals!$F:$F,Raw_Journals!$J:$J,B$3,Raw_Journals!$D:$D,"5600")-SUMIFS(Raw_Journals!$G:$G,Raw_Journals!$J:$J,B$3,Raw_Journals!$D:$D,"5600") | C12: =SUMIFS(Raw_Journals!$F:$F,Raw_Journals!$J:$J,C$3,Raw_Journals!$D:$D,"5600")-SUMIFS(Raw_Journals!$G:$G,Raw_Journals!$J:$J,C$3,Raw_Journals!$D:$D,"5600") | D12: =SUMIFS(Raw_Journals!$F:$F,Raw_Journals!$J:$J,D$3,Raw_Journals!$D:$D,"5600")-SUMIFS(Raw_Journals!$G:$G,Raw_Journals!$J:$J,D$3,Raw_Journals!$D:$D,"5600") | E12: =SUMIFS(Raw_Journals!$F:$F,Raw_Journals!$J:$J,E$3,Raw_Journals!$D:$D,"5600")-SUMIFS(Raw_Journals!$G:$G,Raw_Journals!$J:$J,E$3,Raw_Journals!$D:$D,"5600") | F12: =SUMIFS(Raw_Journals!$F:$F,Raw_Journals!$J:$J,F$3,Raw_Journals!$D:$D,"5600")-SUMIFS(Raw_Journals!$G:$G,Raw_Journals!$J:$J,F$3,Raw_Journals!$D:$D,"5600") | G12: =SUMIFS(Raw_Journals!$F:$F,Raw_Journals!$J:$J,G$3,Raw_Journals!$D:$D,"5600")-SUMIFS(Raw_Journals!$G:$G,Raw_Journals!$J:$J,G$3,Raw_Journals!$D:$D,"5600") | H12: =SUMIFS(Raw_Journals!$F:$F,Raw_Journals!$J:$J,H$3,Raw_Journals!$D:$D,"5600")-SUMIFS(Raw_Journals!$G:$G,Raw_Journals!$J:$J,H$3,Raw_Journals!$D:$D,"5600") | I12: =SUMIFS(Raw_Journals!$F:$F,Raw_Journals!$J:$J,I$3,Raw_Journals!$D:$D,"5600")-SUMIFS(Raw_Journals!$G:$G,Raw_Journals!$J:$J,I$3,Raw_Journals!$D:$D,"5600") | ... S12: =SUMIFS(Raw_Journals!$F:$F,Raw_Journals!$J:$J,S$3,Raw_Journals!$D:$D,"5600")-SUMIFS(Raw_Journals!$G:$G,Raw_Journals!$J:$J,S$3,Raw_Journals!$D:$D,"5600") | T12: =SUM(B12:S12)
A13: Depreciation Expense | B13: =SUMIFS(Raw_Journals!$F:$F,Raw_Journals!$J:$J,B$3,Raw_Journals!$D:$D,"5700")-SUMIFS(Raw_Journals!$G:$G,Raw_Journals!$J:$J,B$3,Raw_Journals!$D:$D,"5700") | C13: =SUMIFS(Raw_Journals!$F:$F,Raw_Journals!$J:$J,C$3,Raw_Journals!$D:$D,"5700")-SUMIFS(Raw_Journals!$G:$G,Raw_Journals!$J:$J,C$3,Raw_Journals!$D:$D,"5700") | D13: =SUMIFS(Raw_Journals!$F:$F,Raw_Journals!$J:$J,D$3,Raw_Journals!$D:$D,"5700")-SUMIFS(Raw_Journals!$G:$G,Raw_Journals!$J:$J,D$3,Raw_Journals!$D:$D,"5700") | E13: =SUMIFS(Raw_Journals!$F:$F,Raw_Journals!$J:$J,E$3,Raw_Journals!$D:$D,"5700")-SUMIFS(Raw_Journals!$G:$G,Raw_Journals!$J:$J,E$3,Raw_Journals!$D:$D,"5700") | F13: =SUMIFS(Raw_Journals!$F:$F,Raw_Journals!$J:$J,F$3,Raw_Journals!$D:$D,"5700")-SUMIFS(Raw_Journals!$G:$G,Raw_Journals!$J:$J,F$3,Raw_Journals!$D:$D,"5700") | G13: =SUMIFS(Raw_Journals!$F:$F,Raw_Journals!$J:$J,G$3,Raw_Journals!$D:$D,"5700")-SUMIFS(Raw_Journals!$G:$G,Raw_Journals!$J:$J,G$3,Raw_Journals!$D:$D,"5700") | H13: =SUMIFS(Raw_Journals!$F:$F,Raw_Journals!$J:$J,H$3,Raw_Journals!$D:$D,"5700")-SUMIFS(Raw_Journals!$G:$G,Raw_Journals!$J:$J,H$3,Raw_Journals!$D:$D,"5700") | I13: =SUMIFS(Raw_Journals!$F:$F,Raw_Journals!$J:$J,I$3,Raw_Journals!$D:$D,"5700")-SUMIFS(Raw_Journals!$G:$G,Raw_Journals!$J:$J,I$3,Raw_Journals!$D:$D,"5700") | ... S13: =SUMIFS(Raw_Journals!$F:$F,Raw_Journals!$J:$J,S$3,Raw_Journals!$D:$D,"5700")-SUMIFS(Raw_Journals!$G:$G,Raw_Journals!$J:$J,S$3,Raw_Journals!$D:$D,"5700") | T13: =SUM(B13:S13)
A14: Miscellaneous Expense | B14: =SUMIFS(Raw_Journals!$F:$F,Raw_Journals!$J:$J,B$3,Raw_Journals!$D:$D,"5800")-SUMIFS(Raw_Journals!$G:$G,Raw_Journals!$J:$J,B$3,Raw_Journals!$D:$D,"5800") | C14: =SUMIFS(Raw_Journals!$F:$F,Raw_Journals!$J:$J,C$3,Raw_Journals!$D:$D,"5800")-SUMIFS(Raw_Journals!$G:$G,Raw_Journals!$J:$J,C$3,Raw_Journals!$D:$D,"5800") | D14: =SUMIFS(Raw_Journals!$F:$F,Raw_Journals!$J:$J,D$3,Raw_Journals!$D:$D,"5800")-SUMIFS(Raw_Journals!$G:$G,Raw_Journals!$J:$J,D$3,Raw_Journals!$D:$D,"5800") | E14: =SUMIFS(Raw_Journals!$F:$F,Raw_Journals!$J:$J,E$3,Raw_Journals!$D:$D,"5800")-SUMIFS(Raw_Journals!$G:$G,Raw_Journals!$J:$J,E$3,Raw_Journals!$D:$D,"5800") | F14: =SUMIFS(Raw_Journals!$F:$F,Raw_Journals!$J:$J,F$3,Raw_Journals!$D:$D,"5800")-SUMIFS(Raw_Journals!$G:$G,Raw_Journals!$J:$J,F$3,Raw_Journals!$D:$D,"5800") | G14: =SUMIFS(Raw_Journals!$F:$F,Raw_Journals!$J:$J,G$3,Raw_Journals!$D:$D,"5800")-SUMIFS(Raw_Journals!$G:$G,Raw_Journals!$J:$J,G$3,Raw_Journals!$D:$D,"5800") | H14: =SUMIFS(Raw_Journals!$F:$F,Raw_Journals!$J:$J,H$3,Raw_Journals!$D:$D,"5800")-SUMIFS(Raw_Journals!$G:$G,Raw_Journals!$J:$J,H$3,Raw_Journals!$D:$D,"5800") | I14: =SUMIFS(Raw_Journals!$F:$F,Raw_Journals!$J:$J,I$3,Raw_Journals!$D:$D,"5800")-SUMIFS(Raw_Journals!$G:$G,Raw_Journals!$J:$J,I$3,Raw_Journals!$D:$D,"5800") | ... S14: =SUMIFS(Raw_Journals!$F:$F,Raw_Journals!$J:$J,S$3,Raw_Journals!$D:$D,"5800")-SUMIFS(Raw_Journals!$G:$G,Raw_Journals!$J:$J,S$3,Raw_Journals!$D:$D,"5800") | T14: =SUM(B14:S14)
A15: Total Expenses | B15: =B7+B8+B9+B10+B11+B12+B13+B14 | C15: =C7+C8+C9+C10+C11+C12+C13+C14 | D15: =D7+D8+D9+D10+D11+D12+D13+D14 | E15: =E7+E8+E9+E10+E11+E12+E13+E14 | F15: =F7+F8+F9+F10+F11+F12+F13+F14 | G15: =G7+G8+G9+G10+G11+G12+G13+G14 | H15: =H7+H8+H9+H10+H11+H12+H13+H14 | I15: =I7+I8+I9+I10+I11+I12+I13+I14 | ... S15: =S7+S8+S9+S10+S11+S12+S13+S14 | T15: =SUM(B15:S15)
A16: NET PROFIT | B16: =B6-B15 | C16: =C6-C15 | D16: =D6-D15 | E16: =E6-E15 | F16: =F6-F15 | G16: =G6-G15 | H16: =H6-H15 | I16: =I6-I15 | ... S16: =S6-S15 | T16: =SUM(B16:S16)

Sheet BalanceSheet
A1: BALANCE SHEET — live SUMIFS over Raw_Journals (₹)
A2: Particulars | B2: As of 31-Mar-2026 | C2: As of 30-Sep-2026
B3: 24315 | C3: 24321
A4: Cash & Bank | B4: =SUMIFS(Raw_Journals!$F:$F,Raw_Journals!$J:$J,"<="&B$3,Raw_Journals!$D:$D,"1000")-SUMIFS(Raw_Journals!$G:$G,Raw_Journals!$J:$J,"<="&B$3,Raw_Journals!$D:$D,"1000") | C4: =SUMIFS(Raw_Journals!$F:$F,Raw_Journals!$J:$J,"<="&C$3,Raw_Journals!$D:$D,"1000")-SUMIFS(Raw_Journals!$G:$G,Raw_Journals!$J:$J,"<="&C$3,Raw_Journals!$D:$D,"1000")
A5: Accounts Receivable | B5: =SUMIFS(Raw_Journals!$F:$F,Raw_Journals!$J:$J,"<="&B$3,Raw_Journals!$D:$D,"1100")-SUMIFS(Raw_Journals!$G:$G,Raw_Journals!$J:$J,"<="&B$3,Raw_Journals!$D:$D,"1100") | C5: =SUMIFS(Raw_Journals!$F:$F,Raw_Journals!$J:$J,"<="&C$3,Raw_Journals!$D:$D,"1100")-SUMIFS(Raw_Journals!$G:$G,Raw_Journals!$J:$J,"<="&C$3,Raw_Journals!$D:$D,"1100")
A6: Inventory | B6: =SUMIFS(Raw_Journals!$F:$F,Raw_Journals!$J:$J,"<="&B$3,Raw_Journals!$D:$D,"1200")-SUMIFS(Raw_Journals!$G:$G,Raw_Journals!$J:$J,"<="&B$3,Raw_Journals!$D:$D,"1200") | C6: =SUMIFS(Raw_Journals!$F:$F,Raw_Journals!$J:$J,"<="&C$3,Raw_Journals!$D:$D,"1200")-SUMIFS(Raw_Journals!$G:$G,Raw_Journals!$J:$J,"<="&C$3,Raw_Journals!$D:$D,"1200")
A7: GST Input Credit | B7: =SUMIFS(Raw_Journals!$F:$F,Raw_Journals!$J:$J,"<="&B$3,Raw_Journals!$D:$D,"1300")-SUMIFS(Raw_Journals!$G:$G,Raw_Journals!$J:$J,"<="&B$3,Raw_Journals!$D:$D,"1300") | C7: =SUMIFS(Raw_Journals!$F:$F,Raw_Journals!$J:$J,"<="&C$3,Raw_Journals!$D:$D,"1300")-SUMIFS(Raw_Journals!$G:$G,Raw_Journals!$J:$J,"<="&C$3,Raw_Journals!$D:$D,"1300")
A8: Equipment (net of depreciation) | B8: =(SUMIFS(Raw_Journals!$F:$F,Raw_Journals!$J:$J,"<="&B$3,Raw_Journals!$D:$D,"1500")-SUMIFS(Raw_Journals!$G:$G,Raw_Journals!$J:$J,"<="&B$3,Raw_Journals!$D:$D,"1500"))+(SUMIFS(Raw_Journals!$F:$F,Raw_Journals!$J:$J,"<="&B$3,Raw_Journals!$D:$D,"1510")-SUMIFS(Raw_Journals!$G:$G,Raw_Journals!$J:$J,"<="&B$3,Raw_Journals!$D:$D,"1510")) | C8: =(SUMIFS(Raw_Journals!$F:$F,Raw_Journals!$J:$J,"<="&C$3,Raw_Journals!$D:$D,"1500")-SUMIFS(Raw_Journals!$G:$G,Raw_Journals!$J:$J,"<="&C$3,Raw_Journals!$D:$D,"1500"))+(SUMIFS(Raw_Journals!$F:$F,Raw_Journals!$J:$J,"<="&C$3,Raw_Journals!$D:$D,"1510")-SUMIFS(Raw_Journals!$G:$G,Raw_Journals!$J:$J,"<="&C$3,Raw_Journals!$D:$D,"1510"))
A9: TOTAL ASSETS | B9: =SUM(B4:B8) | C9: =SUM(C4:C8)
A11: Accounts Payable | B11: =SUMIFS(Raw_Journals!$G:$G,Raw_Journals!$J:$J,"<="&B$3,Raw_Journals!$D:$D,"2000")-SUMIFS(Raw_Journals!$F:$F,Raw_Journals!$J:$J,"<="&B$3,Raw_Journals!$D:$D,"2000") | C11: =SUMIFS(Raw_Journals!$G:$G,Raw_Journals!$J:$J,"<="&C$3,Raw_Journals!$D:$D,"2000")-SUMIFS(Raw_Journals!$F:$F,Raw_Journals!$J:$J,"<="&C$3,Raw_Journals!$D:$D,"2000")
A12: GST Payable | B12: =SUMIFS(Raw_Journals!$G:$G,Raw_Journals!$J:$J,"<="&B$3,Raw_Journals!$D:$D,"2100")-SUMIFS(Raw_Journals!$F:$F,Raw_Journals!$J:$J,"<="&B$3,Raw_Journals!$D:$D,"2100") | C12: =SUMIFS(Raw_Journals!$G:$G,Raw_Journals!$J:$J,"<="&C$3,Raw_Journals!$D:$D,"2100")-SUMIFS(Raw_Journals!$F:$F,Raw_Journals!$J:$J,"<="&C$3,Raw_Journals!$D:$D,"2100")
A13: Term Loan | B13: =SUMIFS(Raw_Journals!$G:$G,Raw_Journals!$J:$J,"<="&B$3,Raw_Journals!$D:$D,"2200")-SUMIFS(Raw_Journals!$F:$F,Raw_Journals!$J:$J,"<="&B$3,Raw_Journals!$D:$D,"2200") | C13: =SUMIFS(Raw_Journals!$G:$G,Raw_Journals!$J:$J,"<="&C$3,Raw_Journals!$D:$D,"2200")-SUMIFS(Raw_Journals!$F:$F,Raw_Journals!$J:$J,"<="&C$3,Raw_Journals!$D:$D,"2200")
A14: TOTAL LIABILITIES | B14: =SUM(B11:B13) | C14: =SUM(C11:C13)
A16: Owner's Capital | B16: =SUMIFS(Raw_Journals!$G:$G,Raw_Journals!$J:$J,"<="&B$3,Raw_Journals!$D:$D,"3000")-SUMIFS(Raw_Journals!$F:$F,Raw_Journals!$J:$J,"<="&B$3,Raw_Journals!$D:$D,"3000") | C16: =SUMIFS(Raw_Journals!$G:$G,Raw_Journals!$J:$J,"<="&C$3,Raw_Journals!$D:$D,"3000")-SUMIFS(Raw_Journals!$F:$F,Raw_Journals!$J:$J,"<="&C$3,Raw_Journals!$D:$D,"3000")
A17: Retained Earnings (opening) | B17: =SUMIFS(Raw_Journals!$G:$G,Raw_Journals!$J:$J,"<="&B$3,Raw_Journals!$D:$D,"3100")-SUMIFS(Raw_Journals!$F:$F,Raw_Journals!$J:$J,"<="&B$3,Raw_Journals!$D:$D,"3100") | C17: =SUMIFS(Raw_Journals!$G:$G,Raw_Journals!$J:$J,"<="&C$3,Raw_Journals!$D:$D,"3100")-SUMIFS(Raw_Journals!$F:$F,Raw_Journals!$J:$J,"<="&C$3,Raw_Journals!$D:$D,"3100")
A18: Current period net profit | B18: ='PL'!T16 | C18: ='PL'!T16
A19: TOTAL EQUITY | B19: =SUM(B16:B18) | C19: =SUM(C16:C18)
A21: Check: Assets = Liabilities + Equity | B21: =IF(ROUND(B9,2)=ROUND(B14+B19,2),"✓ BALANCED","✗ IMBALANCED") | C21: =IF(ROUND(C9,2)=ROUND(C14+C19,2),"✓ BALANCED","✗ IMBALANCED")

Sheet Dashboard
A1: AGARWAL TRADERS — FINANCE DASHBOARD (all cards are live formulas)
A3: YTD Revenue (₹)
A4: ='PL'!T4
A5: YTD Net Profit (₹)
A6: ='PL'!T16
A7: Gross Margin %
A8: =IF('PL'!T4=0,0,'PL'!T6/'PL'!T4)
A9: Net Margin %
A10: =IF('PL'!T4=0,0,'PL'!T16/'PL'!T4)
A11: Cash & Bank (₹)
A12: ='BalanceSheet'!C4
A13: Accounts Receivable (₹)
A14: ='BalanceSheet'!C5
A15: Accounts Payable (₹)
A16: ='BalanceSheet'!C11
A17: Term Loan Outstanding (₹)
A18: ='BalanceSheet'!C13
A19: Current Ratio
A20: =IF('BalanceSheet'!C14=0,0,('BalanceSheet'!C4+'BalanceSheet'!C5+'BalanceSheet'!C6+'BalanceSheet'!C7)/'BalanceSheet'!C14)

Sheet AI_Report
A1: MANAGEMENT NARRATIVE — Agarwal Traders (Apr-25 to Sep-26)
A3: 1. Executive summary
A4: Revenue for the 18-month period is ₹60,358,943 with net profit of ₹106,057,897 — a net margin of 175.7%. Gross margin holds at 30.2%, consistent with a wholesale FMCG mix. Profitability is improving: net profit in the last 6 months (₹39,456,629) vs the first 6 months (₹30,957,948).
A6: 2. Revenue trend
A7: Strongest month was 2026-08 at ₹4,084,174; softest was 2025-08 at ₹2,840,002. Festival-quarter months (Oct/Nov/Mar) run above trend — plan inventory build-up 3 weeks ahead of those peaks.
A9: 3. Expense drivers
A10: Top 3 non-COGS expenses: Salaries Expense ₹2,034,032; Rent Expense ₹450,000; Transport & Logistics ₹326,465. Salaries are the largest controllable line — review headcount against revenue per employee each quarter.
A12: 4. Cash & working capital
A13: Cash & bank stands at ₹9,920,878; receivables at ₹12,408,113 (4 days of sales tied up). Term loan outstanding is ₹1,010,000 with steady ₹55,000/month principal repayment. Tighten collection follow-ups to under 30 days to free working capital.
A15: 5. Recommendations
A16: a) Automate the monthly close: this workbook already reconciles every figure to the journals — run the Checks sheet before signing off. b) Set a 60% ceiling on COGS-to-revenue; flag any month breaching it. c) Build a 13-week cash forecast off the receipts/payments pattern in Raw_Journals to avoid surprise shortfalls.

Sheet Checks
A1: AUTOMATED INTEGRITY CHECKS — every result is a live formula
A3: # | B3: Check | C3: Formula result | D3: Expected
A4: 1 | B4: Every journal entry balances (debits = credits) | C4: =IF(SUM(Raw_Journals!F2:F1117)=SUM(Raw_Journals!G2:G1117),"PASS","FAIL") | D4: PASS
A5: 2 | B5: Trial balance: total debits = total credits | C5: =IF(ROUND(TrialBalance!D25,2)=ROUND(TrialBalance!E25,2),"PASS","FAIL") | D5: PASS
A6: 3 | B6: P&L YTD revenue ties to trial balance (acct 4000) | C6: =IF(ROUND(PL!T4,2)=ROUND(TrialBalance!E15-TrialBalance!D15,2),"PASS","FAIL") | D6: PASS
A7: 4 | B7: Net profit = Gross profit − Total expenses | C7: =IF(ROUND(PL!T16,2)=ROUND(PL!T6-PL!T15,2),"PASS","FAIL") | D7: PASS
A8: 5 | B8: Balance sheet balances (Sep-26) | C8: =IF(BalanceSheet!C21="✓ BALANCED","PASS","FAIL") | D8: PASS
A9: 6 | B9: Receivables and payables are non-negative | C9: =IF(AND(BalanceSheet!C5>=0,BalanceSheet!C11>=0),"PASS","FAIL") | D9: PASS
A10: 7 | B10: No blank account numbers in journals | C10: =IF(COUNTA(Raw_Journals!D2:D1117)=1116,"PASS","FAIL") | D10: PASS
A11: 8 | B11: All period codes within Apr-25..Sep-26 | C11: =IF(AND(MIN(Raw_Journals!J2:J1117)=24304,MAX(Raw_Journals!J2:J1117)=24321),"PASS","FAIL") | D11: PASS
