Workbook

Sheet Guide
A1: WarehousePulse — warehouse stock tracker + Power BI-ready model
A3: Fictional demo data: 'Sharma Wholesale Traders, Patna' (FMCG wholesale).
A4: Opening stock as of 30-Sep-2026; movements 01-Oct-2026 .. 18-Oct-2026.
A6: DAILY ROUTINE
A7: 1. Key today's receipts / issues / adjustments into the Entry sheet (or paste
A8: rows directly into Raw_Receipts / Raw_Issues / Raw_Adjustments — keep column order).
A9: 2. Everything recalculates: Stock_Ledger (closing, WAC, value, days-of-cover,
A10: status), Bin_Map utilisation, Dashboard KPIs/charts/drill-through,
A11: AI_Report narrative and the Checks sheet.
A12: 3. SKUs flagged REORDER or STOCKOUT on Stock_Ledger are your purchase list;
A13: the Dashboard drill-through shows the top-5 SKUs by value per category.
A15: POWER BI
... A25: read TRUE after any recalculation.

Sheet SKU_Master
A1: sku | B1: name | C1: category | D1: uom | E1: reorder_level | F1: std_cost | G1: bin | H1: opening_qty
A2: ST-001 | B2: Basmati Rice 5kg | C2: Staples | D2: bag | E2: 120 | F2: 485 | G2: B1 | H2: 333
A3: ST-002 | B3: Wheat Flour 10kg | C3: Staples | D3: bag | E3: 150 | F3: 425 | G3: C2 | H3: 90
A4: ST-003 | B4: Toor Dal 1kg | C4: Staples | D4: pkt | E4: 200 | F4: 165 | G4: B1 | H4: 228
A5: ST-004 | B5: Sugar 5kg | C5: Staples | D5: bag | E5: 100 | F5: 230 | G5: C4 | H5: 357
A6: ST-005 | B6: Mustard Oil 1L | C6: Staples | D6: btl | E6: 180 | F6: 198 | G6: A3 | H6: 59
A7: ST-006 | B7: Salt 1kg | C7: Staples | D7: pkt | E7: 250 | F7: 32 | G7: A4 | H7: 338
A8: ST-007 | B8: Poha 500g | C8: Staples | D8: pkt | E8: 160 | F8: 45 | G8: A3 | H8: 239
A9: ST-008 | B9: Sona Masoori Rice 5kg | C9: Staples | D9: bag | E9: 110 | F9: 340 | G9: C3 | H9: 40
A10: BV-001 | B10: Masala Chai 250g | C10: Beverages | D10: pkt | E10: 140 | F10: 145 | G10: B3 | H10: 407
A11: BV-002 | B11: Instant Coffee 100g | C11: Beverages | D11: jar | E11: 90 | F11: 285 | G11: C3 | H11: 221
A12: BV-003 | B12: Mango Juice 1L | C12: Beverages | D12: btl | E12: 200 | F12: 115 | G12: B2 | H12: 207
A13: BV-004 | B13: Cola 750ml x12 case | C13: Beverages | D13: case | E13: 80 | F13: 420 | G13: A4 | H13: 290
... A37: HH-006 | B37: Storage Container 5L | C37: Household | D37: pc | E37: 100 | F37: 240 | G37: C1 | H37: 404

Sheet Raw_Receipts
A1: date | B1: grn | C1: sku | D1: qty | E1: unit_cost | F1: bin | G1: value
A2: 46296 | B2: GRN-0001 | C2: PC-002 | D2: 198 | E2: 216.31 | F2: B1 | G2: =D2*E2
A3: 46296 | B3: GRN-0002 | C3: SN-002 | D3: 25 | E3: 92.86 | F3: C4 | G3: =D3*E3
A4: 46296 | B4: GRN-0003 | C4: HH-005 | D4: 62 | E4: 184.69 | F4: C3 | G4: =D4*E4
A5: 46296 | B5: GRN-0004 | C5: SN-003 | D5: 36 | E5: 301.94 | F5: B4 | G5: =D5*E5
A6: 46296 | B6: GRN-0005 | C6: HH-004 | D6: 106 | E6: 118.92 | F6: B3 | G6: =D6*E6
A7: 46296 | B7: GRN-0006 | C7: HH-003 | D7: 101 | E7: 711.95 | F7: B4 | G7: =D7*E7
A8: 46297 | B8: GRN-0007 | C8: SN-002 | D8: 74 | E8: 93.8 | F8: C4 | G8: =D8*E8
A9: 46297 | B9: GRN-0008 | C9: ST-005 | D9: 58 | E9: 192.38 | F9: A3 | G9: =D9*E9
A10: 46297 | B10: GRN-0009 | C10: ST-008 | D10: 98 | E10: 336.17 | F10: C3 | G10: =D10*E10
A11: 46297 | B11: GRN-0010 | C11: SN-002 | D11: 73 | E11: 93.62 | F11: C4 | G11: =D11*E11
A12: 46297 | B12: GRN-0011 | C12: SN-007 | D12: 65 | E12: 765.1 | F12: B2 | G12: =D12*E12
A13: 46297 | B13: GRN-0012 | C13: BV-006 | D13: 150 | E13: 191.47 | F13: C2 | G13: =D13*E13
... A128: 46313 | B128: GRN-0127 | C128: ST-006 | D128: 219 | E128: 32.65 | F128: A4 | G128: =D128*E128

Sheet Raw_Issues
A1: date | B1: do_no | C1: sku | D1: qty | E1: bin
A2: 46296 | B2: DO-0001 | C2: PC-003 | D2: 49 | E2: A1
A3: 46296 | B3: DO-0002 | C3: HH-003 | D3: 56 | E3: B4
A4: 46296 | B4: DO-0003 | C4: BV-008 | D4: 25 | E4: C1
A5: 46296 | B5: DO-0004 | C5: PC-003 | D5: 20 | E5: A1
A6: 46296 | B6: DO-0005 | C6: PC-003 | D6: 43 | E6: A1
A7: 46296 | B7: DO-0006 | C7: ST-004 | D7: 20 | E7: C4
A8: 46296 | B8: DO-0007 | C8: HH-004 | D8: 51 | E8: B3
A9: 46296 | B9: DO-0008 | C9: ST-001 | D9: 24 | E9: B1
A10: 46296 | B10: DO-0009 | C10: ST-005 | D10: 39 | E10: A3
A11: 46296 | B11: DO-0010 | C11: SN-004 | D11: 9 | E11: B2
A12: 46296 | B12: DO-0011 | C12: SN-001 | D12: 39 | E12: A4
A13: 46296 | B13: DO-0012 | C13: SN-008 | D13: 32 | E13: A1
... A224: 46313 | B224: DO-0223 | C224: SN-005 | D224: 461 | E224: C4

Sheet Raw_Adjustments
A1: date | B1: adj_id | C1: sku | D1: qty | E1: reason
A2: 46296 | B2: ADJ-0001 | C2: HH-004 | D2: -4 | E2: Pilferage
A3: 46296 | B3: ADJ-0002 | C3: HH-002 | D3: -11 | E3: Pilferage
A4: 46299 | B4: ADJ-0003 | C4: PC-004 | D4: -12 | E4: Cycle-count correction
A5: 46300 | B5: ADJ-0004 | C5: BV-001 | D5: -14 | E5: Damaged in handling
A6: 46303 | B6: ADJ-0005 | C6: BV-002 | D6: -16 | E6: Pilferage
A7: 46304 | B7: ADJ-0006 | C7: BV-006 | D7: -4 | E7: Pilferage
A8: 46304 | B8: ADJ-0007 | C8: SN-008 | D8: -25 | E8: Damaged in handling
A9: 46305 | B9: ADJ-0008 | C9: PC-002 | D9: -18 | E9: Damaged in handling
A10: 46305 | B10: ADJ-0009 | C10: HH-001 | D10: -25 | E10: Pilferage
A11: 46307 | B11: ADJ-0010 | C11: BV-001 | D11: -16 | E11: Expired / quality hold
A12: 46307 | B12: ADJ-0011 | C12: PC-005 | D12: -8 | E12: Cycle-count correction
A13: 46308 | B13: ADJ-0012 | C13: ST-008 | D13: -4 | E13: Expired / quality hold
... A18: 46313 | B18: ADJ-0017 | C18: HH-004 | D18: -8 | E18: Expired / quality hold

Sheet Stock_Ledger
A1: Stock_Ledger — every figure a live formula (paste new rows into Raw_*)
A2: sku | B2: name | C2: category | D2: bin | E2: reorder_level | F2: opening | G2: receipts_qty | H2: receipts_value | I2: issues_qty | J2: adj_qty | K2: closing | L2: wac | M2: stock_value | N2: avg_daily_issue | O2: days_of_cover | P2: status | Q2: reorder_qty
A3: ST-001 | B3: Basmati Rice 5kg | C3: Staples | D3: B1 | E3: =VLOOKUP($A3,SKU_Master!$A:$G,5,FALSE) | F3: =VLOOKUP($A3,SKU_Master!$A:$H,8,FALSE) | G3: =SUMIFS(Raw_Receipts!$D:$D,Raw_Receipts!$C:$C,$A3) | H3: =SUMIFS(Raw_Receipts!$G:$G,Raw_Receipts!$C:$C,$A3) | I3: =SUMIFS(Raw_Issues!$D:$D,Raw_Issues!$C:$C,$A3) | J3: =SUMIFS(Raw_Adjustments!$D:$D,Raw_Adjustments!$C:$C,$A3) | K3: =F3+G3-I3+J3 | L3: =IF((F3+G3)=0,VLOOKUP($A3,SKU_Master!$A:$G,6,FALSE),(F3*VLOOKUP($A3,SKU_Master!$A:$G,6,FALSE)+H3)/(F3+G3)) | M3: =K3*L3 | N3: =I3/18 | O3: =IF(N3=0,999,K3/N3) | P3: =IF(K3=0,"STOCKOUT",IF(K3<=E3,"REORDER",IF(O3>60,"OVERSTOCK","OK"))) | Q3: =IF(P3="REORDER",MAX(0,E3*2-K3),0)
A4: ST-002 | B4: Wheat Flour 10kg | C4: Staples | D4: C2 | E4: =VLOOKUP($A4,SKU_Master!$A:$G,5,FALSE) | F4: =VLOOKUP($A4,SKU_Master!$A:$H,8,FALSE) | G4: =SUMIFS(Raw_Receipts!$D:$D,Raw_Receipts!$C:$C,$A4) | H4: =SUMIFS(Raw_Receipts!$G:$G,Raw_Receipts!$C:$C,$A4) | I4: =SUMIFS(Raw_Issues!$D:$D,Raw_Issues!$C:$C,$A4) | J4: =SUMIFS(Raw_Adjustments!$D:$D,Raw_Adjustments!$C:$C,$A4) | K4: =F4+G4-I4+J4 | L4: =IF((F4+G4)=0,VLOOKUP($A4,SKU_Master!$A:$G,6,FALSE),(F4*VLOOKUP($A4,SKU_Master!$A:$G,6,FALSE)+H4)/(F4+G4)) | M4: =K4*L4 | N4: =I4/18 | O4: =IF(N4=0,999,K4/N4) | P4: =IF(K4=0,"STOCKOUT",IF(K4<=E4,"REORDER",IF(O4>60,"OVERSTOCK","OK"))) | Q4: =IF(P4="REORDER",MAX(0,E4*2-K4),0)
A5: ST-003 | B5: Toor Dal 1kg | C5: Staples | D5: B1 | E5: =VLOOKUP($A5,SKU_Master!$A:$G,5,FALSE) | F5: =VLOOKUP($A5,SKU_Master!$A:$H,8,FALSE) | G5: =SUMIFS(Raw_Receipts!$D:$D,Raw_Receipts!$C:$C,$A5) | H5: =SUMIFS(Raw_Receipts!$G:$G,Raw_Receipts!$C:$C,$A5) | I5: =SUMIFS(Raw_Issues!$D:$D,Raw_Issues!$C:$C,$A5) | J5: =SUMIFS(Raw_Adjustments!$D:$D,Raw_Adjustments!$C:$C,$A5) | K5: =F5+G5-I5+J5 | L5: =IF((F5+G5)=0,VLOOKUP($A5,SKU_Master!$A:$G,6,FALSE),(F5*VLOOKUP($A5,SKU_Master!$A:$G,6,FALSE)+H5)/(F5+G5)) | M5: =K5*L5 | N5: =I5/18 | O5: =IF(N5=0,999,K5/N5) | P5: =IF(K5=0,"STOCKOUT",IF(K5<=E5,"REORDER",IF(O5>60,"OVERSTOCK","OK"))) | Q5: =IF(P5="REORDER",MAX(0,E5*2-K5),0)
A6: ST-004 | B6: Sugar 5kg | C6: Staples | D6: C4 | E6: =VLOOKUP($A6,SKU_Master!$A:$G,5,FALSE) | F6: =VLOOKUP($A6,SKU_Master!$A:$H,8,FALSE) | G6: =SUMIFS(Raw_Receipts!$D:$D,Raw_Receipts!$C:$C,$A6) | H6: =SUMIFS(Raw_Receipts!$G:$G,Raw_Receipts!$C:$C,$A6) | I6: =SUMIFS(Raw_Issues!$D:$D,Raw_Issues!$C:$C,$A6) | J6: =SUMIFS(Raw_Adjustments!$D:$D,Raw_Adjustments!$C:$C,$A6) | K6: =F6+G6-I6+J6 | L6: =IF((F6+G6)=0,VLOOKUP($A6,SKU_Master!$A:$G,6,FALSE),(F6*VLOOKUP($A6,SKU_Master!$A:$G,6,FALSE)+H6)/(F6+G6)) | M6: =K6*L6 | N6: =I6/18 | O6: =IF(N6=0,999,K6/N6) | P6: =IF(K6=0,"STOCKOUT",IF(K6<=E6,"REORDER",IF(O6>60,"OVERSTOCK","OK"))) | Q6: =IF(P6="REORDER",MAX(0,E6*2-K6),0)
A7: ST-005 | B7: Mustard Oil 1L | C7: Staples | D7: A3 | E7: =VLOOKUP($A7,SKU_Master!$A:$G,5,FALSE) | F7: =VLOOKUP($A7,SKU_Master!$A:$H,8,FALSE) | G7: =SUMIFS(Raw_Receipts!$D:$D,Raw_Receipts!$C:$C,$A7) | H7: =SUMIFS(Raw_Receipts!$G:$G,Raw_Receipts!$C:$C,$A7) | I7: =SUMIFS(Raw_Issues!$D:$D,Raw_Issues!$C:$C,$A7) | J7: =SUMIFS(Raw_Adjustments!$D:$D,Raw_Adjustments!$C:$C,$A7) | K7: =F7+G7-I7+J7 | L7: =IF((F7+G7)=0,VLOOKUP($A7,SKU_Master!$A:$G,6,FALSE),(F7*VLOOKUP($A7,SKU_Master!$A:$G,6,FALSE)+H7)/(F7+G7)) | M7: =K7*L7 | N7: =I7/18 | O7: =IF(N7=0,999,K7/N7) | P7: =IF(K7=0,"STOCKOUT",IF(K7<=E7,"REORDER",IF(O7>60,"OVERSTOCK","OK"))) | Q7: =IF(P7="REORDER",MAX(0,E7*2-K7),0)
A8: ST-006 | B8: Salt 1kg | C8: Staples | D8: A4 | E8: =VLOOKUP($A8,SKU_Master!$A:$G,5,FALSE) | F8: =VLOOKUP($A8,SKU_Master!$A:$H,8,FALSE) | G8: =SUMIFS(Raw_Receipts!$D:$D,Raw_Receipts!$C:$C,$A8) | H8: =SUMIFS(Raw_Receipts!$G:$G,Raw_Receipts!$C:$C,$A8) | I8: =SUMIFS(Raw_Issues!$D:$D,Raw_Issues!$C:$C,$A8) | J8: =SUMIFS(Raw_Adjustments!$D:$D,Raw_Adjustments!$C:$C,$A8) | K8: =F8+G8-I8+J8 | L8: =IF((F8+G8)=0,VLOOKUP($A8,SKU_Master!$A:$G,6,FALSE),(F8*VLOOKUP($A8,SKU_Master!$A:$G,6,FALSE)+H8)/(F8+G8)) | M8: =K8*L8 | N8: =I8/18 | O8: =IF(N8=0,999,K8/N8) | P8: =IF(K8=0,"STOCKOUT",IF(K8<=E8,"REORDER",IF(O8>60,"OVERSTOCK","OK"))) | Q8: =IF(P8="REORDER",MAX(0,E8*2-K8),0)
A9: ST-007 | B9: Poha 500g | C9: Staples | D9: A3 | E9: =VLOOKUP($A9,SKU_Master!$A:$G,5,FALSE) | F9: =VLOOKUP($A9,SKU_Master!$A:$H,8,FALSE) | G9: =SUMIFS(Raw_Receipts!$D:$D,Raw_Receipts!$C:$C,$A9) | H9: =SUMIFS(Raw_Receipts!$G:$G,Raw_Receipts!$C:$C,$A9) | I9: =SUMIFS(Raw_Issues!$D:$D,Raw_Issues!$C:$C,$A9) | J9: =SUMIFS(Raw_Adjustments!$D:$D,Raw_Adjustments!$C:$C,$A9) | K9: =F9+G9-I9+J9 | L9: =IF((F9+G9)=0,VLOOKUP($A9,SKU_Master!$A:$G,6,FALSE),(F9*VLOOKUP($A9,SKU_Master!$A:$G,6,FALSE)+H9)/(F9+G9)) | M9: =K9*L9 | N9: =I9/18 | O9: =IF(N9=0,999,K9/N9) | P9: =IF(K9=0,"STOCKOUT",IF(K9<=E9,"REORDER",IF(O9>60,"OVERSTOCK","OK"))) | Q9: =IF(P9="REORDER",MAX(0,E9*2-K9),0)
A10: ST-008 | B10: Sona Masoori Rice 5kg | C10: Staples | D10: C3 | E10: =VLOOKUP($A10,SKU_Master!$A:$G,5,FALSE) | F10: =VLOOKUP($A10,SKU_Master!$A:$H,8,FALSE) | G10: =SUMIFS(Raw_Receipts!$D:$D,Raw_Receipts!$C:$C,$A10) | H10: =SUMIFS(Raw_Receipts!$G:$G,Raw_Receipts!$C:$C,$A10) | I10: =SUMIFS(Raw_Issues!$D:$D,Raw_Issues!$C:$C,$A10) | J10: =SUMIFS(Raw_Adjustments!$D:$D,Raw_Adjustments!$C:$C,$A10) | K10: =F10+G10-I10+J10 | L10: =IF((F10+G10)=0,VLOOKUP($A10,SKU_Master!$A:$G,6,FALSE),(F10*VLOOKUP($A10,SKU_Master!$A:$G,6,FALSE)+H10)/(F10+G10)) | M10: =K10*L10 | N10: =I10/18 | O10: =IF(N10=0,999,K10/N10) | P10: =IF(K10=0,"STOCKOUT",IF(K10<=E10,"REORDER",IF(O10>60,"OVERSTOCK","OK"))) | Q10: =IF(P10="REORDER",MAX(0,E10*2-K10),0)
A11: BV-001 | B11: Masala Chai 250g | C11: Beverages | D11: B3 | E11: =VLOOKUP($A11,SKU_Master!$A:$G,5,FALSE) | F11: =VLOOKUP($A11,SKU_Master!$A:$H,8,FALSE) | G11: =SUMIFS(Raw_Receipts!$D:$D,Raw_Receipts!$C:$C,$A11) | H11: =SUMIFS(Raw_Receipts!$G:$G,Raw_Receipts!$C:$C,$A11) | I11: =SUMIFS(Raw_Issues!$D:$D,Raw_Issues!$C:$C,$A11) | J11: =SUMIFS(Raw_Adjustments!$D:$D,Raw_Adjustments!$C:$C,$A11) | K11: =F11+G11-I11+J11 | L11: =IF((F11+G11)=0,VLOOKUP($A11,SKU_Master!$A:$G,6,FALSE),(F11*VLOOKUP($A11,SKU_Master!$A:$G,6,FALSE)+H11)/(F11+G11)) | M11: =K11*L11 | N11: =I11/18 | O11: =IF(N11=0,999,K11/N11) | P11: =IF(K11=0,"STOCKOUT",IF(K11<=E11,"REORDER",IF(O11>60,"OVERSTOCK","OK"))) | Q11: =IF(P11="REORDER",MAX(0,E11*2-K11),0)
A12: BV-002 | B12: Instant Coffee 100g | C12: Beverages | D12: C3 | E12: =VLOOKUP($A12,SKU_Master!$A:$G,5,FALSE) | F12: =VLOOKUP($A12,SKU_Master!$A:$H,8,FALSE) | G12: =SUMIFS(Raw_Receipts!$D:$D,Raw_Receipts!$C:$C,$A12) | H12: =SUMIFS(Raw_Receipts!$G:$G,Raw_Receipts!$C:$C,$A12) | I12: =SUMIFS(Raw_Issues!$D:$D,Raw_Issues!$C:$C,$A12) | J12: =SUMIFS(Raw_Adjustments!$D:$D,Raw_Adjustments!$C:$C,$A12) | K12: =F12+G12-I12+J12 | L12: =IF((F12+G12)=0,VLOOKUP($A12,SKU_Master!$A:$G,6,FALSE),(F12*VLOOKUP($A12,SKU_Master!$A:$G,6,FALSE)+H12)/(F12+G12)) | M12: =K12*L12 | N12: =I12/18 | O12: =IF(N12=0,999,K12/N12) | P12: =IF(K12=0,"STOCKOUT",IF(K12<=E12,"REORDER",IF(O12>60,"OVERSTOCK","OK"))) | Q12: =IF(P12="REORDER",MAX(0,E12*2-K12),0)
A13: BV-003 | B13: Mango Juice 1L | C13: Beverages | D13: B2 | E13: =VLOOKUP($A13,SKU_Master!$A:$G,5,FALSE) | F13: =VLOOKUP($A13,SKU_Master!$A:$H,8,FALSE) | G13: =SUMIFS(Raw_Receipts!$D:$D,Raw_Receipts!$C:$C,$A13) | H13: =SUMIFS(Raw_Receipts!$G:$G,Raw_Receipts!$C:$C,$A13) | I13: =SUMIFS(Raw_Issues!$D:$D,Raw_Issues!$C:$C,$A13) | J13: =SUMIFS(Raw_Adjustments!$D:$D,Raw_Adjustments!$C:$C,$A13) | K13: =F13+G13-I13+J13 | L13: =IF((F13+G13)=0,VLOOKUP($A13,SKU_Master!$A:$G,6,FALSE),(F13*VLOOKUP($A13,SKU_Master!$A:$G,6,FALSE)+H13)/(F13+G13)) | M13: =K13*L13 | N13: =I13/18 | O13: =IF(N13=0,999,K13/N13) | P13: =IF(K13=0,"STOCKOUT",IF(K13<=E13,"REORDER",IF(O13>60,"OVERSTOCK","OK"))) | Q13: =IF(P13="REORDER",MAX(0,E13*2-K13),0)
A14: BV-004 | B14: Cola 750ml x12 case | C14: Beverages | D14: A4 | E14: =VLOOKUP($A14,SKU_Master!$A:$G,5,FALSE) | F14: =VLOOKUP($A14,SKU_Master!$A:$H,8,FALSE) | G14: =SUMIFS(Raw_Receipts!$D:$D,Raw_Receipts!$C:$C,$A14) | H14: =SUMIFS(Raw_Receipts!$G:$G,Raw_Receipts!$C:$C,$A14) | I14: =SUMIFS(Raw_Issues!$D:$D,Raw_Issues!$C:$C,$A14) | J14: =SUMIFS(Raw_Adjustments!$D:$D,Raw_Adjustments!$C:$C,$A14) | K14: =F14+G14-I14+J14 | L14: =IF((F14+G14)=0,VLOOKUP($A14,SKU_Master!$A:$G,6,FALSE),(F14*VLOOKUP($A14,SKU_Master!$A:$G,6,FALSE)+H14)/(F14+G14)) | M14: =K14*L14 | N14: =I14/18 | O14: =IF(N14=0,999,K14/N14) | P14: =IF(K14=0,"STOCKOUT",IF(K14<=E14,"REORDER",IF(O14>60,"OVERSTOCK","OK"))) | Q14: =IF(P14="REORDER",MAX(0,E14*2-K14),0)
... A38: HH-006 | B38: Storage Container 5L | C38: Household | D38: C1 | E38: =VLOOKUP($A38,SKU_Master!$A:$G,5,FALSE) | F38: =VLOOKUP($A38,SKU_Master!$A:$H,8,FALSE) | G38: =SUMIFS(Raw_Receipts!$D:$D,Raw_Receipts!$C:$C,$A38) | H38: =SUMIFS(Raw_Receipts!$G:$G,Raw_Receipts!$C:$C,$A38) | I38: =SUMIFS(Raw_Issues!$D:$D,Raw_Issues!$C:$C,$A38) | J38: =SUMIFS(Raw_Adjustments!$D:$D,Raw_Adjustments!$C:$C,$A38) | K38: =F38+G38-I38+J38 | L38: =IF((F38+G38)=0,VLOOKUP($A38,SKU_Master!$A:$G,6,FALSE),(F38*VLOOKUP($A38,SKU_Master!$A:$G,6,FALSE)+H38)/(F38+G38)) | M38: =K38*L38 | N38: =I38/18 | O38: =IF(N38=0,999,K38/N38) | P38: =IF(K38=0,"STOCKOUT",IF(K38<=E38,"REORDER",IF(O38>60,"OVERSTOCK","OK"))) | Q38: =IF(P38="REORDER",MAX(0,E38*2-K38),0)

Sheet Bin_Map
A1: Bin_Map — per-bin stock and utilisation (formula-driven)
A2: bin | B2: capacity | C2: qty_on_hand | D2: #_skus | E2: utilisation | F2: flag
A3: A1 | B3: 2000 | C3: =SUMIFS(Stock_Ledger!$K:$K,Stock_Ledger!$D:$D,$A3) | D3: =COUNTIFS(Stock_Ledger!$D:$D,$A3) | E3: =IF(B3=0,0,C3/B3) | F3: =IF(E3>0.9,"FULL",IF(C3=0,"EMPTY","OK"))
A4: A2 | B4: 2000 | C4: =SUMIFS(Stock_Ledger!$K:$K,Stock_Ledger!$D:$D,$A4) | D4: =COUNTIFS(Stock_Ledger!$D:$D,$A4) | E4: =IF(B4=0,0,C4/B4) | F4: =IF(E4>0.9,"FULL",IF(C4=0,"EMPTY","OK"))
A5: A3 | B5: 2000 | C5: =SUMIFS(Stock_Ledger!$K:$K,Stock_Ledger!$D:$D,$A5) | D5: =COUNTIFS(Stock_Ledger!$D:$D,$A5) | E5: =IF(B5=0,0,C5/B5) | F5: =IF(E5>0.9,"FULL",IF(C5=0,"EMPTY","OK"))
A6: A4 | B6: 2000 | C6: =SUMIFS(Stock_Ledger!$K:$K,Stock_Ledger!$D:$D,$A6) | D6: =COUNTIFS(Stock_Ledger!$D:$D,$A6) | E6: =IF(B6=0,0,C6/B6) | F6: =IF(E6>0.9,"FULL",IF(C6=0,"EMPTY","OK"))
A7: B1 | B7: 2000 | C7: =SUMIFS(Stock_Ledger!$K:$K,Stock_Ledger!$D:$D,$A7) | D7: =COUNTIFS(Stock_Ledger!$D:$D,$A7) | E7: =IF(B7=0,0,C7/B7) | F7: =IF(E7>0.9,"FULL",IF(C7=0,"EMPTY","OK"))
A8: B2 | B8: 2000 | C8: =SUMIFS(Stock_Ledger!$K:$K,Stock_Ledger!$D:$D,$A8) | D8: =COUNTIFS(Stock_Ledger!$D:$D,$A8) | E8: =IF(B8=0,0,C8/B8) | F8: =IF(E8>0.9,"FULL",IF(C8=0,"EMPTY","OK"))
A9: B3 | B9: 2000 | C9: =SUMIFS(Stock_Ledger!$K:$K,Stock_Ledger!$D:$D,$A9) | D9: =COUNTIFS(Stock_Ledger!$D:$D,$A9) | E9: =IF(B9=0,0,C9/B9) | F9: =IF(E9>0.9,"FULL",IF(C9=0,"EMPTY","OK"))
A10: B4 | B10: 2000 | C10: =SUMIFS(Stock_Ledger!$K:$K,Stock_Ledger!$D:$D,$A10) | D10: =COUNTIFS(Stock_Ledger!$D:$D,$A10) | E10: =IF(B10=0,0,C10/B10) | F10: =IF(E10>0.9,"FULL",IF(C10=0,"EMPTY","OK"))
A11: C1 | B11: 2000 | C11: =SUMIFS(Stock_Ledger!$K:$K,Stock_Ledger!$D:$D,$A11) | D11: =COUNTIFS(Stock_Ledger!$D:$D,$A11) | E11: =IF(B11=0,0,C11/B11) | F11: =IF(E11>0.9,"FULL",IF(C11=0,"EMPTY","OK"))
A12: C2 | B12: 2000 | C12: =SUMIFS(Stock_Ledger!$K:$K,Stock_Ledger!$D:$D,$A12) | D12: =COUNTIFS(Stock_Ledger!$D:$D,$A12) | E12: =IF(B12=0,0,C12/B12) | F12: =IF(E12>0.9,"FULL",IF(C12=0,"EMPTY","OK"))
A13: C3 | B13: 2000 | C13: =SUMIFS(Stock_Ledger!$K:$K,Stock_Ledger!$D:$D,$A13) | D13: =COUNTIFS(Stock_Ledger!$D:$D,$A13) | E13: =IF(B13=0,0,C13/B13) | F13: =IF(E13>0.9,"FULL",IF(C13=0,"EMPTY","OK"))
A14: C4 | B14: 2000 | C14: =SUMIFS(Stock_Ledger!$K:$K,Stock_Ledger!$D:$D,$A14) | D14: =COUNTIFS(Stock_Ledger!$D:$D,$A14) | E14: =IF(B14=0,0,C14/B14) | F14: =IF(E14>0.9,"FULL",IF(C14=0,"EMPTY","OK"))

Sheet Entry
A1: Entry — key today's movements here, then copy the row into the matching Raw_* sheet
A3: date (dd-mmm-yy) | B3: type | C3: sku | D3: qty | E3: unit_cost (receipts only) | F3: sku name (auto) | G3: bin (auto)
A4: 46314 | F4: =IF(C4="","",VLOOKUP(C4,SKU_Master!$A:$B,2,FALSE)) | G4: =IF(C4="","",VLOOKUP(C4,SKU_Master!$A:$G,7,FALSE))
A5: 46314 | F5: =IF(C5="","",VLOOKUP(C5,SKU_Master!$A:$B,2,FALSE)) | G5: =IF(C5="","",VLOOKUP(C5,SKU_Master!$A:$G,7,FALSE))
A6: 46314 | F6: =IF(C6="","",VLOOKUP(C6,SKU_Master!$A:$B,2,FALSE)) | G6: =IF(C6="","",VLOOKUP(C6,SKU_Master!$A:$G,7,FALSE))
A7: 46314 | F7: =IF(C7="","",VLOOKUP(C7,SKU_Master!$A:$B,2,FALSE)) | G7: =IF(C7="","",VLOOKUP(C7,SKU_Master!$A:$G,7,FALSE))
A8: 46314 | F8: =IF(C8="","",VLOOKUP(C8,SKU_Master!$A:$B,2,FALSE)) | G8: =IF(C8="","",VLOOKUP(C8,SKU_Master!$A:$G,7,FALSE))
A9: 46314 | F9: =IF(C9="","",VLOOKUP(C9,SKU_Master!$A:$B,2,FALSE)) | G9: =IF(C9="","",VLOOKUP(C9,SKU_Master!$A:$G,7,FALSE))
A10: 46314 | F10: =IF(C10="","",VLOOKUP(C10,SKU_Master!$A:$B,2,FALSE)) | G10: =IF(C10="","",VLOOKUP(C10,SKU_Master!$A:$G,7,FALSE))
A11: 46314 | F11: =IF(C11="","",VLOOKUP(C11,SKU_Master!$A:$B,2,FALSE)) | G11: =IF(C11="","",VLOOKUP(C11,SKU_Master!$A:$G,7,FALSE))
A12: 46314 | F12: =IF(C12="","",VLOOKUP(C12,SKU_Master!$A:$B,2,FALSE)) | G12: =IF(C12="","",VLOOKUP(C12,SKU_Master!$A:$G,7,FALSE))
A13: 46314 | F13: =IF(C13="","",VLOOKUP(C13,SKU_Master!$A:$B,2,FALSE)) | G13: =IF(C13="","",VLOOKUP(C13,SKU_Master!$A:$G,7,FALSE))
A14: 46314 | F14: =IF(C14="","",VLOOKUP(C14,SKU_Master!$A:$B,2,FALSE)) | G14: =IF(C14="","",VLOOKUP(C14,SKU_Master!$A:$G,7,FALSE))
A15: 46314 | F15: =IF(C15="","",VLOOKUP(C15,SKU_Master!$A:$B,2,FALSE)) | G15: =IF(C15="","",VLOOKUP(C15,SKU_Master!$A:$G,7,FALSE))
... A23: 46314 | F23: =IF(C23="","",VLOOKUP(C23,SKU_Master!$A:$B,2,FALSE)) | G23: =IF(C23="","",VLOOKUP(C23,SKU_Master!$A:$G,7,FALSE))
A26: How it works: pick type + SKU from the dropdowns, enter qty; the name/bin fill in automatically. Then copy the row into Raw_Receipts (needs unit_cost), Raw_Issues or Raw_Adjustments (qty may be negative). Use negative qty for damaged/expired stock.
A27: Automation note: these Raw_* tables are plain ranges with AutoFilter (no Table objects) so the workbook recalculates in Excel, LibreOffice and Google Sheets. A 2-minute Power Query 'append new rows' routine is described on PowerBI_Model.

Sheet Dashboard
A1: Dashboard — KPIs (all formula-linked)
A3: Total SKUs | B3: =COUNTA(Stock_Ledger!$A$3:$A$38) | AA3: =IF(Stock_Ledger!$C3=$B$52,Stock_Ledger!$M3,0)
A4: Total stock value | B4: =SUM(Stock_Ledger!$M$3:$M$38) | AA4: =IF(Stock_Ledger!$C4=$B$52,Stock_Ledger!$M4,0)
A5: SKUs on REORDER | B5: =COUNTIF(Stock_Ledger!$P$3:$P$38,"REORDER") | AA5: =IF(Stock_Ledger!$C5=$B$52,Stock_Ledger!$M5,0)
A6: STOCKOUT SKUs | B6: =COUNTIF(Stock_Ledger!$P$3:$P$38,"STOCKOUT") | AA6: =IF(Stock_Ledger!$C6=$B$52,Stock_Ledger!$M6,0)
A7: OVERSTOCK SKUs | B7: =COUNTIF(Stock_Ledger!$P$3:$P$38,"OVERSTOCK") | AA7: =IF(Stock_Ledger!$C7=$B$52,Stock_Ledger!$M7,0)
A8: Avg days of cover | B8: =AVERAGEIF(Stock_Ledger!$O$3:$O$38,"<900") | AA8: =IF(Stock_Ledger!$C8=$B$52,Stock_Ledger!$M8,0)
A9: Receipts value (period) | B9: =SUM(Raw_Receipts!$G:$G) | AA9: =IF(Stock_Ledger!$C9=$B$52,Stock_Ledger!$M9,0)
A10: Issues qty (period) | B10: =SUM(Raw_Issues!$D:$D) | AA10: =IF(Stock_Ledger!$C10=$B$52,Stock_Ledger!$M10,0)
AA11: =IF(Stock_Ledger!$C11=$B$52,Stock_Ledger!$M11,0)
AA12: =IF(Stock_Ledger!$C12=$B$52,Stock_Ledger!$M12,0)
A13: Stock value by category | AA13: =IF(Stock_Ledger!$C13=$B$52,Stock_Ledger!$M13,0)
A14: Category | B14: Stock value | C14: SKUs | AA14: =IF(Stock_Ledger!$C14=$B$52,Stock_Ledger!$M14,0)
A15: Beverages | B15: =SUMIFS(Stock_Ledger!$M:$M,Stock_Ledger!$C:$C,$A15) | C15: =COUNTIFS(Stock_Ledger!$C:$C,$A15) | AA15: =IF(Stock_Ledger!$C15=$B$52,Stock_Ledger!$M15,0)
A16: Household | B16: =SUMIFS(Stock_Ledger!$M:$M,Stock_Ledger!$C:$C,$A16) | C16: =COUNTIFS(Stock_Ledger!$C:$C,$A16) | AA16: =IF(Stock_Ledger!$C16=$B$52,Stock_Ledger!$M16,0)
A17: Personal Care | B17: =SUMIFS(Stock_Ledger!$M:$M,Stock_Ledger!$C:$C,$A17) | C17: =COUNTIFS(Stock_Ledger!$C:$C,$A17) | AA17: =IF(Stock_Ledger!$C17=$B$52,Stock_Ledger!$M17,0)
A18: Snacks | B18: =SUMIFS(Stock_Ledger!$M:$M,Stock_Ledger!$C:$C,$A18) | C18: =COUNTIFS(Stock_Ledger!$C:$C,$A18) | AA18: =IF(Stock_Ledger!$C18=$B$52,Stock_Ledger!$M18,0)
A19: Staples | B19: =SUMIFS(Stock_Ledger!$M:$M,Stock_Ledger!$C:$C,$A19) | C19: =COUNTIFS(Stock_Ledger!$C:$C,$A19) | AA19: =IF(Stock_Ledger!$C19=$B$52,Stock_Ledger!$M19,0)
AA20: =IF(Stock_Ledger!$C20=$B$52,Stock_Ledger!$M20,0)
AA21: =IF(Stock_Ledger!$C21=$B$52,Stock_Ledger!$M21,0)
A22: Daily receipts vs issues (qty) | AA22: =IF(Stock_Ledger!$C22=$B$52,Stock_Ledger!$M22,0)
A23: Date | B23: Receipts qty | C23: Issues qty | AA23: =IF(Stock_Ledger!$C23=$B$52,Stock_Ledger!$M23,0)
A24: 46296 | B24: =SUMIFS(Raw_Receipts!$D:$D,Raw_Receipts!$A:$A,$A24) | C24: =SUMIFS(Raw_Issues!$D:$D,Raw_Issues!$A:$A,$A24) | AA24: =IF(Stock_Ledger!$C24=$B$52,Stock_Ledger!$M24,0)
A25: 46297 | B25: =SUMIFS(Raw_Receipts!$D:$D,Raw_Receipts!$A:$A,$A25) | C25: =SUMIFS(Raw_Issues!$D:$D,Raw_Issues!$A:$A,$A25) | AA25: =IF(Stock_Ledger!$C25=$B$52,Stock_Ledger!$M25,0)
A26: 46298 | B26: =SUMIFS(Raw_Receipts!$D:$D,Raw_Receipts!$A:$A,$A26) | C26: =SUMIFS(Raw_Issues!$D:$D,Raw_Issues!$A:$A,$A26) | AA26: =IF(Stock_Ledger!$C26=$B$52,Stock_Ledger!$M26,0)
A27: 46299 | B27: =SUMIFS(Raw_Receipts!$D:$D,Raw_Receipts!$A:$A,$A27) | C27: =SUMIFS(Raw_Issues!$D:$D,Raw_Issues!$A:$A,$A27) | AA27: =IF(Stock_Ledger!$C27=$B$52,Stock_Ledger!$M27,0)
A28: 46300 | B28: =SUMIFS(Raw_Receipts!$D:$D,Raw_Receipts!$A:$A,$A28) | C28: =SUMIFS(Raw_Issues!$D:$D,Raw_Issues!$A:$A,$A28) | AA28: =IF(Stock_Ledger!$C28=$B$52,Stock_Ledger!$M28,0)
A29: 46301 | B29: =SUMIFS(Raw_Receipts!$D:$D,Raw_Receipts!$A:$A,$A29) | C29: =SUMIFS(Raw_Issues!$D:$D,Raw_Issues!$A:$A,$A29) | AA29: =IF(Stock_Ledger!$C29=$B$52,Stock_Ledger!$M29,0)
A30: 46302 | B30: =SUMIFS(Raw_Receipts!$D:$D,Raw_Receipts!$A:$A,$A30) | C30: =SUMIFS(Raw_Issues!$D:$D,Raw_Issues!$A:$A,$A30) | AA30: =IF(Stock_Ledger!$C30=$B$52,Stock_Ledger!$M30,0)
A31: 46303 | B31: =SUMIFS(Raw_Receipts!$D:$D,Raw_Receipts!$A:$A,$A31) | C31: =SUMIFS(Raw_Issues!$D:$D,Raw_Issues!$A:$A,$A31) | AA31: =IF(Stock_Ledger!$C31=$B$52,Stock_Ledger!$M31,0)
A32: 46304 | B32: =SUMIFS(Raw_Receipts!$D:$D,Raw_Receipts!$A:$A,$A32) | C32: =SUMIFS(Raw_Issues!$D:$D,Raw_Issues!$A:$A,$A32) | AA32: =IF(Stock_Ledger!$C32=$B$52,Stock_Ledger!$M32,0)
A33: 46305 | B33: =SUMIFS(Raw_Receipts!$D:$D,Raw_Receipts!$A:$A,$A33) | C33: =SUMIFS(Raw_Issues!$D:$D,Raw_Issues!$A:$A,$A33) | AA33: =IF(Stock_Ledger!$C33=$B$52,Stock_Ledger!$M33,0)
A34: 46306 | B34: =SUMIFS(Raw_Receipts!$D:$D,Raw_Receipts!$A:$A,$A34) | C34: =SUMIFS(Raw_Issues!$D:$D,Raw_Issues!$A:$A,$A34) | AA34: =IF(Stock_Ledger!$C34=$B$52,Stock_Ledger!$M34,0)
A35: 46307 | B35: =SUMIFS(Raw_Receipts!$D:$D,Raw_Receipts!$A:$A,$A35) | C35: =SUMIFS(Raw_Issues!$D:$D,Raw_Issues!$A:$A,$A35) | AA35: =IF(Stock_Ledger!$C35=$B$52,Stock_Ledger!$M35,0)
... A38: 46310 | B38: =SUMIFS(Raw_Receipts!$D:$D,Raw_Receipts!$A:$A,$A38) | C38: =SUMIFS(Raw_Issues!$D:$D,Raw_Issues!$A:$A,$A38) | AA38: =IF(Stock_Ledger!$C38=$B$52,Stock_Ledger!$M38,0)
A39: 46311 | B39: =SUMIFS(Raw_Receipts!$D:$D,Raw_Receipts!$A:$A,$A39) | C39: =SUMIFS(Raw_Issues!$D:$D,Raw_Issues!$A:$A,$A39)
A40: 46312 | B40: =SUMIFS(Raw_Receipts!$D:$D,Raw_Receipts!$A:$A,$A40) | C40: =SUMIFS(Raw_Issues!$D:$D,Raw_Issues!$A:$A,$A40)
A41: 46313 | B41: =SUMIFS(Raw_Receipts!$D:$D,Raw_Receipts!$A:$A,$A41) | C41: =SUMIFS(Raw_Issues!$D:$D,Raw_Issues!$A:$A,$A41)
A44: Stock status mix
A45: Status | B45: SKUs
...

Sheet AI_Report
A1: AI_Report — rule-based narrative (recalculates with the data)
A3: Key findings
B4: =Dashboard!B4
A5: ="Stock on hand is "&TEXT(B4,"₹#,##0")&" across "&TEXT(Dashboard!B3,"0")&" SKUs. "&TEXT(B5,"0")&" SKUs need reorder and "&TEXT(B6,"0")&" are stocked out." | B5: =Dashboard!B5
A6: Flags | B6: =Dashboard!B6
A7: =IF(B6>0,"⚠ "&B13&" is STOCKED OUT — expedite purchase or transfer","✓ No stockouts") | B7: =SUMIFS(Stock_Ledger!$M:$M,Stock_Ledger!$P:$P,"OVERSTOCK")
A8: =IF(B5>3,"⚠ "&TEXT(B5,"0")&" SKUs at/below reorder level — raise POs for "&TEXT(B14,"#,##0")&" units total","✓ Reorder list is short") | B8: =Dashboard!B9
A9: =IF(B7/B4>0.2,"⚠ "&TEXT(B7,"₹#,##0")&" ("&TEXT(B7/B4,"0%")&") sits in OVERSTOCK — pause buying there","✓ No material overstock") | B9: =Dashboard!B10
A10: =IF(B10>0.2,"⚠ Dispatches up "&TEXT(B10,"0%")&" in the second half of the period — watch fast movers","✓ Dispatch pace is steady") | B10: =IF(SUMIFS(Raw_Issues!$D:$D,Raw_Issues!$A:$A,"<"&DATE(2026,10,10))=0,0,SUMIFS(Raw_Issues!$D:$D,Raw_Issues!$A:$A,">="&DATE(2026,10,10))/SUMIFS(Raw_Issues!$D:$D,Raw_Issues!$A:$A,"<"&DATE(2026,10,10))-1)
A11: =IF(B11>0.4,"⚠ One category holds "&TEXT(B11,"0%")&" of stock value — concentration risk","✓ Stock value spread across categories") | B11: =MAX(Dashboard!B15:B19)/Dashboard!B4
A12: =IF(B12>0,"⚠ "&TEXT(B12,"0")&" bins are over 90% full — rebalance","✓ Bin utilisation is healthy") | B12: =COUNTIF(Bin_Map!$F:$F,"FULL")
A13: =IF(SUMPRODUCT((Stock_Ledger!$K$3:$K$38<0)+0)>0,"⚠ Negative closing stock exists — data error","✓ No negative stock") | B13: =IFERROR(INDEX(Stock_Ledger!$A:$A,MATCH("STOCKOUT",Stock_Ledger!$P:$P,0)),"none")
A14: "ℹ Next: paste today&apos;s rows into Raw_* and the ledger, bins, dashboard and this report all refresh." | B14: =SUM(Stock_Ledger!$Q:$Q)

Sheet Checks
A1: Checks — all must be TRUE after recalculation
A2: Check | B2: Result
A3: Ledger closing = opening + receipts − issues + adjustments (all SKUs) | B3: =SUMPRODUCT(ABS(Stock_Ledger!$K$3:$K$38-(Stock_Ledger!$F$3:$F$38+Stock_Ledger!$G$3:$G$38-Stock_Ledger!$I$3:$I$38+Stock_Ledger!$J$3:$J$38)))<0.01
A4: No negative closing stock | B4: =COUNTIF(Stock_Ledger!$K$3:$K$38,"<0")=0
A5: Stock value = SUM(closing × WAC) | B5: =ABS(SUM(Stock_Ledger!$M$3:$M$38)-SUMPRODUCT(Stock_Ledger!$K$3:$K$38,Stock_Ledger!$L$3:$L$38))<1
A6: Bin quantities tie to ledger closings | B6: =ABS(SUM(Bin_Map!$C$3:$C$14)-SUM(Stock_Ledger!$K$3:$K$38))<0.01
A7: Receipts value ties raw ↔ ledger | B7: =ABS(SUM(Raw_Receipts!$G:$G)-SUM(Stock_Ledger!$H$3:$H$38))<0.01
A8: Issues qty ties raw ↔ ledger | B8: =SUM(Raw_Issues!$D:$D)=SUM(Stock_Ledger!$I$3:$I$38)
A9: Status counts add up to total SKUs | B9: =(COUNTIF(Stock_Ledger!$P$3:$P$38,"OK")+COUNTIF(Stock_Ledger!$P$3:$P$38,"REORDER")+COUNTIF(Stock_Ledger!$P$3:$P$38,"STOCKOUT")+COUNTIF(Stock_Ledger!$P$3:$P$38,"OVERSTOCK"))=COUNTA(Stock_Ledger!$A$3:$A$38)
A10: No orphan SKUs in raw tables (all exist in SKU_Master) | B10: =SUMPRODUCT((COUNTIF(SKU_Master!$A:$A,Raw_Receipts!$C$2:$C$128)=0)+0)+SUMPRODUCT((COUNTIF(SKU_Master!$A:$A,Raw_Issues!$C$2:$C$224)=0)+0)+SUMPRODUCT((COUNTIF(SKU_Master!$A:$A,Raw_Adjustments!$C$2:$C$18)=0)+0)=0

Sheet PowerBI_Model
A1: PowerBI_Model — star schema + DAX for the Power BI dashboard
A3: GRAIN: one row per SKU per day (fact_inventory_daily.csv).
A4: Dimensions: dim_sku (36 SKUs, category, bin), dim_bin (12 bins, capacity),
A5: dim_date (2026-10-01 .. 2026-12-31). All CSVs live in powerbi/.
A6: Relationships: fact[sku] → dim_sku[sku]; fact[bin] → dim_bin[bin];
A7: fact[date] → dim_date[date] (all single-direction, many-to-one).
A9: DAX MEASURES (also in powerbi/MEASURES.md):
A10: Closing Qty = SUM(fact[closing_qty])
A11: Stock Value = SUMX(fact, fact[closing_qty] * RELATED(dim_sku[wac]))
A12: Days of Cover = DIVIDE([Closing Qty], DIVIDE(SUM(fact[issues_qty]), 18))
A13: Reorder SKUs = COUNTROWS(FILTER(VALUES(dim_sku[sku]), [Closing Qty] <=
A14: MAX(dim_sku[reorder_level])))
... A29: Power BI drill-through page filtered by dim_sku[category].
