Workbook

Sheet Sales
A1: Date | B1: Invoice | C1: Customer | D1: Product | E1: Category | F1: Qty | G1: Rate | H1: Amount | I1: COGS
A2: 46113 | B2: INV-2604-0001 | C2: Dubey Kirana | D2: Mango Juice 1L | E2: Beverages | F2: 39 | G2: 125.72 | H2: =F2*G2 | I2: =F2*VLOOKUP(D2,Products!$B$2:$E$13,3,FALSE)
A3: 46113 | B3: INV-2604-0002 | C3: Sharma Provision | D3: Curd Cup 400g | E3: Dairy | F3: 34 | G3: 44.45 | H3: =F3*G3 | I3: =F3*VLOOKUP(D3,Products!$B$2:$E$13,3,FALSE)
A4: 46113 | B4: INV-2604-0003 | C4: Verma Retail | D4: Packaged Water 1L | E4: Beverages | F4: 18 | G4: 20.81 | H4: =F4*G4 | I4: =F4*VLOOKUP(D4,Products!$B$2:$E$13,3,FALSE)
A5: 46113 | B5: INV-2604-0004 | C5: Tiwari General | D5: Cola 750ml | E5: Beverages | F5: 43 | G5: 46.01 | H5: =F5*G5 | I5: =F5*VLOOKUP(D5,Products!$B$2:$E$13,3,FALSE)
A6: 46113 | B6: INV-2604-0005 | C6: Raza Brothers | D6: Cola 750ml | E6: Beverages | F6: 52 | G6: 43.95 | H6: =F6*G6 | I6: =F6*VLOOKUP(D6,Products!$B$2:$E$13,3,FALSE)
A7: 46113 | B7: INV-2604-0006 | C7: Jha Provisions | D7: Biscuits 400g | E7: Snacks | F7: 43 | G7: 40.89 | H7: =F7*G7 | I7: =F7*VLOOKUP(D7,Products!$B$2:$E$13,3,FALSE)
A8: 46113 | B8: INV-2604-0007 | C8: Choudhary Mart | D8: Cola 750ml | E8: Beverages | F8: 24 | G8: 43.99 | H8: =F8*G8 | I8: =F8*VLOOKUP(D8,Products!$B$2:$E$13,3,FALSE)
A9: 46113 | B9: INV-2604-0008 | C9: Kumari Kirana | D9: Paneer 200g | E9: Dairy | F9: 47 | G9: 94.71 | H9: =F9*G9 | I9: =F9*VLOOKUP(D9,Products!$B$2:$E$13,3,FALSE)
A10: 46114 | B10: INV-2604-0009 | C10: Sinha Super Mart | D10: Paneer 200g | E10: Dairy | F10: 60 | G10: 94.38 | H10: =F10*G10 | I10: =F10*VLOOKUP(D10,Products!$B$2:$E$13,3,FALSE)
A11: 46114 | B11: INV-2604-0010 | C11: Sahu Traders | D11: Mango Juice 1L | E11: Beverages | F11: 56 | G11: 125.41 | H11: =F11*G11 | I11: =F11*VLOOKUP(D11,Products!$B$2:$E$13,3,FALSE)
A12: 46114 | B12: INV-2604-0011 | C12: Sharma Provision | D12: Cola 750ml | E12: Beverages | F12: 16 | G12: 46.62 | H12: =F12*G12 | I12: =F12*VLOOKUP(D12,Products!$B$2:$E$13,3,FALSE)
A13: 46114 | B13: INV-2604-0012 | C13: Prasad Traders | D13: Cola 750ml | E13: Beverages | F13: 25 | G13: 43.8 | H13: =F13*G13 | I13: =F13*VLOOKUP(D13,Products!$B$2:$E$13,3,FALSE)
... A1480: 46160 | B1480: INV-2605-1489 | C1480: Singh Super Bazaar | D1480: Mango Juice 1L | E1480: Beverages | F1480: 4000 | G1480: 118 | H1480: =F1480*G1480 | I1480: =F1480*VLOOKUP(D1480,Products!$B$2:$E$13,3,FALSE)
H1481: =F1481*G1481 | I1481: =IF(D1481="","",F1481*VLOOKUP(D1481,Products!$B$2:$E$13,3,FALSE))
H1482: =F1482*G1482 | I1482: =IF(D1482="","",F1482*VLOOKUP(D1482,Products!$B$2:$E$13,3,FALSE))
H1483: =F1483*G1483 | I1483: =IF(D1483="","",F1483*VLOOKUP(D1483,Products!$B$2:$E$13,3,FALSE))
H1484: =F1484*G1484 | I1484: =IF(D1484="","",F1484*VLOOKUP(D1484,Products!$B$2:$E$13,3,FALSE))
H1485: =F1485*G1485 | I1485: =IF(D1485="","",F1485*VLOOKUP(D1485,Products!$B$2:$E$13,3,FALSE))
H1486: =F1486*G1486 | I1486: =IF(D1486="","",F1486*VLOOKUP(D1486,Products!$B$2:$E$13,3,FALSE))
H1487: =F1487*G1487 | I1487: =IF(D1487="","",F1487*VLOOKUP(D1487,Products!$B$2:$E$13,3,FALSE))
H1488: =F1488*G1488 | I1488: =IF(D1488="","",F1488*VLOOKUP(D1488,Products!$B$2:$E$13,3,FALSE))
H1489: =F1489*G1489 | I1489: =IF(D1489="","",F1489*VLOOKUP(D1489,Products!$B$2:$E$13,3,FALSE))
H1490: =F1490*G1490 | I1490: =IF(D1490="","",F1490*VLOOKUP(D1490,Products!$B$2:$E$13,3,FALSE))
H1491: =F1491*G1491 | I1491: =IF(D1491="","",F1491*VLOOKUP(D1491,Products!$B$2:$E$13,3,FALSE))
H1492: =F1492*G1492 | I1492: =IF(D1492="","",F1492*VLOOKUP(D1492,Products!$B$2:$E$13,3,FALSE))
... H2500: =F2500*G2500 | I2500: =IF(D2500="","",F2500*VLOOKUP(D2500,Products!$B$2:$E$13,3,FALSE))

Sheet Purchases
A1: Date | B1: Bill | C1: Supplier | D1: Product | E1: Category | F1: Qty | G1: CostRate | H1: Amount
A2: 46113 | B2: BIL-2604-0001 | C2: Patliputra Agencies | D2: Biscuits 400g | E2: Snacks | F2: 114 | G2: 30.01 | H2: =F2*G2
A3: 46115 | B3: BIL-2604-0002 | C3: Ganga FMCG Supply | D3: Packaged Water 1L | E3: Beverages | F3: 337 | G3: 14.96 | H3: =F3*G3
A4: 46115 | B4: BIL-2604-0003 | C4: Nalanda Distribution | D4: Potato Chips 150g | E4: Snacks | F4: 58 | G4: 38.34 | H4: =F4*G4
A5: 46115 | B5: BIL-2604-0004 | C5: Patliputra Agencies | D5: Dish Soap 500ml | E5: Household | F5: 328 | G5: 80.47 | H5: =F5*G5
A6: 46115 | B6: BIL-2604-0005 | C6: Vaishali Supply House | D6: Instant Noodles 280g | E6: Snacks | F6: 342 | G6: 42.73 | H6: =F6*G6
A7: 46116 | B7: BIL-2604-0006 | C7: Bihar Foods Distributors | D7: Floor Cleaner 1L | E7: Household | F7: 312 | G7: 88.19 | H7: =F7*G7
A8: 46116 | B8: BIL-2604-0007 | C8: Koshi Enterprises | D8: Instant Noodles 280g | E8: Snacks | F8: 325 | G8: 41.5 | H8: =F8*G8
A9: 46116 | B9: BIL-2604-0008 | C9: Ganga FMCG Supply | D9: Detergent 1kg | E9: Household | F9: 114 | G9: 106.29 | H9: =F9*G9
A10: 46117 | B10: BIL-2604-0009 | C10: Ganga FMCG Supply | D10: Floor Cleaner 1L | E10: Household | F10: 308 | G10: 87.41 | H10: =F10*G10
A11: 46117 | B11: BIL-2604-0010 | C11: Vaishali Supply House | D11: Detergent 1kg | E11: Household | F11: 293 | G11: 103.62 | H11: =F11*G11
A12: 46117 | B12: BIL-2604-0011 | C12: Patliputra Agencies | D12: Toned Milk 1L | E12: Dairy | F12: 300 | G12: 55.05 | H12: =F12*G12
A13: 46118 | B13: BIL-2604-0012 | C13: Magadh Wholesale Co. | D13: Detergent 1kg | E13: Household | F13: 292 | G13: 105.4 | H13: =F13*G13
... A357: 46295 | B357: BIL-2609-0356 | C357: Vaishali Supply House | D357: Cola 750ml | E357: Beverages | F357: 294 | G357: 35.39 | H357: =F357*G357
H358: =F358*G358
H359: =F359*G359
H360: =F360*G360
H361: =F361*G361
H362: =F362*G362
H363: =F363*G363
H364: =F364*G364
H365: =F365*G365
H366: =F366*G366
H367: =F367*G367
H368: =F368*G368
H369: =F369*G369
... H1500: =F1500*G1500

Sheet Products
A1: Code | B1: Product | C1: Category | D1: StdCost | E1: TotalSales | F1: TotalQty
A2: P001 | B2: Mango Juice 1L | C2: Beverages | D2: =AVERAGEIF(Purchases!$D$2:$D$2000,B2,Purchases!$G$2:$G$2000) | E2: =SUMIF(Sales!$D$2:$D$5000,B2,Sales!$H$2:$H$5000) | F2: =SUMIF(Sales!$D$2:$D$5000,B2,Sales!$F$2:$F$5000)
A3: P002 | B3: Cola 750ml | C3: Beverages | D3: =AVERAGEIF(Purchases!$D$2:$D$2000,B3,Purchases!$G$2:$G$2000) | E3: =SUMIF(Sales!$D$2:$D$5000,B3,Sales!$H$2:$H$5000) | F3: =SUMIF(Sales!$D$2:$D$5000,B3,Sales!$F$2:$F$5000)
A4: P003 | B4: Packaged Water 1L | C4: Beverages | D4: =AVERAGEIF(Purchases!$D$2:$D$2000,B4,Purchases!$G$2:$G$2000) | E4: =SUMIF(Sales!$D$2:$D$5000,B4,Sales!$H$2:$H$5000) | F4: =SUMIF(Sales!$D$2:$D$5000,B4,Sales!$F$2:$F$5000)
A5: P004 | B5: Potato Chips 150g | C5: Snacks | D5: =AVERAGEIF(Purchases!$D$2:$D$2000,B5,Purchases!$G$2:$G$2000) | E5: =SUMIF(Sales!$D$2:$D$5000,B5,Sales!$H$2:$H$5000) | F5: =SUMIF(Sales!$D$2:$D$5000,B5,Sales!$F$2:$F$5000)
A6: P005 | B6: Biscuits 400g | C6: Snacks | D6: =AVERAGEIF(Purchases!$D$2:$D$2000,B6,Purchases!$G$2:$G$2000) | E6: =SUMIF(Sales!$D$2:$D$5000,B6,Sales!$H$2:$H$5000) | F6: =SUMIF(Sales!$D$2:$D$5000,B6,Sales!$F$2:$F$5000)
A7: P006 | B7: Instant Noodles 280g | C7: Snacks | D7: =AVERAGEIF(Purchases!$D$2:$D$2000,B7,Purchases!$G$2:$G$2000) | E7: =SUMIF(Sales!$D$2:$D$5000,B7,Sales!$H$2:$H$5000) | F7: =SUMIF(Sales!$D$2:$D$5000,B7,Sales!$F$2:$F$5000)
A8: P007 | B8: Toned Milk 1L | C8: Dairy | D8: =AVERAGEIF(Purchases!$D$2:$D$2000,B8,Purchases!$G$2:$G$2000) | E8: =SUMIF(Sales!$D$2:$D$5000,B8,Sales!$H$2:$H$5000) | F8: =SUMIF(Sales!$D$2:$D$5000,B8,Sales!$F$2:$F$5000)
A9: P008 | B9: Paneer 200g | C9: Dairy | D9: =AVERAGEIF(Purchases!$D$2:$D$2000,B9,Purchases!$G$2:$G$2000) | E9: =SUMIF(Sales!$D$2:$D$5000,B9,Sales!$H$2:$H$5000) | F9: =SUMIF(Sales!$D$2:$D$5000,B9,Sales!$F$2:$F$5000)
A10: P009 | B10: Curd Cup 400g | C10: Dairy | D10: =AVERAGEIF(Purchases!$D$2:$D$2000,B10,Purchases!$G$2:$G$2000) | E10: =SUMIF(Sales!$D$2:$D$5000,B10,Sales!$H$2:$H$5000) | F10: =SUMIF(Sales!$D$2:$D$5000,B10,Sales!$F$2:$F$5000)
A11: P010 | B11: Detergent 1kg | C11: Household | D11: =AVERAGEIF(Purchases!$D$2:$D$2000,B11,Purchases!$G$2:$G$2000) | E11: =SUMIF(Sales!$D$2:$D$5000,B11,Sales!$H$2:$H$5000) | F11: =SUMIF(Sales!$D$2:$D$5000,B11,Sales!$F$2:$F$5000)
A12: P011 | B12: Dish Soap 500ml | C12: Household | D12: =AVERAGEIF(Purchases!$D$2:$D$2000,B12,Purchases!$G$2:$G$2000) | E12: =SUMIF(Sales!$D$2:$D$5000,B12,Sales!$H$2:$H$5000) | F12: =SUMIF(Sales!$D$2:$D$5000,B12,Sales!$F$2:$F$5000)
A13: P012 | B13: Floor Cleaner 1L | C13: Household | D13: =AVERAGEIF(Purchases!$D$2:$D$2000,B13,Purchases!$G$2:$G$2000) | E13: =SUMIF(Sales!$D$2:$D$5000,B13,Sales!$H$2:$H$5000) | F13: =SUMIF(Sales!$D$2:$D$5000,B13,Sales!$F$2:$F$5000)

Sheet Monthly
A1: Month | B1: Sales | C1: Purchases | D1: COGS | E1: GrossProfit | F1: Margin% | G1: SeasonalityIdx
A2: 46113 | B2: =SUMIFS(Sales!$H$2:$H$5000,Sales!$A$2:$A$5000,">="&A2,Sales!$A$2:$A$5000,"<"&EDATE(A2,1)) | C2: =SUMIFS(Purchases!$H$2:$H$2000,Purchases!$A$2:$A$2000,">="&A2,Purchases!$A$2:$A$2000,"<"&EDATE(A2,1)) | D2: =SUMIFS(Sales!$I$2:$I$5000,Sales!$A$2:$A$5000,">="&A2,Sales!$A$2:$A$5000,"<"&EDATE(A2,1)) | E2: =B2-D2 | F2: =IF(B2=0,0,E2/B2) | G2: =B2/AVERAGE($B$2:$B$7)
A3: 46143 | B3: =SUMIFS(Sales!$H$2:$H$5000,Sales!$A$2:$A$5000,">="&A3,Sales!$A$2:$A$5000,"<"&EDATE(A3,1)) | C3: =SUMIFS(Purchases!$H$2:$H$2000,Purchases!$A$2:$A$2000,">="&A3,Purchases!$A$2:$A$2000,"<"&EDATE(A3,1)) | D3: =SUMIFS(Sales!$I$2:$I$5000,Sales!$A$2:$A$5000,">="&A3,Sales!$A$2:$A$5000,"<"&EDATE(A3,1)) | E3: =B3-D3 | F3: =IF(B3=0,0,E3/B3) | G3: =B3/AVERAGE($B$2:$B$7)
A4: 46174 | B4: =SUMIFS(Sales!$H$2:$H$5000,Sales!$A$2:$A$5000,">="&A4,Sales!$A$2:$A$5000,"<"&EDATE(A4,1)) | C4: =SUMIFS(Purchases!$H$2:$H$2000,Purchases!$A$2:$A$2000,">="&A4,Purchases!$A$2:$A$2000,"<"&EDATE(A4,1)) | D4: =SUMIFS(Sales!$I$2:$I$5000,Sales!$A$2:$A$5000,">="&A4,Sales!$A$2:$A$5000,"<"&EDATE(A4,1)) | E4: =B4-D4 | F4: =IF(B4=0,0,E4/B4) | G4: =B4/AVERAGE($B$2:$B$7)
A5: 46204 | B5: =SUMIFS(Sales!$H$2:$H$5000,Sales!$A$2:$A$5000,">="&A5,Sales!$A$2:$A$5000,"<"&EDATE(A5,1)) | C5: =SUMIFS(Purchases!$H$2:$H$2000,Purchases!$A$2:$A$2000,">="&A5,Purchases!$A$2:$A$2000,"<"&EDATE(A5,1)) | D5: =SUMIFS(Sales!$I$2:$I$5000,Sales!$A$2:$A$5000,">="&A5,Sales!$A$2:$A$5000,"<"&EDATE(A5,1)) | E5: =B5-D5 | F5: =IF(B5=0,0,E5/B5) | G5: =B5/AVERAGE($B$2:$B$7)
A6: 46235 | B6: =SUMIFS(Sales!$H$2:$H$5000,Sales!$A$2:$A$5000,">="&A6,Sales!$A$2:$A$5000,"<"&EDATE(A6,1)) | C6: =SUMIFS(Purchases!$H$2:$H$2000,Purchases!$A$2:$A$2000,">="&A6,Purchases!$A$2:$A$2000,"<"&EDATE(A6,1)) | D6: =SUMIFS(Sales!$I$2:$I$5000,Sales!$A$2:$A$5000,">="&A6,Sales!$A$2:$A$5000,"<"&EDATE(A6,1)) | E6: =B6-D6 | F6: =IF(B6=0,0,E6/B6) | G6: =B6/AVERAGE($B$2:$B$7)
A7: 46266 | B7: =SUMIFS(Sales!$H$2:$H$5000,Sales!$A$2:$A$5000,">="&A7,Sales!$A$2:$A$5000,"<"&EDATE(A7,1)) | C7: =SUMIFS(Purchases!$H$2:$H$2000,Purchases!$A$2:$A$2000,">="&A7,Purchases!$A$2:$A$2000,"<"&EDATE(A7,1)) | D7: =SUMIFS(Sales!$I$2:$I$5000,Sales!$A$2:$A$5000,">="&A7,Sales!$A$2:$A$5000,"<"&EDATE(A7,1)) | E7: =B7-D7 | F7: =IF(B7=0,0,E7/B7) | G7: =B7/AVERAGE($B$2:$B$7)

Sheet Daily
A1: Date | B1: Sales | C1: Avg | D1: Stdev | E1: Upper(2s) | F1: Lower(2s) | G1: Flag
A2: 46113 | B2: =SUMIF(Sales!$A$2:$A$5000,A2,Sales!$H$2:$H$5000) | C2: =AVERAGE($B$2:$B$184) | D2: =STDEVP($B$2:$B$184) | E2: =C2+2*D2 | F2: =MAX(0,C2-2*D2) | G2: =IF(OR(B2>E2,B2<F2,AND(B2=0,C2>0)),"ANOMALY","")
A3: 46114 | B3: =SUMIF(Sales!$A$2:$A$5000,A3,Sales!$H$2:$H$5000) | C3: =AVERAGE($B$2:$B$184) | D3: =STDEVP($B$2:$B$184) | E3: =C2+2*D2 | F3: =MAX(0,C2-2*D2) | G3: =IF(OR(B3>E3,B3<F3,AND(B3=0,C3>0)),"ANOMALY","")
A4: 46115 | B4: =SUMIF(Sales!$A$2:$A$5000,A4,Sales!$H$2:$H$5000) | C4: =AVERAGE($B$2:$B$184) | D4: =STDEVP($B$2:$B$184) | E4: =C2+2*D2 | F4: =MAX(0,C2-2*D2) | G4: =IF(OR(B4>E4,B4<F4,AND(B4=0,C4>0)),"ANOMALY","")
A5: 46116 | B5: =SUMIF(Sales!$A$2:$A$5000,A5,Sales!$H$2:$H$5000) | C5: =AVERAGE($B$2:$B$184) | D5: =STDEVP($B$2:$B$184) | E5: =C2+2*D2 | F5: =MAX(0,C2-2*D2) | G5: =IF(OR(B5>E5,B5<F5,AND(B5=0,C5>0)),"ANOMALY","")
A6: 46117 | B6: =SUMIF(Sales!$A$2:$A$5000,A6,Sales!$H$2:$H$5000) | C6: =AVERAGE($B$2:$B$184) | D6: =STDEVP($B$2:$B$184) | E6: =C2+2*D2 | F6: =MAX(0,C2-2*D2) | G6: =IF(OR(B6>E6,B6<F6,AND(B6=0,C6>0)),"ANOMALY","")
A7: 46118 | B7: =SUMIF(Sales!$A$2:$A$5000,A7,Sales!$H$2:$H$5000) | C7: =AVERAGE($B$2:$B$184) | D7: =STDEVP($B$2:$B$184) | E7: =C2+2*D2 | F7: =MAX(0,C2-2*D2) | G7: =IF(OR(B7>E7,B7<F7,AND(B7=0,C7>0)),"ANOMALY","")
A8: 46119 | B8: =SUMIF(Sales!$A$2:$A$5000,A8,Sales!$H$2:$H$5000) | C8: =AVERAGE($B$2:$B$184) | D8: =STDEVP($B$2:$B$184) | E8: =C2+2*D2 | F8: =MAX(0,C2-2*D2) | G8: =IF(OR(B8>E8,B8<F8,AND(B8=0,C8>0)),"ANOMALY","")
A9: 46120 | B9: =SUMIF(Sales!$A$2:$A$5000,A9,Sales!$H$2:$H$5000) | C9: =AVERAGE($B$2:$B$184) | D9: =STDEVP($B$2:$B$184) | E9: =C2+2*D2 | F9: =MAX(0,C2-2*D2) | G9: =IF(OR(B9>E9,B9<F9,AND(B9=0,C9>0)),"ANOMALY","")
A10: 46121 | B10: =SUMIF(Sales!$A$2:$A$5000,A10,Sales!$H$2:$H$5000) | C10: =AVERAGE($B$2:$B$184) | D10: =STDEVP($B$2:$B$184) | E10: =C2+2*D2 | F10: =MAX(0,C2-2*D2) | G10: =IF(OR(B10>E10,B10<F10,AND(B10=0,C10>0)),"ANOMALY","")
A11: 46122 | B11: =SUMIF(Sales!$A$2:$A$5000,A11,Sales!$H$2:$H$5000) | C11: =AVERAGE($B$2:$B$184) | D11: =STDEVP($B$2:$B$184) | E11: =C2+2*D2 | F11: =MAX(0,C2-2*D2) | G11: =IF(OR(B11>E11,B11<F11,AND(B11=0,C11>0)),"ANOMALY","")
A12: 46123 | B12: =SUMIF(Sales!$A$2:$A$5000,A12,Sales!$H$2:$H$5000) | C12: =AVERAGE($B$2:$B$184) | D12: =STDEVP($B$2:$B$184) | E12: =C2+2*D2 | F12: =MAX(0,C2-2*D2) | G12: =IF(OR(B12>E12,B12<F12,AND(B12=0,C12>0)),"ANOMALY","")
A13: 46124 | B13: =SUMIF(Sales!$A$2:$A$5000,A13,Sales!$H$2:$H$5000) | C13: =AVERAGE($B$2:$B$184) | D13: =STDEVP($B$2:$B$184) | E13: =C2+2*D2 | F13: =MAX(0,C2-2*D2) | G13: =IF(OR(B13>E13,B13<F13,AND(B13=0,C13>0)),"ANOMALY","")
A14: 46125 | B14: =SUMIF(Sales!$A$2:$A$5000,A14,Sales!$H$2:$H$5000) | C14: =AVERAGE($B$2:$B$184) | D14: =STDEVP($B$2:$B$184) | E14: =C2+2*D2 | F14: =MAX(0,C2-2*D2) | G14: =IF(OR(B14>E14,B14<F14,AND(B14=0,C14>0)),"ANOMALY","")
A15: 46126 | B15: =SUMIF(Sales!$A$2:$A$5000,A15,Sales!$H$2:$H$5000) | C15: =AVERAGE($B$2:$B$184) | D15: =STDEVP($B$2:$B$184) | E15: =C2+2*D2 | F15: =MAX(0,C2-2*D2) | G15: =IF(OR(B15>E15,B15<F15,AND(B15=0,C15>0)),"ANOMALY","")
A16: 46127 | B16: =SUMIF(Sales!$A$2:$A$5000,A16,Sales!$H$2:$H$5000) | C16: =AVERAGE($B$2:$B$184) | D16: =STDEVP($B$2:$B$184) | E16: =C2+2*D2 | F16: =MAX(0,C2-2*D2) | G16: =IF(OR(B16>E16,B16<F16,AND(B16=0,C16>0)),"ANOMALY","")
A17: 46128 | B17: =SUMIF(Sales!$A$2:$A$5000,A17,Sales!$H$2:$H$5000) | C17: =AVERAGE($B$2:$B$184) | D17: =STDEVP($B$2:$B$184) | E17: =C2+2*D2 | F17: =MAX(0,C2-2*D2) | G17: =IF(OR(B17>E17,B17<F17,AND(B17=0,C17>0)),"ANOMALY","")
A18: 46129 | B18: =SUMIF(Sales!$A$2:$A$5000,A18,Sales!$H$2:$H$5000) | C18: =AVERAGE($B$2:$B$184) | D18: =STDEVP($B$2:$B$184) | E18: =C2+2*D2 | F18: =MAX(0,C2-2*D2) | G18: =IF(OR(B18>E18,B18<F18,AND(B18=0,C18>0)),"ANOMALY","")
A19: 46130 | B19: =SUMIF(Sales!$A$2:$A$5000,A19,Sales!$H$2:$H$5000) | C19: =AVERAGE($B$2:$B$184) | D19: =STDEVP($B$2:$B$184) | E19: =C2+2*D2 | F19: =MAX(0,C2-2*D2) | G19: =IF(OR(B19>E19,B19<F19,AND(B19=0,C19>0)),"ANOMALY","")
A20: 46131 | B20: =SUMIF(Sales!$A$2:$A$5000,A20,Sales!$H$2:$H$5000) | C20: =AVERAGE($B$2:$B$184) | D20: =STDEVP($B$2:$B$184) | E20: =C2+2*D2 | F20: =MAX(0,C2-2*D2) | G20: =IF(OR(B20>E20,B20<F20,AND(B20=0,C20>0)),"ANOMALY","")
A21: 46132 | B21: =SUMIF(Sales!$A$2:$A$5000,A21,Sales!$H$2:$H$5000) | C21: =AVERAGE($B$2:$B$184) | D21: =STDEVP($B$2:$B$184) | E21: =C2+2*D2 | F21: =MAX(0,C2-2*D2) | G21: =IF(OR(B21>E21,B21<F21,AND(B21=0,C21>0)),"ANOMALY","")
A22: 46133 | B22: =SUMIF(Sales!$A$2:$A$5000,A22,Sales!$H$2:$H$5000) | C22: =AVERAGE($B$2:$B$184) | D22: =STDEVP($B$2:$B$184) | E22: =C2+2*D2 | F22: =MAX(0,C2-2*D2) | G22: =IF(OR(B22>E22,B22<F22,AND(B22=0,C22>0)),"ANOMALY","")
A23: 46134 | B23: =SUMIF(Sales!$A$2:$A$5000,A23,Sales!$H$2:$H$5000) | C23: =AVERAGE($B$2:$B$184) | D23: =STDEVP($B$2:$B$184) | E23: =C2+2*D2 | F23: =MAX(0,C2-2*D2) | G23: =IF(OR(B23>E23,B23<F23,AND(B23=0,C23>0)),"ANOMALY","")
A24: 46135 | B24: =SUMIF(Sales!$A$2:$A$5000,A24,Sales!$H$2:$H$5000) | C24: =AVERAGE($B$2:$B$184) | D24: =STDEVP($B$2:$B$184) | E24: =C2+2*D2 | F24: =MAX(0,C2-2*D2) | G24: =IF(OR(B24>E24,B24<F24,AND(B24=0,C24>0)),"ANOMALY","")
A25: 46136 | B25: =SUMIF(Sales!$A$2:$A$5000,A25,Sales!$H$2:$H$5000) | C25: =AVERAGE($B$2:$B$184) | D25: =STDEVP($B$2:$B$184) | E25: =C2+2*D2 | F25: =MAX(0,C2-2*D2) | G25: =IF(OR(B25>E25,B25<F25,AND(B25=0,C25>0)),"ANOMALY","")
A26: 46137 | B26: =SUMIF(Sales!$A$2:$A$5000,A26,Sales!$H$2:$H$5000) | C26: =AVERAGE($B$2:$B$184) | D26: =STDEVP($B$2:$B$184) | E26: =C2+2*D2 | F26: =MAX(0,C2-2*D2) | G26: =IF(OR(B26>E26,B26<F26,AND(B26=0,C26>0)),"ANOMALY","")
A27: 46138 | B27: =SUMIF(Sales!$A$2:$A$5000,A27,Sales!$H$2:$H$5000) | C27: =AVERAGE($B$2:$B$184) | D27: =STDEVP($B$2:$B$184) | E27: =C2+2*D2 | F27: =MAX(0,C2-2*D2) | G27: =IF(OR(B27>E27,B27<F27,AND(B27=0,C27>0)),"ANOMALY","")
A28: 46139 | B28: =SUMIF(Sales!$A$2:$A$5000,A28,Sales!$H$2:$H$5000) | C28: =AVERAGE($B$2:$B$184) | D28: =STDEVP($B$2:$B$184) | E28: =C2+2*D2 | F28: =MAX(0,C2-2*D2) | G28: =IF(OR(B28>E28,B28<F28,AND(B28=0,C28>0)),"ANOMALY","")
A29: 46140 | B29: =SUMIF(Sales!$A$2:$A$5000,A29,Sales!$H$2:$H$5000) | C29: =AVERAGE($B$2:$B$184) | D29: =STDEVP($B$2:$B$184) | E29: =C2+2*D2 | F29: =MAX(0,C2-2*D2) | G29: =IF(OR(B29>E29,B29<F29,AND(B29=0,C29>0)),"ANOMALY","")
A30: 46141 | B30: =SUMIF(Sales!$A$2:$A$5000,A30,Sales!$H$2:$H$5000) | C30: =AVERAGE($B$2:$B$184) | D30: =STDEVP($B$2:$B$184) | E30: =C2+2*D2 | F30: =MAX(0,C2-2*D2) | G30: =IF(OR(B30>E30,B30<F30,AND(B30=0,C30>0)),"ANOMALY","")
A31: 46142 | B31: =SUMIF(Sales!$A$2:$A$5000,A31,Sales!$H$2:$H$5000) | C31: =AVERAGE($B$2:$B$184) | D31: =STDEVP($B$2:$B$184) | E31: =C2+2*D2 | F31: =MAX(0,C2-2*D2) | G31: =IF(OR(B31>E31,B31<F31,AND(B31=0,C31>0)),"ANOMALY","")
A32: 46143 | B32: =SUMIF(Sales!$A$2:$A$5000,A32,Sales!$H$2:$H$5000) | C32: =AVERAGE($B$2:$B$184) | D32: =STDEVP($B$2:$B$184) | E32: =C2+2*D2 | F32: =MAX(0,C2-2*D2) | G32: =IF(OR(B32>E32,B32<F32,AND(B32=0,C32>0)),"ANOMALY","")
A33: 46144 | B33: =SUMIF(Sales!$A$2:$A$5000,A33,Sales!$H$2:$H$5000) | C33: =AVERAGE($B$2:$B$184) | D33: =STDEVP($B$2:$B$184) | E33: =C2+2*D2 | F33: =MAX(0,C2-2*D2) | G33: =IF(OR(B33>E33,B33<F33,AND(B33=0,C33>0)),"ANOMALY","")
A34: 46145 | B34: =SUMIF(Sales!$A$2:$A$5000,A34,Sales!$H$2:$H$5000) | C34: =AVERAGE($B$2:$B$184) | D34: =STDEVP($B$2:$B$184) | E34: =C2+2*D2 | F34: =MAX(0,C2-2*D2) | G34: =IF(OR(B34>E34,B34<F34,AND(B34=0,C34>0)),"ANOMALY","")
A35: 46146 | B35: =SUMIF(Sales!$A$2:$A$5000,A35,Sales!$H$2:$H$5000) | C35: =AVERAGE($B$2:$B$184) | D35: =STDEVP($B$2:$B$184) | E35: =C2+2*D2 | F35: =MAX(0,C2-2*D2) | G35: =IF(OR(B35>E35,B35<F35,AND(B35=0,C35>0)),"ANOMALY","")
A36: 46147 | B36: =SUMIF(Sales!$A$2:$A$5000,A36,Sales!$H$2:$H$5000) | C36: =AVERAGE($B$2:$B$184) | D36: =STDEVP($B$2:$B$184) | E36: =C2+2*D2 | F36: =MAX(0,C2-2*D2) | G36: =IF(OR(B36>E36,B36<F36,AND(B36=0,C36>0)),"ANOMALY","")
A37: 46148 | B37: =SUMIF(Sales!$A$2:$A$5000,A37,Sales!$H$2:$H$5000) | C37: =AVERAGE($B$2:$B$184) | D37: =STDEVP($B$2:$B$184) | E37: =C2+2*D2 | F37: =MAX(0,C2-2*D2) | G37: =IF(OR(B37>E37,B37<F37,AND(B37=0,C37>0)),"ANOMALY","")
A38: 46149 | B38: =SUMIF(Sales!$A$2:$A$5000,A38,Sales!$H$2:$H$5000) | C38: =AVERAGE($B$2:$B$184) | D38: =STDEVP($B$2:$B$184) | E38: =C2+2*D2 | F38: =MAX(0,C2-2*D2) | G38: =IF(OR(B38>E38,B38<F38,AND(B38=0,C38>0)),"ANOMALY","")
A39: 46150 | B39: =SUMIF(Sales!$A$2:$A$5000,A39,Sales!$H$2:$H$5000) | C39: =AVERAGE($B$2:$B$184) | D39: =STDEVP($B$2:$B$184) | E39: =C2+2*D2 | F39: =MAX(0,C2-2*D2) | G39: =IF(OR(B39>E39,B39<F39,AND(B39=0,C39>0)),"ANOMALY","")
A40: 46151 | B40: =SUMIF(Sales!$A$2:$A$5000,A40,Sales!$H$2:$H$5000) | C40: =AVERAGE($B$2:$B$184) | D40: =STDEVP($B$2:$B$184) | E40: =C2+2*D2 | F40: =MAX(0,C2-2*D2) | G40: =IF(OR(B40>E40,B40<F40,AND(B40=0,C40>0)),"ANOMALY","")
...

Sheet Dashboard
A1: Verma Trading Co., Patna (fictional demo data)
A2: Consolidated MIS dashboard — every figure below is a live formula over the Sales / Purchases ranges. Paste new rows into those tables and this page refreshes.
A4: KEY PERFORMANCE INDICATORS
A5: Total Sales (Rs.) | C5: Total Purchases (Rs.) | E5: Gross Profit (Rs.) | G5: Margin %
A6: =SUM(Sales!$H$2:$H$5000) | C6: =SUM(Purchases!$H$2:$H$2000) | E6: =SUM(Sales!$H$2:$H$5000)-SUM(Sales!$I$2:$I$5000) | G6: =IF(SUM(Sales!$H$2:$H$5000)=0,0,(SUM(Sales!$H$2:$H$5000)-SUM(Sales!$I$2:$I$5000))/SUM(Sales!$H$2:$H$5000))
A8: Transactions | C8: Avg Ticket (Rs.) | E8: Anomaly Days | G8: Products Sold
A9: =COUNTA(Sales!$B$2:$B$5000) | C9: =AVERAGE(Sales!$H$2:$H$5000) | E9: =COUNTIF(Daily!$G$2:$G$184,"ANOMALY") | G9: =SUMPRODUCT(--(Products!$E$2:$E$13>0))
A12: Sales by Category | E12: Top 5 Products by Sales
A13: Category | B13: Sales | E13: Product | F13: Sales
A14: Beverages | B14: =SUMIF(Sales!$E$2:$E$5000,A14,Sales!$H$2:$H$5000) | E14: =INDEX(Products!$B$2:$B$13,MATCH(LARGE(Products!$E$2:$E$13,1),Products!$E$2:$E$13,0)) | F14: =LARGE(Products!$E$2:$E$13,1)
A15: Dairy | B15: =SUMIF(Sales!$E$2:$E$5000,A15,Sales!$H$2:$H$5000) | E15: =INDEX(Products!$B$2:$B$13,MATCH(LARGE(Products!$E$2:$E$13,2),Products!$E$2:$E$13,0)) | F15: =LARGE(Products!$E$2:$E$13,2)
A16: Household | B16: =SUMIF(Sales!$E$2:$E$5000,A16,Sales!$H$2:$H$5000) | E16: =INDEX(Products!$B$2:$B$13,MATCH(LARGE(Products!$E$2:$E$13,3),Products!$E$2:$E$13,0)) | F16: =LARGE(Products!$E$2:$E$13,3)
A17: Snacks | B17: =SUMIF(Sales!$E$2:$E$5000,A17,Sales!$H$2:$H$5000) | E17: =INDEX(Products!$B$2:$B$13,MATCH(LARGE(Products!$E$2:$E$13,4),Products!$E$2:$E$13,0)) | F17: =LARGE(Products!$E$2:$E$13,4)
E18: =INDEX(Products!$B$2:$B$13,MATCH(LARGE(Products!$E$2:$E$13,5),Products!$E$2:$E$13,0)) | F18: =LARGE(Products!$E$2:$E$13,5)

Sheet Checks
A1: INTEGRITY CHECKS — all must read OK
A2: Check | B2: Difference | C2: Status
A3: Sales amounts = Qty x Rate on every row | B3: =SUM(Sales!$H$2:$H$5000)-SUMPRODUCT(Sales!$F$2:$F$5000,Sales!$G$2:$G$5000) | C3: =IF(ABS(B3)<0.01,"OK","FAIL")
A4: Purchase amounts = Qty x CostRate on every row | B4: =SUM(Purchases!$H$2:$H$2000)-SUMPRODUCT(Purchases!$F$2:$F$2000,Purchases!$G$2:$G$2000) | C4: =IF(ABS(B4)<0.01,"OK","FAIL")
A5: No negative quantities | B5: =SUMPRODUCT(--(Sales!$F$2:$F$5000<0))+SUMPRODUCT(--(Purchases!$F$2:$F$2000<0)) | C5: =IF(B5=0,"OK","FAIL")
A6: All sale products exist in master | B6: =SUMPRODUCT(--(Sales!$D$2:$D$5000<>""),--ISNA(MATCH(Sales!$D$2:$D$5000,Products!$B$2:$B$13,0))) | C6: =IF(B6=0,"OK","FAIL")
A7: Dates inside Apr-Sep 2026 | B7: =SUMPRODUCT(--(Sales!$A$2:$A$5000<>""),--((Sales!$A$2:$A$5000<DATE(2026,4,1))+(Sales!$A$2:$A$5000>DATE(2026,9,30)))) | C7: =IF(B7=0,"OK","FAIL")
A8: Every product has a StdCost | B8: =SUMPRODUCT(--(Products!$D$2:$D$13=0)) | C8: =IF(B8=0,"OK","FAIL")

Sheet Guide
A1: HANDOVER GUIDE — keeping this MIS fresh
A3: 1. Paste new daily rows at the bottom of the Sales / Purchases data ranges (rows 2-5000 / 2-2000 carry formula headroom; Amount and COGS columns are pre-filled with formulas down to the headroom limit — copy the last formula row down if you outgrow it).
A4: 2. Never type over the blue formula columns (Amount, COGS, StdCost, TotalSales, TotalQty) — they recalculate on paste.
A5: 3. Formula ranges carry headroom (Sales rows 2-5000, Purchases 2-2000): if you outgrow them, extend the range ends in the formulas.
A6: 4. Monthly, Daily, Dashboard and Checks sheets need no manual refresh: open the file and Excel recalculates.
A7: 5. Charts read the Monthly / Dashboard tables, so new months appear once you extend the Monthly sheet's month column.
A8: 6. Checks sheet: every row must read OK before the weekly review — a FAIL pinpoints the exact broken rule.
A9: 7. Anomaly flags (Daily sheet) use avg ± 2 standard deviations on daily sales: investigate any ANOMALY row before the management meeting.
A10: Source files simulated here as data/*.csv (two sales parts + one purchases file, mirroring the client's several workbooks); in production, import each client workbook into the Sales / Purchases tables (Data > From Text/CSV) or paste directly.
