Workbook

Sheet Register
A1: Demo Traders (FICTIONAL — synthetic demo data)
A2: Cleaned asset register. Line totals and the Summary sheet are Excel formulas — see BEFORE_AFTER.md.
A3: Asset ID | B3: Item | C3: Category | D3: Purchase Date | E3: Quantity | F3: Unit Price | G3: Line Total | H3: Status | I3: Location | J3: Flag | K3: Notes
A4: AST-032 | B4: Office Printer — S/N 1032 | C4: IT Equipment | D4: 45046 | E4: 1 | F4: 5184 | G4: =IF(OR(E4="",F4=""),"",E4*F4) | H4: In Storage | I4: Patna | K4: Date '30 Apr 2023' normalised; Price '₹5,184' converted to 5184
A5: AST-009 | B5: Bookshelf — S/N 1009 | C5: Furniture | D5: 44895 | E5: 4 | F5: 2733 | G5: =IF(OR(E5="",F5=""),"",E5*F5) | H5: In Use | I5: Delhi | K5: Date '30.11.2022' normalised; Quantity text '4' converted to number; Price 'Rs. 2733' converted to 2733
A6: AST-014 | B6: Pickup Truck — S/N 1014 | C6: Vehicle | D6: 45080 | E6: 7 | F6: 86918 | G6: =IF(OR(E6="",F6=""),"",E6*F6) | H6: In Storage | I6: Mumbai | K6: Date '03.06.2023' normalised; Price 'INR 86,918' converted to 86918
A7: AST-007 | B7: Tool Chest — S/N 1007 | C7: Tools | D7: 44821 | E7: 10 | F7: 1859 | G7: =IF(OR(E7="",F7=""),"",E7*F7) | H7: In Use | I7: Kolkata
A8: AST-026 | B8: Pickup Truck — S/N 1026 | C8: Vehicle | D8: 44824 | E8: 7 | F8: 88562 | G8: =IF(OR(E8="",F8=""),"",E8*F8) | H8: In Storage | I8: Mumbai | K8: Date '2022-09-20' normalised; Price 'INR 88,562' converted to 88562
A9: AST-049 | B9: Bookshelf — S/N 1049 | C9: Furniture | D9: 44975 | E9: 4 | F9: 8213 | G9: =IF(OR(E9="",F9=""),"",E9*F9) | H9: In Use | I9: Delhi | K9: Date '18.02.2023' normalised; Price 'Rs. 8213' converted to 8213
A10: AST-028 | B10: External Hard Drive — S/N 1028 | C10: IT Equipment | D10: 44898 | E10: 1 | F10: 4636 | G10: =IF(OR(E10="",F10=""),"",E10*F10) | H10: Under Repair | I10: Patna | K10: Date 'December 03, 2022' normalised; Price '₹4,636' converted to 4636
A11: AST-040 | B11: External Hard Drive — S/N 1040 | C11: IT Equipment | D11: 44642 | E11: 1 | F11: 6280 | G11: =IF(OR(E11="",F11=""),"",E11*F11) | H11: Under Repair | I11: Patna | K11: Date '22/03/2022' normalised; Price '₹6,280' converted to 6280
A12: AST-004 | B12: External Hard Drive — S/N 1004 | C12: IT Equipment | D12: 44710 | E12: 1 | F12: 1348 | G12: =IF(OR(E12="",F12=""),"",E12*F12) | H12: Under Repair | I12: Patna | K12: Date '29.05.2022' normalised; Price '₹1,348' converted to 1348
A13: AST-022 | B13: Scooter — S/N 1022 | C13: Vehicle | D13: 44676 | E13: 7 | F13: 88014 | G13: =IF(OR(E13="",F13=""),"",E13*F13) | H13: Under Repair | I13: Mumbai | K13: Date '25 Apr 2022' normalised; Price 'INR 88,014' converted to 88014
A14: AST-037 | B14: Filing Cabinet — S/N 1037 | C14: Furniture | D14: 45231 | E14: 4 | F14: 6569 | G14: =IF(OR(E14="",F14=""),"",E14*F14) | H14: In Use | I14: Delhi | K14: Date '01 Nov 2023' normalised; Price 'Rs. 6569' converted to 6569
A15: AST-012 | B15: Laptop 14in — S/N 1012 | C15: IT Equipment | D15: 45006 | E15: 1 | F15: 2444 | G15: =IF(OR(E15="",F15=""),"",E15*F15) | H15: In Use | I15: Patna | K15: Date '21 Mar 2023' normalised; Price '₹2,444' converted to 2444
A16: AST-031 | B16: Welding Kit — S/N 1031 | C16: Tools | D16: 45009 | E16: 10 | F16: 45 | G16: =IF(OR(E16="",F16=""),"",E16*F16) | H16: In Use | I16: Kolkata | J16: Price currency symbol was '$' — verify currency | K16: Date '2023-03-24' normalised; Price '$45' converted to 45 (currency symbol was '$' — figure kept as supplied; verify currency)
A17: AST-030 | B17: Delivery Van — S/N 1030 | C17: Vehicle | D17: 44972 | E17: 7 | F17: 89110 | G17: =IF(OR(E17="",F17=""),"",E17*F17) | H17: In Use | I17: Mumbai | K17: Date '15/02/2023' normalised; Price 'INR 89,110' converted to 89110
A18: AST-045 | B18: Office Chair — S/N 1045 | C18: Furniture | D18: 44827 | E18: 4 | F18: 7665 | G18: =IF(OR(E18="",F18=""),"",E18*F18) | H18: In Use | I18: Delhi | K18: Date '23/09/2022' normalised; Price 'Rs. 7665' converted to 7665
A19: AST-001 | B19: Work Desk — S/N 1001 | C19: Furniture | D19: 44599 | E19: 4 | F19: 1637 | G19: =IF(OR(E19="",F19=""),"",E19*F19) | H19: In Use | I19: Delhi | K19: Date '2022-02-07' normalised; Price 'Rs. 1637' converted to 1637
A20: AST-024 | B20: Laptop 14in — S/N 1024 | C20: IT Equipment | D20: 44750 | E20: 1 | F20: 4088 | G20: =IF(OR(E20="",F20=""),"",E20*F20) | H20: In Use | I20: Patna | K20: Date '08.07.2022' normalised; Price '₹4,088' converted to 4088
A21: AST-005 | B21: Office Chair — S/N 1005 | C21: Furniture | D21: 44747 | F21: 2185 | G21: =IF(OR(E21="",F21=""),"",E21*F21) | H21: Disposed | I21: Delhi | J21: Quantity missing — line total not computed | K21: Date '05/07/2022' normalised; Quantity missing; Price 'Rs. 2185' converted to 2185
A22: AST-053 | B22: Conference Table — S/N 1053 | C22: Furniture | D22: 45123 | E22: 4 | F22: 8761 | G22: =IF(OR(E22="",F22=""),"",E22*F22) | H22: Disposed | I22: Delhi | K22: Date 'July 16, 2023' normalised; Price 'Rs. 8761' converted to 8761
A23: AST-033 | B23: Conference Table — S/N 1033 | C23: Furniture | D23: 45083 | E23: 4 | F23: 6021 | G23: =IF(OR(E23="",F23=""),"",E23*F23) | H23: In Use | I23: Delhi | K23: Date 'June 06, 2023' normalised; Quantity text '4' converted to number; Price 'Rs. 6021' converted to 6021
A24: AST-015 | B24: Drill Machine — S/N 1015 | C24: Tools | D24: 45117 | E24: 10 | F24: 2955 | G24: =IF(OR(E24="",F24=""),"",E24*F24) | H24: In Use | I24: Kolkata | K24: Date '10/07/2023' normalised
A25: AST-046 | B25: Scooter — S/N 1046 | C25: Vehicle | D25: 44864 | E25: 7 | F25: 91302 | G25: =IF(OR(E25="",F25=""),"",E25*F25) | H25: Under Repair | I25: Mumbai | K25: Date '2022-10-30' normalised; Price 'INR 91,302' converted to 91302
A26: AST-020 | B26: Office Printer — S/N 1020 | C26: IT Equipment | D26: 44602 | E26: 1 | F26: 3540 | G26: =IF(OR(E26="",F26=""),"",E26*F26) | H26: In Storage | I26: Patna | K26: Date '10/02/2022' normalised; Price '₹3,540' converted to 3540
A27: AST-039 | B27: Air Compressor — S/N 1039 | C27: Tools | D27: 44605 | E27: 10 | F27: 6243 | G27: =IF(OR(E27="",F27=""),"",E27*F27) | H27: In Use | I27: Kolkata | K27: Date '13.02.2022' normalised
A28: AST-052 | B28: External Hard Drive — S/N 1052 | C28: IT Equipment | D28: 45086 | E28: 1 | F28: 7924 | G28: =IF(OR(E28="",F28=""),"",E28*F28) | H28: Under Repair | I28: Patna | K28: Date '09 Jun 2023' normalised; Price '₹7,924' converted to 7924
A29: AST-025 | B29: Office Chair — S/N 1025 | C29: Furniture | D29: 44787 | E29: 4 | F29: 4925 | G29: =IF(OR(E29="",F29=""),"",E29*F29) | H29: In Use | I29: Delhi | K29: Date '14/08/2022' normalised; Price 'Rs. 4925' converted to 4925
A30: AST-013 | B30: Conference Table — S/N 1013 | C30: Furniture | D30: 45043 | E30: 4 | F30: 3281 | G30: =IF(OR(E30="",F30=""),"",E30*F30) | H30: In Use | I30: Delhi | K30: Date 'April 27, 2023' normalised; Price 'Rs. 3281' converted to 3281
A31: AST-016 | B31: External Hard Drive — S/N 1016 | C31: IT Equipment | D31: 45154 | E31: 1 | F31: 2992 | G31: =IF(OR(E31="",F31=""),"",E31*F31) | H31: Under Repair | I31: Patna | K31: Date '2023-08-16' normalised; Price '₹2,992' converted to 2992
A32: AST-050 | B32: Pickup Truck — S/N 1050 | C32: Vehicle | D32: 45012 | E32: 7 | F32: 91850 | G32: =IF(OR(E32="",F32=""),"",E32*F32) | H32: In Storage | I32: Mumbai | K32: Date '27/03/2023' normalised; Price 'INR 91,850' converted to 91850
A33: AST-054 | B33: Delivery Van — S/N 1054 | C33: Vehicle | D33: 45160 | E33: 7 | F33: 92398 | G33: =IF(OR(E33="",F33=""),"",E33*F33) | H33: In Use | I33: Mumbai | K33: Date '22.08.2023' normalised; Price 'INR 92,398' converted to 92398
... A36: AST-029 | B36: Bookshelf — S/N 1029 | C36: Furniture | D36: 44935 | E36: 4 | F36: 5473 | G36: =IF(OR(E36="",F36=""),"",E36*F36) | H36: Disposed | I36: Delhi | K36: Date '09.01.2023' normalised; Price 'Rs. 5473' converted to 5473
A37: AST-023 | B37: Generator — S/N 1023 | C37: Tools | D37: 44713 | E37: 10 | F37: 4051 | G37: =IF(OR(E37="",F37=""),"",E37*F37) | H37: Disposed | I37: Kolkata
A38: AST-048 | B38: Laptop 14in — S/N 1048 | C38: IT Equipment | D38: 44938 | E38: 1 | F38: 7376 | G38: =IF(OR(E38="",F38=""),"",E38*F38) | H38: In Use | I38: Patna | K38: Date 'January 12, 2023' normalised; Quantity text '1' converted to number; Price '₹7,376' converted to 7376
A39: AST-044 | B39: Office Printer — S/N 1044 | C39: IT Equipment | D39: 44790 | E39: 1 | F39: 6828 | G39: =IF(OR(E39="",F39=""),"",E39*F39) | H39: In Storage | I39: Patna | K39: Date '17.08.2022' normalised; Price '₹6,828' converted to 6828
A40: AST-002 | B40: Pickup Truck — S/N 1002 | C40: Vehicle | D40: 44636 | E40: 7 | F40: 85274 | G40: =IF(OR(E40="",F40=""),"",E40*F40) | H40: In Storage | I40: Mumbai | K40: Date '16 Mar 2022' normalised; Price 'INR 85,274' converted to 85274
A41: AST-006 | B41: Delivery Van — S/N 1006 | C41: Vehicle | D41: 44784 | E41: 7 | F41: 85822 | G41: =IF(OR(E41="",F41=""),"",E41*F41) | H41: In Use | I41: Mumbai | K41: Date '2022-08-11' normalised; Price 'INR 85,822' converted to 85822
A42: AST-011 | B42: Welding Kit — S/N 1011 | C42: Tools | E42: 10 | F42: 2407 | G42: =IF(OR(E42="",F42=""),"",E42*F42) | H42: Disposed | I42: Kolkata | J42: Purchase date could not be parsed | K42: Date '31/02/2024' could not be parsed — left blank
...

Sheet Summary
A1: Asset Register — Summary
A2: All values below are Excel formulas over the Register sheet. Synthetic demo data — fictional business 'Demo Traders'.
A4: Category | B4: Asset Count | C4: Total Value
A5: IT Equipment | B5: =COUNTIF(Register!$C$4:$C$58,A5) | C5: =SUMIF(Register!$C$4:$C$58,A5,Register!$G$4:$G$58)
A6: Furniture | B6: =COUNTIF(Register!$C$4:$C$58,A6) | C6: =SUMIF(Register!$C$4:$C$58,A6,Register!$G$4:$G$58)
A7: Vehicle | B7: =COUNTIF(Register!$C$4:$C$58,A7) | C7: =SUMIF(Register!$C$4:$C$58,A7,Register!$G$4:$G$58)
A8: Tools | B8: =COUNTIF(Register!$C$4:$C$58,A8) | C8: =SUMIF(Register!$C$4:$C$58,A8,Register!$G$4:$G$58)
A9: Grand Total | B9: =SUM(B5:B8) | C9: =SUM(C5:C8)
A11: Total assets (rows) | B11: =COUNTA(Register!$A$4:$A$58)
A12: Flagged rows | B12: =COUNTIF(Register!$J$4:$J$58,"?*")
A14: Build notes (counts recorded at build time, not formulas)
A15: Rows in before.xlsx | B15: 60
A16: Rows in after.xlsx | B16: 55
A17: Duplicate rows removed | B17: 5
