Workbook

Sheet Guide
A1: DPRPulse — Detailed Project Report Financial Model
A3: Fictional demo case: Sharma Agro Foods, turmeric processing unit, Patna (Bihar). Project cost Rs 240 lakh; promoter margin 25%; term loan Rs 180 lakh @ 10% for 7 years (1-yr moratorium).
A5: How to use:
A6: 1. Blue cells on the Assumptions sheet are the ONLY inputs — change them and the whole model recalculates.
A7: 2. Every other number in this workbook is a live formula. Nothing is pasted as a value.
A8: 3. Read order: Assumptions -> Project_Cost -> Means_of_Finance -> Loan_Schedule -> Revenue_Cost -> PL -> CashFlow_DSCR -> BalanceSheet -> Ratios -> Sensitivity -> Dashboard.
A9: 4. The Checks sheet must show TRUE on all 10 rows; the Dashboard carries the banker's summary.
A11: Sheet | B11: What it holds
A12: Assumptions | B12: All model inputs (blue). Utilisation ramp, prices, cost %, loan terms.
A13: Project_Cost | B13: Rs 240 lakh capex split across 7 heads.
A14: Means_of_Finance | B14: Promoter Rs 60 lakh + term loan Rs 180 lakh; margin 25%.
A15: Loan_Schedule | B15: Annual amortisation: 1-yr moratorium, then 6 equal instalments.
A16: Revenue_Cost | B16: Production, price, revenue and the 7 operating-cost lines.
A17: PL | B17: 7-year projected profit & loss; tax 25% on positive PBT.
A18: CashFlow_DSCR | B18: Cash accruals, debt service, DSCR, NPV @12%, equity IRR, payback.
A19: BalanceSheet | B19: Projected balance sheet; assets = liabilities every year.
A20: Ratios | B20: Bank ratios: DSCR, D:E, break-even utilisation, NPV, IRR.
A21: Sensitivity | B21: 4 scenarios: base, revenue -5%, raw +3pp, combined stress.
A22: Dashboard | B22: 8 KPIs, 3 charts, risk flags for the banker.
A23: Checks | B23: 10 mechanical integrity checks — all must read TRUE.

Sheet Assumptions
A1: Parameter | B1: Value | C1: Note
A2: Capacity (MT/year) | B2: 1200
A3: Selling price Y1 (Rs/kg) | B3: 150
A4: Price escalation /yr | B4: 0.03
A5: Capacity utilisation Y1..Y7 | B5: 0.55 | C5: 0.65 | D5: 0.75 | E5: 0.85 | F5: 0.9 | G5: 0.9 | H5: 0.9
A6: Raw material (% of revenue) | B6: 0.76
A7: Packing (% of revenue) | B7: 0.06
A8: Admin & selling (% of revenue) | B8: 0.05
A9: Power & fuel Y1 (Rs lakh) | B9: 22
A10: Power escalation /yr | B10: 0.04
A11: Salaries Y1 (Rs lakh) | B11: 34
A12: Salary escalation /yr | B12: 0.05
A13: Repairs & maintenance (Rs lakh/yr) | B13: 2.2 | C13: flat
A14: Insurance Y1 (Rs lakh) | B14: 1.5
A15: Insurance escalation /yr | B15: 0.03
A16: Depreciation - building (Rs lakh/yr) | B16: 2.75 | C16: 55 / 20 yrs
A17: Depreciation - P&M incl. contingency | B17: 12 | C17: 120 / 10 yrs
A18: Depreciation - electricals | B18: 1.8 | C18: 18 / 10 yrs
A19: Preliminary amortisation Y1-Y5 | B19: 2.4 | C19: 12 / 5 yrs
A20: Corporate tax rate | B20: 0.25 | C20: on positive PBT
A21: Term loan (Rs lakh) | B21: 180
A22: Interest rate /yr | B22: 0.1
A23: Moratorium (years) | B23: 1 | C23: interest serviced
A24: Repayment years | B24: 6 | C24: annual instalments
A25: Promoter equity (Rs lakh) | B25: 60
A26: Discount rate (NPV/IRR hurdle) | B26: 0.12
A27: Project cost total (Rs lakh) | B27: 240 | C27: check vs Project_Cost

Sheet Project_Cost
A1: Head | B1: Rs lakh | C1: % of total
A2: Land & site development | B2: 30 | C2: =B2/$B$9
A3: Building & civil works | B3: 55 | C3: =B3/$B$9
A4: Plant & machinery | B4: 110 | C4: =B4/$B$9
A5: Contingency | B5: 10 | C5: =B5/$B$9
A6: Electricals & utilities | B6: 18 | C6: =B6/$B$9
A7: Preliminary & pre-operative | B7: 12 | C7: =B7/$B$9
A8: Margin for working capital | B8: 5 | C8: =B8/$B$9
A9: TOTAL | B9: =SUM(B2:B8) | C9: =SUM(C2:C8)
A11: Check: total = Rs 240 lakh? | B11: =B9=240

Sheet Means_of_Finance
A1: Source | B1: Rs lakh
A2: Promoter contribution | B2: =Assumptions!$B$25
A3: Term loan | B3: =Assumptions!$B$21
A4: TOTAL | B4: =SUM(B2:B3)
A6: Promoter margin | B6: =B2/B4
A7: Debt-equity (at start) | B7: =B3/B2
A9: Check: total = project cost? | B9: =B4=Project_Cost!$B$9

Sheet Loan_Schedule
A1: Year | B1: 0 | C1: 1 | D1: 2 | E1: 3 | F1: 4 | G1: 5 | H1: 6 | I1: 7
A2: Opening balance | B2: =Assumptions!$B$21 | C2: =B6 | D2: =C6 | E2: =D6 | F2: =E6 | G2: =F6 | H2: =G6 | I2: =H6
A3: Interest | B3: 0 | C3: =C2*Assumptions!$B$22 | D3: =D2*Assumptions!$B$22 | E3: =E2*Assumptions!$B$22 | F3: =F2*Assumptions!$B$22 | G3: =G2*Assumptions!$B$22 | H3: =H2*Assumptions!$B$22 | I3: =I2*Assumptions!$B$22
A4: Annual payment | B4: 0 | C4: =C3 | D4: =-PMT(Assumptions!$B$22,Assumptions!$B$24,Assumptions!$B$21) | E4: =-PMT(Assumptions!$B$22,Assumptions!$B$24,Assumptions!$B$21) | F4: =-PMT(Assumptions!$B$22,Assumptions!$B$24,Assumptions!$B$21) | G4: =-PMT(Assumptions!$B$22,Assumptions!$B$24,Assumptions!$B$21) | H4: =-PMT(Assumptions!$B$22,Assumptions!$B$24,Assumptions!$B$21) | I4: =-PMT(Assumptions!$B$22,Assumptions!$B$24,Assumptions!$B$21)
A5: Principal repaid | B5: 0 | C5: 0 | D5: =D4-D3 | E5: =E4-E3 | F5: =F4-F3 | G5: =G4-G3 | H5: =H4-H3 | I5: =I4-I3
A6: Closing balance | B6: =B2-B5 | C6: =C2-C5 | D6: =D2-D5 | E6: =E2-E5 | F6: =F2-F5 | G6: =G2-G5 | H6: =H2-H5 | I6: =I2-I5
A8: Check: fully repaid by Y7? | B8: =ABS(I6)<0.01
A9: Annuity (Rs lakh, Y2-Y7) | B9: =D4

Sheet Revenue_Cost
A1: Year | B1: 1 | C1: 2 | D1: 3 | E1: 4 | F1: 5 | G1: 6 | H1: 7
A2: Production (kg) | B2: =1200000*Assumptions!B5 | C2: =1200000*Assumptions!C5 | D2: =1200000*Assumptions!D5 | E2: =1200000*Assumptions!E5 | F2: =1200000*Assumptions!F5 | G2: =1200000*Assumptions!G5 | H2: =1200000*Assumptions!H5
A3: Selling price (Rs/kg) | B3: =Assumptions!$B$3 | C3: =B3*(1+Assumptions!$B$4) | D3: =C3*(1+Assumptions!$B$4) | E3: =D3*(1+Assumptions!$B$4) | F3: =E3*(1+Assumptions!$B$4) | G3: =F3*(1+Assumptions!$B$4) | H3: =G3*(1+Assumptions!$B$4)
A4: Revenue (Rs lakh) | B4: =B2*B3/100000 | C4: =C2*C3/100000 | D4: =D2*D3/100000 | E4: =E2*E3/100000 | F4: =F2*F3/100000 | G4: =G2*G3/100000 | H4: =H2*H3/100000
A6: Raw material | B6: =B4*Assumptions!$B$6 | C6: =C4*Assumptions!$B$6 | D6: =D4*Assumptions!$B$6 | E6: =E4*Assumptions!$B$6 | F6: =F4*Assumptions!$B$6 | G6: =G4*Assumptions!$B$6 | H6: =H4*Assumptions!$B$6
A7: Packing | B7: =B4*Assumptions!$B$7 | C7: =C4*Assumptions!$B$7 | D7: =D4*Assumptions!$B$7 | E7: =E4*Assumptions!$B$7 | F7: =F4*Assumptions!$B$7 | G7: =G4*Assumptions!$B$7 | H7: =H4*Assumptions!$B$7
A8: Power & fuel | B8: =Assumptions!$B$9 | C8: =B8*(1+Assumptions!$B$10) | D8: =C8*(1+Assumptions!$B$10) | E8: =D8*(1+Assumptions!$B$10) | F8: =E8*(1+Assumptions!$B$10) | G8: =F8*(1+Assumptions!$B$10) | H8: =G8*(1+Assumptions!$B$10)
A9: Salaries & wages | B9: =Assumptions!$B$11 | C9: =B9*(1+Assumptions!$B$12) | D9: =C9*(1+Assumptions!$B$12) | E9: =D9*(1+Assumptions!$B$12) | F9: =E9*(1+Assumptions!$B$12) | G9: =F9*(1+Assumptions!$B$12) | H9: =G9*(1+Assumptions!$B$12)
A10: Repairs & maintenance | B10: =Assumptions!$B$13 | C10: =Assumptions!$B$13 | D10: =Assumptions!$B$13 | E10: =Assumptions!$B$13 | F10: =Assumptions!$B$13 | G10: =Assumptions!$B$13 | H10: =Assumptions!$B$13
A11: Admin & selling | B11: =B4*Assumptions!$B$8 | C11: =C4*Assumptions!$B$8 | D11: =D4*Assumptions!$B$8 | E11: =E4*Assumptions!$B$8 | F11: =F4*Assumptions!$B$8 | G11: =G4*Assumptions!$B$8 | H11: =H4*Assumptions!$B$8
A12: Insurance | B12: =Assumptions!$B$14 | C12: =B12*(1+Assumptions!$B$15) | D12: =C12*(1+Assumptions!$B$15) | E12: =D12*(1+Assumptions!$B$15) | F12: =E12*(1+Assumptions!$B$15) | G12: =F12*(1+Assumptions!$B$15) | H12: =G12*(1+Assumptions!$B$15)
A13: Total operating cost | B13: =SUM(B6:B12) | C13: =SUM(C6:C12) | D13: =SUM(D6:D12) | E13: =SUM(E6:E12) | F13: =SUM(F6:F12) | G13: =SUM(G6:G12) | H13: =SUM(H6:H12)
A14: EBITDA | B14: =B4-B13 | C14: =C4-C13 | D14: =D4-D13 | E14: =E4-E13 | F14: =F4-F13 | G14: =G4-G13 | H14: =H4-H13

Sheet PL
A1: Year | B1: 1 | C1: 2 | D1: 3 | E1: 4 | F1: 5 | G1: 6 | H1: 7
A2: Revenue | B2: =Revenue_Cost!B4 | C2: =Revenue_Cost!C4 | D2: =Revenue_Cost!D4 | E2: =Revenue_Cost!E4 | F2: =Revenue_Cost!F4 | G2: =Revenue_Cost!G4 | H2: =Revenue_Cost!H4
A3: Total operating cost | B3: =Revenue_Cost!B13 | C3: =Revenue_Cost!C13 | D3: =Revenue_Cost!D13 | E3: =Revenue_Cost!E13 | F3: =Revenue_Cost!F13 | G3: =Revenue_Cost!G13 | H3: =Revenue_Cost!H13
A4: EBITDA | B4: =Revenue_Cost!B14 | C4: =Revenue_Cost!C14 | D4: =Revenue_Cost!D14 | E4: =Revenue_Cost!E14 | F4: =Revenue_Cost!F14 | G4: =Revenue_Cost!G14 | H4: =Revenue_Cost!H14
A5: Depreciation & amortisation | B5: =Assumptions!$B$16+Assumptions!$B$17+Assumptions!$B$18+IF(B$1<=5,Assumptions!$B$19,0) | C5: =Assumptions!$B$16+Assumptions!$B$17+Assumptions!$B$18+IF(C$1<=5,Assumptions!$B$19,0) | D5: =Assumptions!$B$16+Assumptions!$B$17+Assumptions!$B$18+IF(D$1<=5,Assumptions!$B$19,0) | E5: =Assumptions!$B$16+Assumptions!$B$17+Assumptions!$B$18+IF(E$1<=5,Assumptions!$B$19,0) | F5: =Assumptions!$B$16+Assumptions!$B$17+Assumptions!$B$18+IF(F$1<=5,Assumptions!$B$19,0) | G5: =Assumptions!$B$16+Assumptions!$B$17+Assumptions!$B$18+IF(G$1<=5,Assumptions!$B$19,0) | H5: =Assumptions!$B$16+Assumptions!$B$17+Assumptions!$B$18+IF(H$1<=5,Assumptions!$B$19,0)
A6: Interest | B6: =Loan_Schedule!C3 | C6: =Loan_Schedule!D3 | D6: =Loan_Schedule!E3 | E6: =Loan_Schedule!F3 | F6: =Loan_Schedule!G3 | G6: =Loan_Schedule!H3 | H6: =Loan_Schedule!I3
A7: Profit before tax | B7: =B4-B5-B6 | C7: =C4-C5-C6 | D7: =D4-D5-D6 | E7: =E4-E5-E6 | F7: =F4-F5-F6 | G7: =G4-G5-G6 | H7: =H4-H5-H6
A8: Tax | B8: =IF(B7>0,B7*Assumptions!$B$20,0) | C8: =IF(C7>0,C7*Assumptions!$B$20,0) | D8: =IF(D7>0,D7*Assumptions!$B$20,0) | E8: =IF(E7>0,E7*Assumptions!$B$20,0) | F8: =IF(F7>0,F7*Assumptions!$B$20,0) | G8: =IF(G7>0,G7*Assumptions!$B$20,0) | H8: =IF(H7>0,H7*Assumptions!$B$20,0)
A9: Profit after tax | B9: =B7-B8 | C9: =C7-C8 | D9: =D7-D8 | E9: =E7-E8 | F9: =F7-F8 | G9: =G7-G8 | H9: =H7-H8
A10: Cash accruals (PAT + depr.) | B10: =B9+B5 | C10: =C9+C5 | D10: =D9+D5 | E10: =E9+E5 | F10: =F9+F5 | G10: =G9+G5 | H10: =H9+H5

Sheet CashFlow_DSCR
A1: Year | B1: 0 | C1: 1 | D1: 2 | E1: 3 | F1: 4 | G1: 5 | H1: 6 | I1: 7
A2: Cash accruals | B2: 0 | C2: =PL!B10 | D2: =PL!C10 | E2: =PL!D10 | F2: =PL!E10 | G2: =PL!F10 | H2: =PL!G10 | I2: =PL!H10
A3: Debt service (interest + principal) | B3: 0 | C3: =Loan_Schedule!C3+Loan_Schedule!C5 | D3: =Loan_Schedule!D3+Loan_Schedule!D5 | E3: =Loan_Schedule!E3+Loan_Schedule!E5 | F3: =Loan_Schedule!F3+Loan_Schedule!F5 | G3: =Loan_Schedule!G3+Loan_Schedule!G5 | H3: =Loan_Schedule!H3+Loan_Schedule!H5 | I3: =Loan_Schedule!I3+Loan_Schedule!I5
A4: Net cash to equity | B4: =-Assumptions!$B$25 | C4: =C2-Loan_Schedule!C5 | D4: =D2-Loan_Schedule!D5 | E4: =E2-Loan_Schedule!E5 | F4: =F2-Loan_Schedule!F5 | G4: =G2-Loan_Schedule!G5 | H4: =H2-Loan_Schedule!H5 | I4: =I2-Loan_Schedule!I5
A5: Cumulative (incl. Y0 equity) | B5: =B4 | C5: =B5+C4 | D5: =C5+D4 | E5: =D5+E4 | F5: =E5+F4 | G5: =F5+G4 | H5: =G5+H4 | I5: =H5+I4
A6: DSCR | C6: =IF(C3=0,"",C2/C3) | D6: =IF(D3=0,"",D2/D3) | E6: =IF(E3=0,"",E2/E3) | F6: =IF(F3=0,"",F2/F3) | G6: =IF(G3=0,"",G2/G3) | H6: =IF(H3=0,"",H2/H3) | I6: =IF(I3=0,"",I2/I3)
A7: Payback flag | B7: =IF(B5>=0,B$1,"") | C7: =IF(C5>=0,C$1,"") | D7: =IF(D5>=0,D$1,"") | E7: =IF(E5>=0,E$1,"") | F7: =IF(F5>=0,F$1,"") | G7: =IF(G5>=0,G$1,"") | H7: =IF(H5>=0,H$1,"") | I7: =IF(I5>=0,I$1,"")
A9: Average DSCR (Y1-Y7) | B9: =AVERAGE(C6:I6)
A10: Minimum DSCR, repayment years (Y2-Y7) | B10: =MIN(D6:I6)
A11: NPV @12% (Rs lakh) | B11: =B4+NPV(Assumptions!$B$26,C4:I4)
A12: Equity IRR | B12: =IRR(B4:I4)
A13: Payback year | B13: =MIN(B7:I7)
A15: Principal repaid | B15: 0 | C15: =Loan_Schedule!C5 | D15: =Loan_Schedule!D5 | E15: =Loan_Schedule!E5 | F15: =Loan_Schedule!F5 | G15: =Loan_Schedule!G5 | H15: =Loan_Schedule!H5 | I15: =Loan_Schedule!I5
A16: Project cash balance | B16: =5 | C16: =B16+C2-C15 | D16: =C16+D2-D15 | E16: =D16+E2-E15 | F16: =E16+F2-F15 | G16: =F16+G2-G15 | H16: =G16+H2-H15 | I16: =H16+I2-I15

Sheet BalanceSheet
A1: Year | B1: 0 | C1: 1 | D1: 2 | E1: 3 | F1: 4 | G1: 5 | H1: 6 | I1: 7
A2: Net block (fixed assets) | B2: =30+55+120+18 | C2: =(30+55+120+18)-(Assumptions!$B$16+Assumptions!$B$17+Assumptions!$B$18)*C$1 | D2: =(30+55+120+18)-(Assumptions!$B$16+Assumptions!$B$17+Assumptions!$B$18)*D$1 | E2: =(30+55+120+18)-(Assumptions!$B$16+Assumptions!$B$17+Assumptions!$B$18)*E$1 | F2: =(30+55+120+18)-(Assumptions!$B$16+Assumptions!$B$17+Assumptions!$B$18)*F$1 | G2: =(30+55+120+18)-(Assumptions!$B$16+Assumptions!$B$17+Assumptions!$B$18)*G$1 | H2: =(30+55+120+18)-(Assumptions!$B$16+Assumptions!$B$17+Assumptions!$B$18)*H$1 | I2: =(30+55+120+18)-(Assumptions!$B$16+Assumptions!$B$17+Assumptions!$B$18)*I$1
A3: Preliminary expenses not written off | B3: =12 | C3: =12-Assumptions!$B$19*MIN(C$1,5) | D3: =12-Assumptions!$B$19*MIN(D$1,5) | E3: =12-Assumptions!$B$19*MIN(E$1,5) | F3: =12-Assumptions!$B$19*MIN(F$1,5) | G3: =12-Assumptions!$B$19*MIN(G$1,5) | H3: =12-Assumptions!$B$19*MIN(H$1,5) | I3: =12-Assumptions!$B$19*MIN(I$1,5)
A4: Cash & bank | B4: =CashFlow_DSCR!B16 | C4: =CashFlow_DSCR!C16 | D4: =CashFlow_DSCR!D16 | E4: =CashFlow_DSCR!E16 | F4: =CashFlow_DSCR!F16 | G4: =CashFlow_DSCR!G16 | H4: =CashFlow_DSCR!H16 | I4: =CashFlow_DSCR!I16
A5: TOTAL ASSETS | B5: =SUM(B2:B4) | C5: =SUM(C2:C4) | D5: =SUM(D2:D4) | E5: =SUM(E2:E4) | F5: =SUM(F2:F4) | G5: =SUM(G2:G4) | H5: =SUM(H2:H4) | I5: =SUM(I2:I4)
A7: Equity capital | B7: =60 | C7: =60 | D7: =60 | E7: =60 | F7: =60 | G7: =60 | H7: =60 | I7: =60
A8: Reserves (accumulated PAT) | B8: =0 | C8: =B8+PL!B9 | D8: =C8+PL!C9 | E8: =D8+PL!D9 | F8: =E8+PL!E9 | G8: =F8+PL!F9 | H8: =G8+PL!G9 | I8: =H8+PL!H9
A9: Term loan outstanding | B9: =Loan_Schedule!B6 | C9: =Loan_Schedule!C6 | D9: =Loan_Schedule!D6 | E9: =Loan_Schedule!E6 | F9: =Loan_Schedule!F6 | G9: =Loan_Schedule!G6 | H9: =Loan_Schedule!H6 | I9: =Loan_Schedule!I6
A10: TOTAL LIABILITIES | B10: =SUM(B7:B9) | C10: =SUM(C7:C9) | D10: =SUM(D7:D9) | E10: =SUM(E7:E9) | F10: =SUM(F7:F9) | G10: =SUM(G7:G9) | H10: =SUM(H7:H9) | I10: =SUM(I7:I9)
A11: Check: assets - liabilities | B11: =B5-B10 | C11: =C5-C10 | D11: =D5-D10 | E11: =E5-E10 | F11: =F5-F10 | G11: =G5-G10 | H11: =H5-H10 | I11: =I5-I10

Sheet Ratios
A1: Ratio | B1: Value
A2: Project cost (Rs lakh) | B2: =Project_Cost!$B$9
A3: Term loan (Rs lakh) | B3: =Assumptions!$B$21
A4: Promoter margin | B4: =Means_of_Finance!$B$6
A5: Debt-equity (at start) | B5: =Means_of_Finance!$B$7
A6: Average DSCR (Y1-Y7) | B6: =CashFlow_DSCR!$B$9
A7: Minimum DSCR, repayment years | B7: =CashFlow_DSCR!$B$10
A8: NPV @12% (Rs lakh) | B8: =CashFlow_DSCR!$B$11
A9: Equity IRR | B9: =CashFlow_DSCR!$B$12
A10: Payback year | B10: =CashFlow_DSCR!$B$13
A11: Break-even capacity utilisation | B11: =(Revenue_Cost!$B$8+Revenue_Cost!$B$9+Revenue_Cost!$B$10+Revenue_Cost!$B$12+PL!$B$5+Loan_Schedule!$C$3)/(1-Assumptions!$B$6-Assumptions!$B$7-Assumptions!$B$8)/(1200000*Assumptions!$B$3/100000)
A12: Bank norm: min DSCR >= 1.25x? | B12: =B7>=1.25

Sheet Sensitivity
A1: Scenario / line | B1: Y0 | C1: 1 | D1: 2 | E1: 3 | F1: 4 | G1: 5 | H1: 6 | I1: 7
A2: S0 Base (revenue x 1.0, raw 76%)
A3: Revenue (Rs lakh) | B3: 0 | C3: =Revenue_Cost!B4*1.0 | D3: =Revenue_Cost!C4*1.0 | E3: =Revenue_Cost!D4*1.0 | F3: =Revenue_Cost!E4*1.0 | G3: =Revenue_Cost!F4*1.0 | H3: =Revenue_Cost!G4*1.0 | I3: =Revenue_Cost!H4*1.0
A4: Raw material | B4: 0 | C4: =C3*0.76 | D4: =D3*0.76 | E4: =E3*0.76 | F4: =F3*0.76 | G4: =G3*0.76 | H4: =H3*0.76 | I4: =I3*0.76
A5: Packing | B5: 0 | C5: =C3*Assumptions!$B$7 | D5: =D3*Assumptions!$B$7 | E5: =E3*Assumptions!$B$7 | F5: =F3*Assumptions!$B$7 | G5: =G3*Assumptions!$B$7 | H5: =H3*Assumptions!$B$7 | I5: =I3*Assumptions!$B$7
A6: Power & fuel | B6: 0 | C6: =Revenue_Cost!B8 | D6: =Revenue_Cost!C8 | E6: =Revenue_Cost!D8 | F6: =Revenue_Cost!E8 | G6: =Revenue_Cost!F8 | H6: =Revenue_Cost!G8 | I6: =Revenue_Cost!H8
A7: Salaries | B7: 0 | C7: =Revenue_Cost!B9 | D7: =Revenue_Cost!C9 | E7: =Revenue_Cost!D9 | F7: =Revenue_Cost!E9 | G7: =Revenue_Cost!F9 | H7: =Revenue_Cost!G9 | I7: =Revenue_Cost!H9
A8: Repairs | B8: 0 | C8: =Assumptions!$B$13 | D8: =Assumptions!$B$13 | E8: =Assumptions!$B$13 | F8: =Assumptions!$B$13 | G8: =Assumptions!$B$13 | H8: =Assumptions!$B$13 | I8: =Assumptions!$B$13
A9: Admin & selling | B9: 0 | C9: =C3*Assumptions!$B$8 | D9: =D3*Assumptions!$B$8 | E9: =E3*Assumptions!$B$8 | F9: =F3*Assumptions!$B$8 | G9: =G3*Assumptions!$B$8 | H9: =H3*Assumptions!$B$8 | I9: =I3*Assumptions!$B$8
A10: Insurance | B10: 0 | C10: =Revenue_Cost!B12 | D10: =Revenue_Cost!C12 | E10: =Revenue_Cost!D12 | F10: =Revenue_Cost!E12 | G10: =Revenue_Cost!F12 | H10: =Revenue_Cost!G12 | I10: =Revenue_Cost!H12
A11: Total operating cost | B11: 0 | C11: =SUM(C4:C10) | D11: =SUM(D4:D10) | E11: =SUM(E4:E10) | F11: =SUM(F4:F10) | G11: =SUM(G4:G10) | H11: =SUM(H4:H10) | I11: =SUM(I4:I10)
A12: EBITDA | B12: 0 | C12: =C3-C11 | D12: =D3-D11 | E12: =E3-E11 | F12: =F3-F11 | G12: =G3-G11 | H12: =H3-H11 | I12: =I3-I11
A13: Depreciation | B13: 0 | C13: =PL!B5 | D13: =PL!C5 | E13: =PL!D5 | F13: =PL!E5 | G13: =PL!F5 | H13: =PL!G5 | I13: =PL!H5
A14: Interest | B14: 0 | C14: =Loan_Schedule!C3 | D14: =Loan_Schedule!D3 | E14: =Loan_Schedule!E3 | F14: =Loan_Schedule!F3 | G14: =Loan_Schedule!G3 | H14: =Loan_Schedule!H3 | I14: =Loan_Schedule!I3
A15: PBT | B15: 0 | C15: =C12-C13-C14 | D15: =D12-D13-D14 | E15: =E12-E13-E14 | F15: =F12-F13-F14 | G15: =G12-G13-G14 | H15: =H12-H13-H14 | I15: =I12-I13-I14
A16: Tax | B16: 0 | C16: =IF(C15>0,C15*Assumptions!$B$20,0) | D16: =IF(D15>0,D15*Assumptions!$B$20,0) | E16: =IF(E15>0,E15*Assumptions!$B$20,0) | F16: =IF(F15>0,F15*Assumptions!$B$20,0) | G16: =IF(G15>0,G15*Assumptions!$B$20,0) | H16: =IF(H15>0,H15*Assumptions!$B$20,0) | I16: =IF(I15>0,I15*Assumptions!$B$20,0)
A17: PAT | B17: 0 | C17: =C15-C16 | D17: =D15-D16 | E17: =E15-E16 | F17: =F15-F16 | G17: =G15-G16 | H17: =H15-H16 | I17: =I15-I16
A18: Cash accruals | B18: 0 | C18: =C17+C13 | D18: =D17+D13 | E18: =E17+E13 | F18: =F17+F13 | G18: =G17+G13 | H18: =H17+H13 | I18: =I17+I13
A19: Debt service | B19: 0 | C19: =CashFlow_DSCR!C3 | D19: =CashFlow_DSCR!D3 | E19: =CashFlow_DSCR!E3 | F19: =CashFlow_DSCR!F3 | G19: =CashFlow_DSCR!G3 | H19: =CashFlow_DSCR!H3 | I19: =CashFlow_DSCR!I3
A20: Net cash to equity | B20: =-Assumptions!$B$25 | C20: =C18-Loan_Schedule!C5 | D20: =D18-Loan_Schedule!D5 | E20: =E18-Loan_Schedule!E5 | F20: =F18-Loan_Schedule!F5 | G20: =G18-Loan_Schedule!G5 | H20: =H18-Loan_Schedule!H5 | I20: =I18-Loan_Schedule!I5
A21: DSCR | C21: =IF(C19=0,"",C18/C19) | D21: =IF(D19=0,"",D18/D19) | E21: =IF(E19=0,"",E18/E19) | F21: =IF(F19=0,"",F18/F19) | G21: =IF(G19=0,"",G18/G19) | H21: =IF(H19=0,"",H18/H19) | I21: =IF(I19=0,"",I18/I19)
A23: Min DSCR, repayment years (Y2-Y7) | B23: =MIN(D21:I21)
A24: Average DSCR (Y1-Y7) | B24: =AVERAGE(C21:I21)
A25: NPV @12% (Rs lakh) | B25: =B20+NPV(Assumptions!$B$26,C20:I20)
A26: Equity IRR | B26: =IRR(B20:I20)
A27: S1 Revenue -5% (revenue x 0.95, raw 76%)
A28: Revenue (Rs lakh) | B28: 0 | C28: =Revenue_Cost!B4*0.95 | D28: =Revenue_Cost!C4*0.95 | E28: =Revenue_Cost!D4*0.95 | F28: =Revenue_Cost!E4*0.95 | G28: =Revenue_Cost!F4*0.95 | H28: =Revenue_Cost!G4*0.95 | I28: =Revenue_Cost!H4*0.95
A29: Raw material | B29: 0 | C29: =C28*0.76 | D29: =D28*0.76 | E29: =E28*0.76 | F29: =F28*0.76 | G29: =G28*0.76 | H29: =H28*0.76 | I29: =I28*0.76
A30: Packing | B30: 0 | C30: =C28*Assumptions!$B$7 | D30: =D28*Assumptions!$B$7 | E30: =E28*Assumptions!$B$7 | F30: =F28*Assumptions!$B$7 | G30: =G28*Assumptions!$B$7 | H30: =H28*Assumptions!$B$7 | I30: =I28*Assumptions!$B$7
A31: Power & fuel | B31: 0 | C31: =Revenue_Cost!B8 | D31: =Revenue_Cost!C8 | E31: =Revenue_Cost!D8 | F31: =Revenue_Cost!E8 | G31: =Revenue_Cost!F8 | H31: =Revenue_Cost!G8 | I31: =Revenue_Cost!H8
A32: Salaries | B32: 0 | C32: =Revenue_Cost!B9 | D32: =Revenue_Cost!C9 | E32: =Revenue_Cost!D9 | F32: =Revenue_Cost!E9 | G32: =Revenue_Cost!F9 | H32: =Revenue_Cost!G9 | I32: =Revenue_Cost!H9
A33: Repairs | B33: 0 | C33: =Assumptions!$B$13 | D33: =Assumptions!$B$13 | E33: =Assumptions!$B$13 | F33: =Assumptions!$B$13 | G33: =Assumptions!$B$13 | H33: =Assumptions!$B$13 | I33: =Assumptions!$B$13
A34: Admin & selling | B34: 0 | C34: =C28*Assumptions!$B$8 | D34: =D28*Assumptions!$B$8 | E34: =E28*Assumptions!$B$8 | F34: =F28*Assumptions!$B$8 | G34: =G28*Assumptions!$B$8 | H34: =H28*Assumptions!$B$8 | I34: =I28*Assumptions!$B$8
A35: Insurance | B35: 0 | C35: =Revenue_Cost!B12 | D35: =Revenue_Cost!C12 | E35: =Revenue_Cost!D12 | F35: =Revenue_Cost!E12 | G35: =Revenue_Cost!F12 | H35: =Revenue_Cost!G12 | I35: =Revenue_Cost!H12
A36: Total operating cost | B36: 0 | C36: =SUM(C29:C35) | D36: =SUM(D29:D35) | E36: =SUM(E29:E35) | F36: =SUM(F29:F35) | G36: =SUM(G29:G35) | H36: =SUM(H29:H35) | I36: =SUM(I29:I35)
A37: EBITDA | B37: 0 | C37: =C28-C36 | D37: =D28-D36 | E37: =E28-E36 | F37: =F28-F36 | G37: =G28-G36 | H37: =H28-H36 | I37: =I28-I36
A38: Depreciation | B38: 0 | C38: =PL!B5 | D38: =PL!C5 | E38: =PL!D5 | F38: =PL!E5 | G38: =PL!F5 | H38: =PL!G5 | I38: =PL!H5
A39: Interest | B39: 0 | C39: =Loan_Schedule!C3 | D39: =Loan_Schedule!D3 | E39: =Loan_Schedule!E3 | F39: =Loan_Schedule!F3 | G39: =Loan_Schedule!G3 | H39: =Loan_Schedule!H3 | I39: =Loan_Schedule!I3
A40: PBT | B40: 0 | C40: =C37-C38-C39 | D40: =D37-D38-D39 | E40: =E37-E38-E39 | F40: =F37-F38-F39 | G40: =G37-G38-G39 | H40: =H37-H38-H39 | I40: =I37-I38-I39
A41: Tax | B41: 0 | C41: =IF(C40>0,C40*Assumptions!$B$20,0) | D41: =IF(D40>0,D40*Assumptions!$B$20,0) | E41: =IF(E40>0,E40*Assumptions!$B$20,0) | F41: =IF(F40>0,F40*Assumptions!$B$20,0) | G41: =IF(G40>0,G40*Assumptions!$B$20,0) | H41: =IF(H40>0,H40*Assumptions!$B$20,0) | I41: =IF(I40>0,I40*Assumptions!$B$20,0)
...

Sheet Dashboard
A1: DPRPulse — Banker's Dashboard
A3: KPI | B3: Value | D3: Year | E3: Cash accruals | F3: Debt service | H3: DSCR | I3: Bank norm | K3: Scenario | L3: NPV @12%
A4: Project cost (Rs lakh) | B4: =Ratios!$B$2 | D4: 1 | E4: =CashFlow_DSCR!C2 | F4: =CashFlow_DSCR!C3 | H4: =CashFlow_DSCR!C6 | I4: 1.25 | K4: S0 Base | L4: =Sensitivity!B25
A5: Term loan (Rs lakh) | B5: =Ratios!$B$3 | D5: 2 | E5: =CashFlow_DSCR!D2 | F5: =CashFlow_DSCR!D3 | H5: =CashFlow_DSCR!D6 | I5: 1.25 | K5: S1 Revenue -5% | L5: =Sensitivity!B50
A6: Promoter margin | B6: =Ratios!$B$4 | D6: 3 | E6: =CashFlow_DSCR!E2 | F6: =CashFlow_DSCR!E3 | H6: =CashFlow_DSCR!E6 | I6: 1.25 | K6: S2 Raw material +3pp | L6: =Sensitivity!B75
A7: Average DSCR | B7: =Ratios!$B$6 | D7: 4 | E7: =CashFlow_DSCR!F2 | F7: =CashFlow_DSCR!F3 | H7: =CashFlow_DSCR!F6 | I7: 1.25 | K7: S3 Combined stress | L7: =Sensitivity!B100
A8: Minimum DSCR (repayment) | B8: =Ratios!$B$7 | D8: 5 | E8: =CashFlow_DSCR!G2 | F8: =CashFlow_DSCR!G3 | H8: =CashFlow_DSCR!G6 | I8: 1.25
A9: NPV @12% (Rs lakh) | B9: =Ratios!$B$8 | D9: 6 | E9: =CashFlow_DSCR!H2 | F9: =CashFlow_DSCR!H3 | H9: =CashFlow_DSCR!H6 | I9: 1.25
A10: Equity IRR | B10: =Ratios!$B$9 | D10: 7 | E10: =CashFlow_DSCR!I2 | F10: =CashFlow_DSCR!I3 | H10: =CashFlow_DSCR!I6 | I10: 1.25
A11: Break-even utilisation | B11: =Ratios!$B$11
A13: Risk flags
A14: =IF(Sensitivity!B73<1.25,"RISK: raw-material +3pp drags min DSCR to "&TEXT(Sensitivity!B73,"0.00")&"x - lock input prices","OK: raw-material +3pp stays above 1.25x")
A15: =IF(Sensitivity!B98<1.25,"RISK: combined stress drags min DSCR to "&TEXT(Sensitivity!B98,"0.00")&"x - keep a contingency buffer","OK: combined stress stays above 1.25x")
A16: =IF(CashFlow_DSCR!$B$10>=1.25,"Base case services debt comfortably (min DSCR "&TEXT(CashFlow_DSCR!$B$10,"0.00")&"x)","Base case DSCR below 1.25x - restructure")

Sheet Checks
A1: Check | B1: Result | C1: Note
A2: Project cost adds to Rs 240 lakh | B2: =Project_Cost!$B$9=240 | C2: 7 capex heads
A3: Means of finance = project cost | B3: =Means_of_Finance!$B$4=Project_Cost!$B$9
A4: Term loan fully repaid by Y7 | B4: =ABS(Loan_Schedule!$I$6)<0.01
A5: Balance sheet balances every year | B5: =AND(ABS(BalanceSheet!B11)<0.01,ABS(BalanceSheet!C11)<0.01,ABS(BalanceSheet!D11)<0.01,ABS(BalanceSheet!E11)<0.01,ABS(BalanceSheet!F11)<0.01,ABS(BalanceSheet!G11)<0.01,ABS(BalanceSheet!H11)<0.01,ABS(BalanceSheet!I11)<0.01) | C5: assets - liabilities within 0.01
A6: Min DSCR (repayment) >= 1.25x | B6: =CashFlow_DSCR!$B$10>=1.25 | C6: bank norm
A7: Cash balance never negative | B7: =MIN(BalanceSheet!$B$4:$I$4)>=0
A8: NPV @12% positive | B8: =Ratios!$B$8>0
A9: IRR exceeds hurdle rate | B9: =Ratios!$B$9>Assumptions!$B$26
A10: Utilisation ramp non-decreasing | B10: =AND(Assumptions!C5>=Assumptions!B5,Assumptions!D5>=Assumptions!C5,Assumptions!E5>=Assumptions!D5,Assumptions!F5>=Assumptions!E5,Assumptions!G5>=Assumptions!F5,Assumptions!H5>=Assumptions!G5)
A11: S1 mild stress still services debt | B11: =Sensitivity!$B$48>=1.25 | C11: revenue -5%
